Workbook

Sheet Wheat_Mo
A1: Commodity | B1: Metric | C1: Crop Year | D1: AUG | E1: SEP | F1: OCT | G1: NOV | H1: DEC | I1: JAN | J1: FEB | K1: MAR | L1: APR | M1: MAY | N1: JUN | O1: JUL | P1: AUG/JUL
A2: Wheat, excluding durum | B2: Planted Area | C2: 02-03 | D2: 19.5012 | P2: =D2 -> 19.5012
A3: Wheat, excluding durum | B3: Planted Area | C3: 03-04 | D3: 19.7719 | P3: =D3 -> 19.7719
A4: Wheat, excluding durum | B4: Planted Area | C4: 04-05 | D4: 19.1433 | P4: =D4 -> 19.1433
A5: Wheat, excluding durum | B5: Planted Area | C5: 05-06 | D5: 18.1559 | P5: =D5 -> 18.1559
A6: Wheat, excluding durum | B6: Planted Area | C6: 06-07 | D6: 20.549875 | P6: =D6 -> 20.549875
A7: Wheat, excluding durum | B7: Planted Area | C7: 07-08 | D7: 16.9631 | P7: =D7 -> 16.9631
A8: Wheat, excluding durum | B8: Planted Area | C8: 08-09 | D8: 19.111 | P8: =D8 -> 19.111
A9: Wheat, excluding durum | B9: Planted Area | C9: 09-10 | D9: 19.2571 | P9: =D9 -> 19.2571
A10: Wheat, excluding durum | B10: Planted Area | C10: 10-11 | D10: 17.9841 | P10: =D10 -> 17.9841
A11: Wheat, excluding durum | B11: Planted Area | C11: 11-12 | D11: 17.551812 | P11: =D11 -> 17.551812
A12: Wheat, excluding durum | B12: Planted Area | C12: 12-13 | D12: 19.0678 | P12: =D12 -> 19.0678
A13: Wheat, excluding durum | B13: Planted Area | C13: 13-14 | D13: 21.2865 | P13: =D13 -> 21.2865
... A93: Wheat, excluding durum | B93: Production | C93: 24-25 | D93: 29558.525 | P93: =D93 -> 29558.525
A94: Wheat, excluding durum | B94: Exports | C94: 02-03 | D94: 557.6 | E94: 557.6 | F94: 557.6 | G94: 557.6 | H94: 557.6 | I94: 349.26667 | J94: 349.26667 | K94: 349.26667 | L94: 596.85 | M94: 596.85 | N94: 596.85 | O94: 596.85 | P94: =SUM(D94:O94) -> 6223.2
A95: Wheat, excluding durum | B95: Exports | C95: 03-04 | D95: 1012.5 | E95: 1012.5 | F95: 1012.5 | G95: 1012.5 | H95: 1012.5 | I95: 837.56667 | J95: 837.56667 | K95: 837.56667 | L95: 1181.025 | M95: 1181.025 | N95: 1181.025 | O95: 1181.025 | P95: =SUM(D95:O95) -> 12299.3
A96: Wheat, excluding durum | B96: Exports | C96: 04-05 | D96: 995.62 | E96: 995.62 | F96: 995.62 | G96: 995.62 | H96: 995.62 | I96: 993.8 | J96: 993.8 | K96: 993.8 | L96: 908.9 | M96: 908.9 | N96: 908.9 | O96: 908.9 | P96: =SUM(D96:O96) -> 11595.1
A97: Wheat, excluding durum | B97: Exports | C97: 05-06 | D97: 813.6 | E97: 813.6 | F97: 813.6 | G97: 813.6 | H97: 813.6 | I97: 846.33333 | J97: 846.33333 | K97: 846.33333 | L97: 1204.725 | M97: 1204.725 | N97: 1204.725 | O97: 1204.725 | P97: =SUM(D97:O97) -> 11425.9
A98: Wheat, excluding durum | B98: Exports | C98: 06-07 | D98: 1328.44 | E98: 1328.44 | F98: 1328.44 | G98: 1328.44 | H98: 1328.44 | I98: 1001.2333 | J98: 1001.2333 | K98: 1001.2333 | L98: 1325.675 | M98: 1325.675 | N98: 1325.675 | O98: 1325.675 | P98: =SUM(D98:O98) -> 14948.6
A99: Wheat, excluding durum | B99: Exports | C99: 07-08 | D99: 1142.24 | E99: 1142.24 | F99: 1142.24 | G99: 1142.24 | H99: 1142.24 | I99: 872.6 | J99: 872.6 | K99: 872.6 | L99: 1088.275 | M99: 1088.275 | N99: 1088.275 | O99: 1088.275 | P99: =SUM(D99:O99) -> 12682.1
A100: Wheat, excluding durum | B100: Exports | C100: 08-09 | D100: 1139.56 | E100: 1139.56 | F100: 1139.56 | G100: 1139.56 | H100: 1139.56 | I100: 1202.9667 | J100: 1202.9667 | K100: 1202.9667 | L100: 1414.925 | M100: 1414.925 | N100: 1414.925 | O100: 1414.925 | P100: =SUM(D100:O100) -> 14966.4
A101: Wheat, excluding durum | B101: Exports | C101: 09-10 | D101: 1180.3 | E101: 1180.3 | F101: 1180.3 | G101: 1180.3 | H101: 1180.3 | I101: 1150.1667 | J101: 1150.1667 | K101: 1150.1667 | L101: 1327.35 | M101: 1327.35 | N101: 1327.35 | O101: 1327.35 | P101: =SUM(D101:O101) -> 14661.4
A102: Wheat, excluding durum | B102: Exports | C102: 10-11 | D102: 1061.1 | E102: 1061.1 | F102: 1061.1 | G102: 1061.1 | H102: 1061.1 | I102: 854.43333 | J102: 854.43333 | K102: 854.43333 | L102: 1253.025 | M102: 1253.025 | N102: 1253.025 | O102: 1253.025 | P102: =SUM(D102:O102) -> 12880.9
A103: Wheat, excluding durum | B103: Exports | C103: 11-12 | D103: 1185.26 | E103: 1185.26 | F103: 1185.26 | G103: 1185.26 | H103: 1185.26 | I103: 1166.2 | J103: 1166.2 | K103: 1166.2 | L103: 1122.825 | M103: 1122.825 | N103: 1122.825 | O103: 1122.825 | P103: =SUM(D103:O103) -> 13916.2
A104: Wheat, excluding durum | B104: Exports | C104: 12-13 | D104: 1221.06 | E104: 1221.06 | F104: 1221.06 | G104: 1221.06 | H104: 1221.06 | I104: 1235.3 | J104: 1235.3 | K104: 1235.3 | L104: 1380.375 | M104: 1380.375 | N104: 1380.375 | O104: 1380.375 | P104: =SUM(D104:O104) -> 15332.7
A105: Wheat, excluding durum | B105: Exports | C105: 13-14 | D105: 1389.6 | E105: 1389.6 | F105: 1389.6 | G105: 1389.6 | H105: 1389.6 | I105: 1356.7 | J105: 1356.7 | K105: 1356.7 | L105: 1852.075 | M105: 1852.075 | N105: 1852.075 | O105: 1852.075 | P105: =SUM(D105:O105) -> 18426.4
... A254: Wheat, excluding durum | B254: FSR | C254: 24-25 | D254: 267.48667 | E254: 267.48667 | F254: 267.48667 | G254: 267.48667 | H254: 267.48667 | I254: 247.66667 | J254: 247.66667 | K254: 247.66667 | L254: 429.54167 | M254: 429.54167 | N254: 429.54167 | O254: 429.54167 | P254: =SUM(D254:O254) -> 3798.6
A255: Wheat, excluding durum | B255: STOCKS | C255: 02-03 | D255: 16151.675 | E255: 15063.948 | F255: 13947.305 | G255: 12866.386 | H255: 11815.781 | I255: 10976.048 | J255: 10111.689 | K255: 9248.088 | L255: 7962.742 | M255: 6678.452 | N255: 5392.77 | O255: 4106.552 | P255: =O255 -> 4106.552
A256: Wheat, excluding durum | B256: STOCKS | C256: 03-04 | D256: 21432.351 | E256: 19924.308 | F256: 18414.015 | G256: 16902.702 | H256: 15391.129 | I256: 14092.037 | J256: 12793.206 | K256: 11494.202 | L256: 9673.569 | M256: 7852.816 | N256: 6031.973 | O256: 4211.064 | P256: =O256 -> 4211.064
A257: Wheat, excluding durum | B257: STOCKS | C257: 04-05 | D257: 22654.862 | E257: 21105.19 | F257: 19555.164 | G257: 18003.912 | H257: 16452.342 | I257: 14928.591 | J257: 13404.675 | K257: 11881.082 | L257: 10269.305 | M257: 8657.568 | N257: 7046.531 | O257: 5435.038 | P257: =O257 -> 5435.038
A258: Wheat, excluding durum | B258: STOCKS | C258: 05-06 | D258: 23873.432 | E258: 22477.65 | F258: 21081.27 | G258: 19683.67 | H258: 18285.95 | I258: 16906.088 | J258: 15525.896 | K258: 14145.858 | L258: 12214.775 | M258: 10283.896 | N258: 8353.827 | O258: 6423.97 | P258: =O258 -> 6423.97
A259: Wheat, excluding durum | B259: STOCKS | C259: 06-07 | D259: 26399.879 | E259: 24456.54 | F259: 22510.723 | G259: 20563.93 | H259: 18617.181 | I259: 17015.655 | J259: 15413.72 | K259: 13811.518 | L259: 11760.424 | M259: 9709.822 | N259: 7659.254 | O259: 5608.144 | P259: =O259 -> 5608.144
A260: Wheat, excluding durum | B260: STOCKS | C260: 07-08 | D260: 20414.747 | E260: 18815.195 | F260: 17213.422 | G260: 15611.581 | H260: 14009.001 | I260: 12728.011 | J260: 11446.675 | K260: 10166.273 | L260: 8514.328 | M260: 6862.3013 | N260: 5209.5547 | O260: 3557.422 | P260: =O260 -> 3557.422
A261: Wheat, excluding durum | B261: STOCKS | C261: 08-09 | D261: 24974.793 | E261: 23292.671 | F261: 21608.764 | G261: 19924.279 | H261: 18239.437 | I261: 16523.579 | J261: 14808.1 | K261: 13092.833 | L261: 10980.958 | M261: 8869.7567 | N261: 6755.5693 | O261: 4641.696 | P261: =O261 -> 4641.696
A262: Wheat, excluding durum | B262: STOCKS | C262: 09-10 | D262: 24505.106 | E262: 22809.274 | F262: 21107.072 | G262: 19405.63 | H262: 17692.05 | I262: 16125.203 | J262: 14558.045 | K262: 12991.158 | L262: 11005.026 | M262: 9018.242 | N262: 7032.256 | O262: 5048.966 | P262: =O262 -> 5048.966
A263: Wheat, excluding durum | B263: STOCKS | C263: 10-11 | D263: 23712.117 | E263: 22102.003 | F263: 20489.174 | G263: 18876.605 | H263: 17264.467 | I263: 15933.209 | J263: 14601.487 | K263: 13270.055 | L263: 11399.071 | M263: 9527.8907 | N263: 7656.4363 | O263: 5793.688 | P263: =O263 -> 5793.688
A264: Wheat, excluding durum | B264: STOCKS | C264: 11-12 | D264: 25048.217 | E264: 23187.563 | F264: 21324.92 | G264: 19466.707 | H264: 17604.119 | I264: 15799.712 | J264: 14006.974 | K264: 12212.829 | L264: 10269.672 | M264: 8325.0923 | N264: 6389.4037 | O264: 4445.797 | P264: =O264 -> 4445.797
A265: Wheat, excluding durum | B265: STOCKS | C265: 12-13 | D265: 25224.128 | E265: 23383.559 | F265: 21542.851 | G265: 19701.293 | H265: 17859.205 | I265: 16088.534 | J265: 14317.626 | K265: 12546.849 | L265: 10403.09 | M265: 8259.5283 | N265: 6128.4277 | O265: 3985.236 | P265: =O265 -> 3985.236
A266: Wheat, excluding durum | B266: STOCKS | C266: 13-14 | D266: 33052.108 | E266: 31035.351 | F266: 29016.786 | G266: 26997.994 | H266: 24984.69 | I266: 23033.509 | J266: 21082.601 | K266: 19135.13 | L266: 16520.188 | M266: 13898.952 | N266: 11279.242 | O266: 8658.62 | P266: =O266 -> 8658.62
... A277: Wheat, excluding durum | B277: STOCKS | C277: 24-25 | D277: 31948.314 | E277: 29613.339 | F277: 27292.678 | G277: 24961.843 | H277: 22631.29 | I277: 20247.347 | J277: 17861.149 | K277: 15476.003 | L277: 12553.911 | M277: 9631.9843 | N277: 6711.4837 | O277: 3808.442 | P277: =O277 -> 3808.442

Sheet Wheat_Yr
A1: Wheat
A2: Commodity | B2: Metric | C2: Unit | D2: 2002-03 | E2: 2003-04 | F2: 2004-05 | G2: 2005-06 | H2: 2006-07 | I2: 2007-08 | J2: 2008-09 | K2: 2009-10 | L2: 2010-11 | M2: 2011-12 | N2: 2012-13 | O2: 2013-14 | P2: 2014-15 | Q2: 2015-16 | R2: 2016-17 | S2: 2017-18 | T2: 2018-19 | U2: 2019-20 | V2: 2020-21 | W2: 2021-22 | X2: 2022-23 | Y2: 2023-24 | Z2: 2024-25 | AA2: 2025-26
A3: Wheat | B3: Planted Area | C3: MLN AC | D3: =Wheat_Mo!P3 -> 19.7719 | E3: =Wheat_Mo!P18 -> 18.7067 | F3: =Wheat_Mo!P33 -> 17.426 | G3: =Wheat_Mo!P48 -> 27.795898 | H3: =Wheat_Mo!P63 -> 54.807602 | I3: =Wheat_Mo!P78 -> 21550.3 | J3: =Wheat_Mo!P93 -> 29558.525 | K3: =Wheat_Mo!P108 -> 15621.4 | L3: =Wheat_Mo!P123 -> 23.074 | M3: =Wheat_Mo!P138 -> 87.64 | N3: =Wheat_Mo!P153 -> 2645.4 | O3: =Wheat_Mo!P168 -> 394 | P3: =Wheat_Mo!P183 -> 389.7 | Q3: =Wheat_Mo!P198 -> 0 | R3: =Wheat_Mo!P213 -> 3114 | S3: =Wheat_Mo!P228 -> 3250.3 | T3: =Wheat_Mo!P243 -> 4608.1 | U3: =Wheat_Mo!P258 -> 6423.97 | V3: =Wheat_Mo!P273 -> 5220.774 | W3: =Wheat_Mo!P288 -> 0 | X3: =Wheat_Mo!P303 -> 0 | Y3: =Wheat_Mo!P318 -> 0 | Z3: =Wheat_Mo!P333 -> 0 | AA3: =Wheat_Mo!P348 -> 0
A4: Wheat | B4: Harvested Area | C4: MLN AC | D4: =Wheat_Mo!P4 -> 19.1433 | E4: =Wheat_Mo!P19 -> 20.1276 | F4: =Wheat_Mo!P34 -> 17.2035 | G4: =Wheat_Mo!P49 -> 35.8138 | H4: =Wheat_Mo!P64 -> 53.201238 | I4: =Wheat_Mo!P79 -> 20274.9 | J4: =Wheat_Mo!P94 -> 6223.2 | K4: =Wheat_Mo!P109 -> 17570.2 | L4: =Wheat_Mo!P124 -> 114.97 | M4: =Wheat_Mo!P139 -> 80.139 | N4: =Wheat_Mo!P154 -> 2532.5 | O4: =Wheat_Mo!P169 -> 646 | P4: =Wheat_Mo!P184 -> 356.7 | Q4: =Wheat_Mo!P199 -> 0 | R4: =Wheat_Mo!P214 -> 3022.3 | S4: =Wheat_Mo!P229 -> 3256 | T4: =Wheat_Mo!P244 -> 4807.9 | U4: =Wheat_Mo!P259 -> 5608.144 | V4: =Wheat_Mo!P274 -> 3662.765 | W4: =Wheat_Mo!P289 -> 0 | X4: =Wheat_Mo!P304 -> 0 | Y4: =Wheat_Mo!P319 -> 0 | Z4: =Wheat_Mo!P334 -> 0 | AA4: =Wheat_Mo!P349 -> 0
A5: Wheat | B5: Proportion Harvested | C5: % | D5: =IF(D3<>0,D4/D3,"") -> 0.96820741 | E5: =IF(E3<>0,E4/E3,"") -> 1.0759567 | F5: =IF(F3<>0,F4/F3,"") -> 0.98723172 | G5: =IF(G3<>0,G4/G3,"") -> 1.2884563 | H5: =IF(H3<>0,H4/H3,"") -> 0.97069085 | I5: =IF(I3<>0,I4/I3,"") -> 0.94081753 | J5: =IF(J3<>0,J4/J3,"") -> 0.21053825 | K5: =IF(K3<>0,K4/K3,"") -> 1.1247519 | ... AA5: =IF(AA3<>0,AA4/AA3,"")
A6: Wheat | B6: Yield | C6: BU/AC | D6: =Wheat_Mo!O6 -> 0 | E6: =Wheat_Mo!O21 -> 0 | F6: =Wheat_Mo!O36 -> 0 | G6: =Wheat_Mo!O51 -> 0 | H6: =Wheat_Mo!O66 -> 0 | I6: =Wheat_Mo!O81 -> 0 | J6: =Wheat_Mo!O96 -> 908.9 | K6: =Wheat_Mo!O111 -> 1993.1 | L6: =Wheat_Mo!O126 -> 2.885 | M6: =Wheat_Mo!O141 -> 217.825 | N6: =Wheat_Mo!O156 -> 233.55 | O6: =Wheat_Mo!O171 -> 42.75 | P6: =Wheat_Mo!O186 -> 0 | Q6: =Wheat_Mo!O201 -> 0 | R6: =Wheat_Mo!O216 -> 287.55 | S6: =Wheat_Mo!O231 -> 286.075 | T6: =Wheat_Mo!O246 -> 475.725 | U6: =Wheat_Mo!O261 -> 4641.696 | V6: =Wheat_Mo!O276 -> 4721.078 | W6: =Wheat_Mo!O291 -> 0 | X6: =Wheat_Mo!O306 -> 0 | Y6: =Wheat_Mo!O321 -> 0 | Z6: =Wheat_Mo!O336 -> 0 | AA6: =Wheat_Mo!O351 -> 0
A7: Wheat
A8: Wheat | B8: Beginning Stocks | C8: KMT | D8: =Wheat_Mo!P8 -> 19.111 | E8: =Wheat_Mo!P23 -> 21.0167 | F8: =Wheat_Mo!P38 -> 17.9002 | G8: =Wheat_Mo!P53 -> 36.362107 | H8: =Wheat_Mo!P68 -> 56.090804 | I8: =Wheat_Mo!P83 -> 24249.4 | J8: =Wheat_Mo!P98 -> 14948.6 | K8: =Wheat_Mo!P113 -> 12352.3 | L8: =Wheat_Mo!P128 -> 49.984 | M8: =Wheat_Mo!P143 -> 2742 | N8: =Wheat_Mo!P158 -> 2781.8 | O8: =Wheat_Mo!P173 -> 783 | P8: =Wheat_Mo!P188 -> 0 | Q8: =Wheat_Mo!P203 -> 0 | R8: =Wheat_Mo!P218 -> 3539.4 | S8: =Wheat_Mo!P233 -> 3674.5 | T8: =Wheat_Mo!P248 -> 4654.2 | U8: =Wheat_Mo!P263 -> 5793.688 | V8: =Wheat_Mo!P278 -> 0 | X8: =Wheat_Mo!P308 -> 0 | Y8: =Wheat_Mo!P323 -> 0 | Z8: =Wheat_Mo!P338 -> 0 | AA8: =Wheat_Mo!P353 -> 0
A9: Wheat | B9: Imports | C9: KMT | D9: =Wheat_Mo!P9 -> 19.2571 | E9: =Wheat_Mo!P24 -> 20.4091 | F9: =Wheat_Mo!P39 -> 16.4159 | G9: =Wheat_Mo!P54 -> 45.198136 | H9: =Wheat_Mo!P69 -> 52.100725 | I9: =Wheat_Mo!P84 -> 22258.7 | J9: =Wheat_Mo!P99 -> 12682.1 | K9: =Wheat_Mo!P114 -> 20476.1 | L9: =Wheat_Mo!P129 -> 153.567 | M9: =Wheat_Mo!P144 -> 2703 | N9: =Wheat_Mo!P159 -> 2870.6 | O9: =Wheat_Mo!P174 -> 879 | P9: =Wheat_Mo!P189 -> 0 | Q9: =Wheat_Mo!P204 -> 0 | R9: =Wheat_Mo!P219 -> 3286.4 | S9: =Wheat_Mo!P234 -> 4343.8 | T9: =Wheat_Mo!P249 -> 5194.3 | U9: =Wheat_Mo!P264 -> 4445.797 | V9: =Wheat_Mo!P279 -> 0 | W9: =Wheat_Mo!P294 -> 0 | X9: =Wheat_Mo!P309 -> 0 | Y9: =Wheat_Mo!P324 -> 0 | Z9: =Wheat_Mo!P339 -> 0 | AA9: =Wheat_Mo!P354 -> 0
A10: Wheat | B10: Production | C10: KMT | D10: =Wheat_Mo!P10 -> 17.9841 | E10: =Wheat_Mo!P25 -> 15.9745 | F10: =Wheat_Mo!P40 -> 17.0386 | G10: =Wheat_Mo!P55 -> 43.123955 | H10: =Wheat_Mo!P70 -> 54.352309 | I10: =Wheat_Mo!P85 -> 24378.1 | J10: =Wheat_Mo!P100 -> 14966.4 | K10: =Wheat_Mo!P115 -> 21783.8 | L10: =Wheat_Mo!P130 -> 95.714 | M10: =Wheat_Mo!P145 -> 2628.3 | N10: =Wheat_Mo!P160 -> 2866.3 | O10: =Wheat_Mo!P175 -> 801 | P10: =Wheat_Mo!P190 -> 0 | Q10: =Wheat_Mo!P205 -> 0 | R10: =Wheat_Mo!P220 -> 3426.7 | S10: =Wheat_Mo!P235 -> 4521.4 | T10: =Wheat_Mo!P250 -> 4785.5 | U10: =Wheat_Mo!P265 -> 3985.236 | V10: =Wheat_Mo!P280 -> 0 | W10: =Wheat_Mo!P295 -> 0 | X10: =Wheat_Mo!P310 -> 0 | Y10: =Wheat_Mo!P325 -> 0 | Z10: =Wheat_Mo!P340 -> 0 | AA10: =Wheat_Mo!P355 -> 0
A11: Wheat
A12: Wheat | B12: Food | C12: KMT | D12: =Wheat_Mo!P12 -> 19.0678 | E12: =Wheat_Mo!P27 -> 18.1311 | F12: =Wheat_Mo!P42 -> 19.1602 | G12: =Wheat_Mo!P57 -> 45.09991 | H12: =Wheat_Mo!P72 -> 18837 | I12: =Wheat_Mo!P87 -> 26567.1 | J12: =Wheat_Mo!P102 -> 12880.9 | K12: =Wheat_Mo!P117 -> 172.652 | L12: =Wheat_Mo!P132 -> 76.114 | M12: =Wheat_Mo!P147 -> 2569.8 | N12: =Wheat_Mo!P162 -> 2944.5 | O12: =Wheat_Mo!P177 -> 730 | P12: =Wheat_Mo!P192 -> 0 | Q12: =Wheat_Mo!P207 -> 0 | R12: =Wheat_Mo!P222 -> 3309.4 | S12: =Wheat_Mo!P237 -> 2775.8 | T12: =Wheat_Mo!P252 -> 3874.4 | U12: =Wheat_Mo!P267 -> 6197.487 | V12: =Wheat_Mo!P282 -> 0 | W12: =Wheat_Mo!P297 -> 0 | X12: =Wheat_Mo!P312 -> 0 | Y12: =Wheat_Mo!P327 -> 0 | Z12: =Wheat_Mo!P342 -> 0 | AA12: =Wheat_Mo!P357 -> 0
A13: Wheat | B13: Industrial | C13: KMT | D13: =Wheat_Mo!P13 -> 21.2865 | E13: =Wheat_Mo!P28 -> 17.6074 | F13: =Wheat_Mo!P43 -> 19.0832 | G13: =Wheat_Mo!P58 -> 44.116781 | H13: =Wheat_Mo!P73 -> 19994.1 | I13: =Wheat_Mo!P88 -> 27652.8 | J13: =Wheat_Mo!P103 -> 13916.2 | K13: =Wheat_Mo!P118 -> 16.312 | L13: =Wheat_Mo!P133 -> 95.118 | M13: =Wheat_Mo!P148 -> 2539.1 | N13: =Wheat_Mo!P163 -> 109 | O13: =Wheat_Mo!P178 -> 563 | P13: =Wheat_Mo!P193 -> 0 | Q13: =Wheat_Mo!P208 -> 0 | R13: =Wheat_Mo!P223 -> 3262.5 | S13: =Wheat_Mo!P238 -> 3917.1 | T13: =Wheat_Mo!P253 -> 4683.8 | U13: =Wheat_Mo!P268 -> 4151.001 | V13: =Wheat_Mo!P283 -> 0 | W13: =Wheat_Mo!P298 -> 0 | X13: =Wheat_Mo!P313 -> 0 | Y13: =Wheat_Mo!P328 -> 0 | Z13: =Wheat_Mo!P343 -> 0 | AA13: =Wheat_Mo!P358 -> 0
A14: Wheat | B14: FSR | C14: KMT | D14: =Wheat_Mo!P14 -> 19.6078 | E14: =Wheat_Mo!P29 -> 20.1745 | F14: =Wheat_Mo!P44 -> 17.218082 | G14: =Wheat_Mo!P59 -> 54.751125 | H14: =Wheat_Mo!P74 -> 19833.5 | I14: =Wheat_Mo!P89 -> 28866 | J14: =Wheat_Mo!P104 -> 15332.7 | K14: =Wheat_Mo!P119 -> 13.274 | L14: =Wheat_Mo!P134 -> 178.637 | M14: =Wheat_Mo!P149 -> 2491.4 | N14: =Wheat_Mo!P164 -> 119 | O14: =Wheat_Mo!P179 -> 499.5 | P14: =Wheat_Mo!P194 -> 0 | Q14: =Wheat_Mo!P209 -> 2796.4 | R14: =Wheat_Mo!P224 -> 3211.7 | S14: =Wheat_Mo!P239 -> 3297.8 | T14: =Wheat_Mo!P254 -> 3798.6 | U14: =Wheat_Mo!P269 -> 5181.894 | V14: =Wheat_Mo!P284 -> 0 | W14: =Wheat_Mo!P299 -> 0 | X14: =Wheat_Mo!P314 -> 0 | Y14: =Wheat_Mo!P329 -> 0 | Z14: =Wheat_Mo!P344 -> 0 | AA14: =Wheat_Mo!P359 -> 0
A15: Wheat | B15: Exports | C15: KMT | D15: =Wheat_Mo!P15 -> 18.3973 | E15: =Wheat_Mo!P30 -> 16.5812 | F15: =Wheat_Mo!P45 -> 19.0551 | G15: =Wheat_Mo!P60 -> 47.100415 | H15: =Wheat_Mo!P75 -> 21919.2 | I15: =Wheat_Mo!P90 -> 19389.66 | J15: =Wheat_Mo!P105 -> 18426.4 | K15: =Wheat_Mo!P120 -> 22.732 | L15: =Wheat_Mo!P135 -> 128.711 | M15: =Wheat_Mo!P150 -> 2503.4 | N15: =Wheat_Mo!P165 -> 134 | O15: =Wheat_Mo!P180 -> 565.3 | P15: =Wheat_Mo!P195 -> 0 | Q15: =Wheat_Mo!P210 -> 2775 | R15: =Wheat_Mo!P225 -> 3293.6 | S15: =Wheat_Mo!P240 -> 3321.7 | T15: =Wheat_Mo!P255 -> 4106.552 | U15: =Wheat_Mo!P270 -> 5336.108 | V15: =Wheat_Mo!P285 -> 0 | W15: =Wheat_Mo!P300 -> 0 | X15: =Wheat_Mo!P315 -> 0 | Y15: =Wheat_Mo!P330 -> 0 | Z15: =Wheat_Mo!P345 -> 0 | AA15: =Wheat_Mo!P360 -> 0
A16: Wheat
A17: Wheat | B17: Ending Stocks | C17: KMT | D17: =Wheat_Mo!P17 -> 17.3463 | E17: =Wheat_Mo!P32 -> 18.3619 | F17: =Wheat_Mo!P47 -> 19.9824 | G17: =Wheat_Mo!P62 -> 54.565488 | H17: =Wheat_Mo!P77 -> 23099.9 | I17: =Wheat_Mo!P92 -> 29166.662 | J17: =Wheat_Mo!P107 -> 17190.8 | K17: =Wheat_Mo!P122 -> 20.478 | L17: =Wheat_Mo!P137 -> 63.799 | M17: =Wheat_Mo!P152 -> 2474.9 | N17: =Wheat_Mo!P167 -> 411 | O17: =Wheat_Mo!P182 -> 379.7 | P17: =Wheat_Mo!P197 -> 0 | Q17: =Wheat_Mo!P212 -> 2920 | R17: =Wheat_Mo!P227 -> 3265.1 | S17: =Wheat_Mo!P242 -> 4498.9 | T17: =Wheat_Mo!P257 -> 5435.038 | U17: =Wheat_Mo!P272 -> 4843.063 | V17: =Wheat_Mo!P287 -> 0 | W17: =Wheat_Mo!P302 -> 0 | X17: =Wheat_Mo!P317 -> 0 | Y17: =Wheat_Mo!P332 -> 0 | Z17: =Wheat_Mo!P347 -> 0 | AA17: =Wheat_Mo!P362 -> 0
A18: Wheat | B18: Stocks-to-Use | C18: %
A19: Wheat | B19: STU Days | C19: Days
A20: Wheat | B20: CHECK | C20: KMT | D20: =D8+D10+D9-D12-D13-D14-D15-D17 -> -39.3535 | E20: =E8+E10+E9-E12-E13-E14-E15-E17 -> -33.4558 | F20: =F8+F10+F9-F12-F13-F14-F15-F17 -> -43.144282 | G20: =G8+G10+G9-G12-G13-G14-G15-G17 -> -120.94952 | H20: =H8+H10+H9-H12-H13-H14-H15-H17 -> -103521.16 | I20: =I8+I10+I9-I12-I13-I14-I15-I17 -> -60756.022 | J20: =J8+J10+J9-J12-J13-J14-J15-J17 -> -35149.9 | K20: =K8+K10+K9-K12-K13-K14-K15-K17 -> 54366.752 | ... AA20: =AA8+AA10+AA9-AA12-AA13-AA14-AA15-AA17 -> 0

Sheet Durum_Yr
A1: Durum
A2: Commodity | B2: Metric | C2: Unit | D2: 2002-03 | E2: 2003-04 | F2: 2004-05 | G2: 2005-06 | H2: 2006-07 | I2: 2007-08 | J2: 2008-09 | K2: 2009-10 | L2: 2010-11 | M2: 2011-12 | N2: 2012-13 | O2: 2013-14 | P2: 2014-15 | Q2: 2015-16 | R2: 2016-17 | S2: 2017-18 | T2: 2018-19 | U2: 2019-20 | V2: 2020-21 | W2: 2021-22 | X2: 2022-23 | Y2: 2023-24 | Z2: 2024-25 | AA2: 2025-26
A3: Durum | B3: Planted Area | C3: MLN AC | D3: =Durum_Mo!P3 -> 0 | E3: =Durum_Mo!P18 -> 0 | F3: =Durum_Mo!P33 -> 0 | G3: =Durum_Mo!P48 -> 0 | H3: =Durum_Mo!P63 -> 0 | I3: =Durum_Mo!P78 -> 0 | J3: =Durum_Mo!P93 -> 0 | K3: =Durum_Mo!P108 -> 0 | L3: =Durum_Mo!P123 -> 0 | M3: =Durum_Mo!P138 -> 0 | N3: =Durum_Mo!P153 -> 0 | O3: =Durum_Mo!P168 -> 0 | P3: =Durum_Mo!P183 -> 0 | Q3: =Durum_Mo!P198 -> 0 | R3: =Durum_Mo!P213 -> 0 | S3: =Durum_Mo!P228 -> 0 | T3: =Durum_Mo!P243 -> 0 | U3: =Durum_Mo!P258 -> 0 | V3: =Durum_Mo!P273 -> 0 | W3: =Durum_Mo!P288 -> 0 | X3: =Durum_Mo!P303 -> 0 | Y3: =Durum_Mo!P318 -> 0 | Z3: =Durum_Mo!P333 -> 0 | AA3: =Durum_Mo!P348 -> 0
A4: Durum | B4: Harvested Area | C4: MLN AC | D4: =Durum_Mo!P4 -> 0 | E4: =Durum_Mo!P19 -> 0 | F4: =Durum_Mo!P34 -> 0 | G4: =Durum_Mo!P49 -> 0 | H4: =Durum_Mo!P64 -> 0 | I4: =Durum_Mo!P79 -> 0 | J4: =Durum_Mo!P94 -> 0 | K4: =Durum_Mo!P109 -> 0 | L4: =Durum_Mo!P124 -> 0 | M4: =Durum_Mo!P139 -> 0 | N4: =Durum_Mo!P154 -> 0 | O4: =Durum_Mo!P169 -> 0 | P4: =Durum_Mo!P184 -> 0 | Q4: =Durum_Mo!P199 -> 0 | R4: =Durum_Mo!P214 -> 0 | S4: =Durum_Mo!P229 -> 0 | T4: =Durum_Mo!P244 -> 0 | U4: =Durum_Mo!P259 -> 0 | V4: =Durum_Mo!P274 -> 0 | W4: =Durum_Mo!P289 -> 0 | X4: =Durum_Mo!P304 -> 0 | Y4: =Durum_Mo!P319 -> 0 | Z4: =Durum_Mo!P334 -> 0 | AA4: =Durum_Mo!P349 -> 0
A5: Durum | B5: Proportion Harvested | C5: % | D5: =IF(D3<>0,D4/D3,"") | E5: =IF(E3<>0,E4/E3,"") | F5: =IF(F3<>0,F4/F3,"") | G5: =IF(G3<>0,G4/G3,"") | H5: =IF(H3<>0,H4/H3,"") | I5: =IF(I3<>0,I4/I3,"") | J5: =IF(J3<>0,J4/J3,"") | K5: =IF(K3<>0,K4/K3,"") | ... AA5: =IF(AA3<>0,AA4/AA3,"")
A6: Durum | B6: Yield | C6: BU/AC | D6: =Durum_Mo!O6 -> 0 | E6: =Durum_Mo!O21 -> 0 | F6: =Durum_Mo!O36 -> 0 | G6: =Durum_Mo!O51 -> 0 | H6: =Durum_Mo!O66 -> 0 | I6: =Durum_Mo!O81 -> 0 | J6: =Durum_Mo!O96 -> 0 | K6: =Durum_Mo!O111 -> 0 | L6: =Durum_Mo!O126 -> 0 | M6: =Durum_Mo!O141 -> 0 | N6: =Durum_Mo!O156 -> 0 | O6: =Durum_Mo!O171 -> 0 | P6: =Durum_Mo!O186 -> 0 | Q6: =Durum_Mo!O201 -> 0 | R6: =Durum_Mo!O216 -> 0 | S6: =Durum_Mo!O231 -> 0 | T6: =Durum_Mo!O246 -> 0 | U6: =Durum_Mo!O261 -> 0 | V6: =Durum_Mo!O276 -> 0 | W6: =Durum_Mo!O291 -> 0 | X6: =Durum_Mo!O306 -> 0 | Y6: =Durum_Mo!O321 -> 0 | Z6: =Durum_Mo!O336 -> 0 | AA6: =Durum_Mo!O351 -> 0
A7: Durum
A8: Durum | B8: Beginning Stocks | C8: KMT | D8: =Durum_Mo!P8 -> 14.7 | E8: =Durum_Mo!P23 -> 2.3 | F8: =Durum_Mo!P38 -> 1.6 | G8: =Durum_Mo!P53 -> 7.2 | H8: =Durum_Mo!P68 -> 1.6 | I8: =Durum_Mo!P83 -> 6.9 | J8: =Durum_Mo!P98 -> 5.7 | K8: =Durum_Mo!P113 -> 5.5 | L8: =Durum_Mo!P128 -> 93.4 | M8: =Durum_Mo!P143 -> 43 | N8: =Durum_Mo!P158 -> 104.8 | O8: =Durum_Mo!P173 -> 9.3 | P8: =Durum_Mo!P188 -> 17.1 | Q8: =Durum_Mo!P203 -> 32.1 | R8: =Durum_Mo!P218 -> 18.3 | S8: =Durum_Mo!P233 -> 11.3 | T8: =Durum_Mo!P248 -> 41.5 | U8: =Durum_Mo!P263 -> 236.5 | V8: =Durum_Mo!P278 -> 32.6 | W8: =Durum_Mo!P293 -> 22.1 | X8: =Durum_Mo!P308 -> 2.6 | Y8: =Durum_Mo!P323 -> 10.3 | Z8: =Durum_Mo!P338 -> 7.1 | AA8: =Durum_Mo!P353 -> 0
A9: Durum | B9: Imports | C9: KMT | D9: =Durum_Mo!P9 -> 11630.7 | E9: =Durum_Mo!P24 -> 12634.8 | F9: =Durum_Mo!P39 -> 14404.2 | G9: =Durum_Mo!P54 -> 17743.8 | H9: =Durum_Mo!P69 -> 10038.6 | I9: =Durum_Mo!P84 -> 11044.2 | J9: =Durum_Mo!P99 -> 16557.9 | K9: =Durum_Mo!P114 -> 16198.8 | L9: =Durum_Mo!P129 -> 9074.1 | M9: =Durum_Mo!P144 -> 12516.3 | N9: =Durum_Mo!P159 -> 13879.8 | O9: =Durum_Mo!P174 -> 19513.5 | P9: =Durum_Mo!P189 -> 15578.1 | Q9: =Durum_Mo!P204 -> 16166.1 | R9: =Durum_Mo!P219 -> 23285.4 | S9: =Durum_Mo!P234 -> 14886.6 | T9: =Durum_Mo!P249 -> 17354.4 | U9: =Durum_Mo!P264 -> 15051 | V9: =Durum_Mo!P279 -> 19713.6 | W9: =Durum_Mo!P294 -> 9097.5 | X9: =Durum_Mo!P309 -> 17371.2 | Y9: =Durum_Mo!P324 -> 12740.7 | Z9: =Durum_Mo!P339 -> 19140.9 | AA9: =Durum_Mo!P354 -> 0
A10: Durum | B10: Production | C10: KMT | D10: =Durum_Mo!P10 -> 69.371667 | E10: =Durum_Mo!P25 -> 62.435 | F10: =Durum_Mo!P40 -> 63.29 | G10: =Durum_Mo!P55 -> 61.936667 | H10: =Durum_Mo!P70 -> 64.568333 | I10: =Durum_Mo!P85 -> 56.203333 | J10: =Durum_Mo!P100 -> 59.365 | K10: =Durum_Mo!P115 -> 65.505 | L10: =Durum_Mo!P130 -> 63.263333 | M10: =Durum_Mo!P145 -> 58.081667 | N10: =Durum_Mo!P160 -> 57.916667 | O10: =Durum_Mo!P175 -> 59.168333 | P10: =Durum_Mo!P190 -> 50.04 | Q10: =Durum_Mo!P205 -> 52.376667 | R10: =Durum_Mo!P220 -> 43.588333 | S10: =Durum_Mo!P235 -> 50.371667 | T10: =Durum_Mo!P250 -> 51.108333 | U10: =Durum_Mo!P265 -> 54.166667 | V10: =Durum_Mo!P280 -> 49.595 | W10: =Durum_Mo!P295 -> 52.735 | X10: =Durum_Mo!P310 -> 49.371667 | Y10: =Durum_Mo!P325 -> 48.043333 | Z10: =Durum_Mo!P340 -> 50.623333 | AA10: =Durum_Mo!P355 -> 0
A11: Durum
A12: Durum | B12: Food | C12: KMT | D12: =Durum_Mo!P12 -> 10805.708 | E12: =Durum_Mo!P27 -> 11579.628 | F12: =Durum_Mo!P42 -> 12861.067 | G12: =Durum_Mo!P57 -> 15844.657 | H12: =Durum_Mo!P72 -> 10923.428 | I12: =Durum_Mo!P87 -> 10661.127 | J12: =Durum_Mo!P102 -> 14398.197 | K12: =Durum_Mo!P117 -> 14503.097 | L12: =Durum_Mo!P132 -> 9439.465 | M12: =Durum_Mo!P147 -> 11694.338 | N12: =Durum_Mo!P162 -> 13252.672 | O12: =Durum_Mo!P177 -> 17577.985 | P12: =Durum_Mo!P192 -> 15029.968 | Q12: =Durum_Mo!P207 -> 14867.915 | R12: =Durum_Mo!P222 -> 21386.72 | S12: =Durum_Mo!P237 -> 14097.537 | T12: =Durum_Mo!P252 -> 15852.237 | U12: =Durum_Mo!P267 -> 15005.278 | V12: =Durum_Mo!P282 -> 18157.303 | W12: =Durum_Mo!P297 -> 8635.715 | X12: =Durum_Mo!P312 -> 16023.635 | Y12: =Durum_Mo!P327 -> 11690.798 | Z12: =Durum_Mo!P342 -> 17785.512 | AA12: =Durum_Mo!P357 -> 0
A13: Durum | B13: Industrial | C13: KMT | D13: =Durum_Mo!P13 -> 706.62 | E13: =Durum_Mo!P28 -> 829.53667 | F13: =Durum_Mo!P43 -> 768.64333 | G13: =Durum_Mo!P58 -> 1057.9067 | H13: =Durum_Mo!P73 -> 1068.8033 | I13: =Durum_Mo!P88 -> 781.87 | J13: =Durum_Mo!P103 -> 911.63833 | K13: =Durum_Mo!P118 -> 944.89833 | L13: =Durum_Mo!P133 -> 792.67167 | M13: =Durum_Mo!P148 -> 886.78 | N13: =Durum_Mo!P163 -> 1033.2117 | O13: =Durum_Mo!P178 -> 1273.6467 | P13: =Durum_Mo!P193 -> 1277.9917 | Q13: =Durum_Mo!P208 -> 1153.7083 | R13: =Durum_Mo!P223 -> 1145.6917 | S13: =Durum_Mo!P238 -> 1101.8917 | T13: =Durum_Mo!P253 -> 1136.355 | U13: =Durum_Mo!P268 -> 1323.755 | V13: =Durum_Mo!P283 -> 1462.9017 | W13: =Durum_Mo!P298 -> 657.65 | X13: =Durum_Mo!P313 -> 1315.0933 | Y13: =Durum_Mo!P328 -> 915.45833 | Z13: =Durum_Mo!P343 -> 1468.865 | AA13: =Durum_Mo!P358 -> 0
A14: Durum | B14: FSR | C14: KMT | D14: =Durum_Mo!P14 -> 8407.4 | E14: =Durum_Mo!P29 -> 8819.4 | F14: =Durum_Mo!P44 -> 11480.6 | G14: =Durum_Mo!P59 -> 14873.1 | H14: =Durum_Mo!P74 -> 8483.7 | I14: =Durum_Mo!P89 -> 5851.6 | J14: =Durum_Mo!P104 -> 10778.5 | K14: =Durum_Mo!P119 -> 12965.8 | L14: =Durum_Mo!P134 -> 8287 | M14: =Durum_Mo!P149 -> 8568.1 | N14: =Durum_Mo!P164 -> 8054.4 | O14: =Durum_Mo!P179 -> 10980 | P14: =Durum_Mo!P194 -> 7620.7 | Q14: =Durum_Mo!P209 -> 8036.1 | R14: =Durum_Mo!P224 -> 12046.4 | S14: =Durum_Mo!P239 -> 9621.1 | T14: =Durum_Mo!P254 -> 11509 | U14: =Durum_Mo!P269 -> 8702.8 | V14: =Durum_Mo!P284 -> 8622.9 | W14: =Durum_Mo!P299 -> 5023.6 | X14: =Durum_Mo!P314 -> 6971 | Y14: =Durum_Mo!P329 -> 6145.5 | Z14: =Durum_Mo!P344 -> 7896.4 | AA14: =Durum_Mo!P359 -> 0
A15: Durum | B15: Exports | C15: KMT | D15: =Durum_Mo!P15 -> 0 | E15: =Durum_Mo!P30 -> 0 | F15: =Durum_Mo!P45 -> 0 | G15: =Durum_Mo!P60 -> 0 | H15: =Durum_Mo!P75 -> 0 | I15: =Durum_Mo!P90 -> 0 | J15: =Durum_Mo!P105 -> 0 | K15: =Durum_Mo!P120 -> 0 | L15: =Durum_Mo!P135 -> 0 | M15: =Durum_Mo!P150 -> 0 | N15: =Durum_Mo!P165 -> 0 | O15: =Durum_Mo!P180 -> 0 | P15: =Durum_Mo!P195 -> 0 | Q15: =Durum_Mo!P210 -> 0 | R15: =Durum_Mo!P225 -> 0 | S15: =Durum_Mo!P240 -> 0 | T15: =Durum_Mo!P255 -> 0 | U15: =Durum_Mo!P270 -> 0 | V15: =Durum_Mo!P285 -> 0 | W15: =Durum_Mo!P300 -> 0 | X15: =Durum_Mo!P315 -> 0 | Y15: =Durum_Mo!P330 -> 0 | Z15: =Durum_Mo!P345 -> 0 | AA15: =Durum_Mo!P360 -> 0
A16: Durum
A17: Durum | B17: Ending Stocks | C17: KMT | D17: =Durum_Mo!P17 -> 0 | E17: =Durum_Mo!P32 -> 9.094947e-13 | F17: =Durum_Mo!P47 -> -9.094947e-13 | G17: =Durum_Mo!P62 -> -4.5474735e-13 | H17: =Durum_Mo!P77 -> 6.8212103e-13 | I17: =Durum_Mo!P92 -> -1.2505552e-12 | J17: =Durum_Mo!P107 -> 1.5916157e-12 | K17: =Durum_Mo!P122 -> 0 | L17: =Durum_Mo!P137 -> -4.5474735e-13 | M17: =Durum_Mo!P152 -> -9.094947e-13 | N17: =Durum_Mo!P167 -> 6.8212103e-13 | O17: =Durum_Mo!P182 -> 9.094947e-13 | P17: =Durum_Mo!P197 -> 5.6843419e-13 | Q17: =Durum_Mo!P212 -> 2.2737368e-13 | R17: =Durum_Mo!P227 -> 6.8212103e-13 | S17: =Durum_Mo!P242 -> 0 | T17: =Durum_Mo!P257 -> 2.2737368e-13 | U17: =Durum_Mo!P272 -> -1.5916157e-12 | V17: =Durum_Mo!P287 -> 3.4106051e-13 | W17: =Durum_Mo!P302 -> -3.4106051e-13 | X17: =Durum_Mo!P317 -> -4.5474735e-13 | Y17: =Durum_Mo!P332 -> 0 | Z17: =Durum_Mo!P347 -> 3.4106051e-13 | AA17: =Durum_Mo!P362 -> 0
A18: Durum | B18: Stocks-to-Use | C18: %
A19: Durum | B19: STU Days | C19: Days
A20: Durum | B20: CHECK | C20: KMT | D20: =D8+D10+D9-D12-D13-D14-D15-D17 -> -8204.9567 | E20: =E8+E10+E9-E12-E13-E14-E15-E17 -> -8529.03 | F20: =F8+F10+F9-F12-F13-F14-F15-F17 -> -10641.22 | G20: =G8+G10+G9-G12-G13-G14-G15-G17 -> -13962.727 | H20: =H8+H10+H9-H12-H13-H14-H15-H17 -> -10371.163 | I20: =I8+I10+I9-I12-I13-I14-I15-I17 -> -6187.2933 | J20: =J8+J10+J9-J12-J13-J14-J15-J17 -> -9465.37 | K20: =K8+K10+K9-K12-K13-K14-K15-K17 -> -12143.99 | ... AA20: =AA8+AA10+AA9-AA12-AA13-AA14-AA15-AA17 -> 0

Sheet Canola_Yr
A1: Canola
A2: Commodity | B2: Metric | C2: Unit | D2: 2002-03 | E2: 2003-04 | F2: 2004-05 | G2: 2005-06 | H2: 2006-07 | I2: 2007-08 | J2: 2008-09 | K2: 2009-10 | L2: 2010-11 | M2: 2011-12 | N2: 2012-13 | O2: 2013-14 | P2: 2014-15 | Q2: 2015-16 | R2: 2016-17 | S2: 2017-18 | T2: 2018-19 | U2: 2019-20 | V2: 2020-21 | W2: 2021-22 | X2: 2022-23 | Y2: 2023-24 | Z2: 2024-25 | AA2: 2025-26
A3: Canola | B3: Planted Area | C3: MLN AC | D3: =Canola_Mo!P3 -> 0 | E3: =Canola_Mo!P18 -> 0 | F3: =Canola_Mo!P33 -> 0 | G3: =Canola_Mo!P48 -> 0 | H3: =Canola_Mo!P63 -> 0 | I3: =Canola_Mo!P78 -> 0 | J3: =Canola_Mo!P93 -> 0 | K3: =Canola_Mo!P108 -> 0 | L3: =Canola_Mo!P123 -> 0 | M3: =Canola_Mo!P138 -> 0 | N3: =Canola_Mo!P153 -> 0 | O3: =Canola_Mo!P168 -> 0 | P3: =Canola_Mo!P183 -> 0 | Q3: =Canola_Mo!P198 -> 0 | R3: =Canola_Mo!P213 -> 0 | S3: =Canola_Mo!P228 -> 0 | T3: =Canola_Mo!P243 -> 0 | U3: =Canola_Mo!P258 -> 0 | V3: =Canola_Mo!P273 -> 0 | W3: =Canola_Mo!P288 -> 0 | X3: =Canola_Mo!P303 -> 0 | Y3: =Canola_Mo!P318 -> 0 | Z3: =Canola_Mo!P333 -> 0 | AA3: =Canola_Mo!P348 -> 0
A4: Canola | B4: Harvested Area | C4: MLN AC | D4: =Canola_Mo!P4 -> 0 | E4: =Canola_Mo!P19 -> 0 | F4: =Canola_Mo!P34 -> 0 | G4: =Canola_Mo!P49 -> 0 | H4: =Canola_Mo!P64 -> 0 | I4: =Canola_Mo!P79 -> 0 | J4: =Canola_Mo!P94 -> 0 | K4: =Canola_Mo!P109 -> 0 | L4: =Canola_Mo!P124 -> 0 | M4: =Canola_Mo!P139 -> 0 | N4: =Canola_Mo!P154 -> 0 | O4: =Canola_Mo!P169 -> 0 | P4: =Canola_Mo!P184 -> 0 | Q4: =Canola_Mo!P199 -> 0 | R4: =Canola_Mo!P214 -> 0 | S4: =Canola_Mo!P229 -> 0 | T4: =Canola_Mo!P244 -> 0 | U4: =Canola_Mo!P259 -> 0 | V4: =Canola_Mo!P274 -> 0 | W4: =Canola_Mo!P289 -> 0 | X4: =Canola_Mo!P304 -> 0 | Y4: =Canola_Mo!P319 -> 0 | Z4: =Canola_Mo!P334 -> 0 | AA4: =Canola_Mo!P349 -> 0
A5: Canola | B5: Proportion Harvested | C5: % | D5: =IF(D3<>0,D4/D3,"") | E5: =IF(E3<>0,E4/E3,"") | F5: =IF(F3<>0,F4/F3,"") | G5: =IF(G3<>0,G4/G3,"") | H5: =IF(H3<>0,H4/H3,"") | I5: =IF(I3<>0,I4/I3,"") | J5: =IF(J3<>0,J4/J3,"") | K5: =IF(K3<>0,K4/K3,"") | ... AA5: =IF(AA3<>0,AA4/AA3,"")
A6: Canola | B6: Yield | C6: BU/AC | D6: =Canola_Mo!O6 -> 0 | E6: =Canola_Mo!O21 -> 0 | F6: =Canola_Mo!O36 -> 0 | G6: =Canola_Mo!O51 -> 0 | H6: =Canola_Mo!O66 -> 0 | I6: =Canola_Mo!O81 -> 0 | J6: =Canola_Mo!O96 -> 0 | K6: =Canola_Mo!O111 -> 0 | L6: =Canola_Mo!O126 -> 0 | M6: =Canola_Mo!O141 -> 0 | N6: =Canola_Mo!O156 -> 0 | O6: =Canola_Mo!O171 -> 0 | P6: =Canola_Mo!O186 -> 0 | Q6: =Canola_Mo!O201 -> 0 | R6: =Canola_Mo!O216 -> 0 | S6: =Canola_Mo!O231 -> 0 | T6: =Canola_Mo!O246 -> 0 | U6: =Canola_Mo!O261 -> 0 | V6: =Canola_Mo!O276 -> 0 | W6: =Canola_Mo!O291 -> 0 | X6: =Canola_Mo!O306 -> 0 | Y6: =Canola_Mo!O321 -> 0 | Z6: =Canola_Mo!O336 -> 0 | AA6: =Canola_Mo!O351 -> 0
A7: Canola
A8: Canola | B8: Beginning Stocks | C8: KMT | D8: =Canola_Mo!P8 -> 239.6 | E8: =Canola_Mo!P23 -> 242.6 | F8: =Canola_Mo!P38 -> 107.6 | G8: =Canola_Mo!P53 -> 139.5 | H8: =Canola_Mo!P68 -> 203 | I8: =Canola_Mo!P83 -> 178.8 | J8: =Canola_Mo!P98 -> 120.5 | K8: =Canola_Mo!P113 -> 127.9 | L8: =Canola_Mo!P128 -> 223.7 | M8: =Canola_Mo!P143 -> 96.6 | N8: =Canola_Mo!P158 -> 127.6 | O8: =Canola_Mo!P173 -> 66.1 | P8: =Canola_Mo!P188 -> 76.6 | Q8: =Canola_Mo!P203 -> 105 | R8: =Canola_Mo!P218 -> 94.5 | S8: =Canola_Mo!P233 -> 108 | T8: =Canola_Mo!P248 -> 146.5 | U8: =Canola_Mo!P263 -> 132.5 | V8: =Canola_Mo!P278 -> 125.1 | W8: =Canola_Mo!P293 -> 104.7 | X8: =Canola_Mo!P308 -> 151.3 | Y8: =Canola_Mo!P323 -> 276.1 | Z8: =Canola_Mo!P338 -> 130.9 | AA8: =Canola_Mo!P353 -> 0
A9: Canola | B9: Imports | C9: KMT | D9: =Canola_Mo!P9 -> 5354.377 | E9: =Canola_Mo!P24 -> 8040.227 | F9: =Canola_Mo!P39 -> 8813.372 | G9: =Canola_Mo!P54 -> 10810.186 | H9: =Canola_Mo!P69 -> 10422.269 | I9: =Canola_Mo!P84 -> 11205.519 | J9: =Canola_Mo!P99 -> 14325.129 | K9: =Canola_Mo!P114 -> 14783.971 | L9: =Canola_Mo!P129 -> 15310.095 | M9: =Canola_Mo!P144 -> 17474.063 | N9: =Canola_Mo!P159 -> 16567.434 | O9: =Canola_Mo!P174 -> 21294.014 | P9: =Canola_Mo!P189 -> 19308.624 | Q9: =Canola_Mo!P204 -> 21646.226 | R9: =Canola_Mo!P219 -> 23288.92 | S9: =Canola_Mo!P234 -> 25221.42 | T9: =Canola_Mo!P249 -> 24397.469 | U9: =Canola_Mo!P264 -> 23991.072 | V9: =Canola_Mo!P279 -> 23650.531 | W9: =Canola_Mo!P294 -> 17496.347 | X9: =Canola_Mo!P309 -> 22597.472 | Y9: =Canola_Mo!P324 -> 23735.093 | Z9: =Canola_Mo!P339 -> 23651.996 | AA9: =Canola_Mo!P354 -> 0
A10: Canola | B10: Production | C10: KMT | D10: =Canola_Mo!P10 -> 0 | E10: =Canola_Mo!P25 -> 0 | F10: =Canola_Mo!P40 -> 0 | G10: =Canola_Mo!P55 -> 0 | H10: =Canola_Mo!P70 -> 0 | I10: =Canola_Mo!P85 -> 0 | J10: =Canola_Mo!P100 -> 0 | K10: =Canola_Mo!P115 -> 0 | L10: =Canola_Mo!P130 -> 0 | M10: =Canola_Mo!P145 -> 0 | N10: =Canola_Mo!P160 -> 0 | O10: =Canola_Mo!P175 -> 0 | P10: =Canola_Mo!P190 -> 0 | Q10: =Canola_Mo!P205 -> 0 | R10: =Canola_Mo!P220 -> 0 | S10: =Canola_Mo!P235 -> 0 | T10: =Canola_Mo!P250 -> 0 | U10: =Canola_Mo!P265 -> 0 | V10: =Canola_Mo!P280 -> 0 | W10: =Canola_Mo!P295 -> 0 | X10: =Canola_Mo!P310 -> 0 | Y10: =Canola_Mo!P325 -> 0 | Z10: =Canola_Mo!P340 -> 0 | AA10: =Canola_Mo!P355 -> 0
A11: Canola
A12: Canola | B12: Food | C12: KMT | D12: =Canola_Mo!P12 -> 31755.05 | E12: =Canola_Mo!P27 -> 38009.2 | F12: =Canola_Mo!P42 -> 41541.5 | G12: =Canola_Mo!P57 -> 43311.2 | H12: =Canola_Mo!P72 -> 46545.55 | I12: =Canola_Mo!P87 -> 50653.75 | J12: =Canola_Mo!P102 -> 52915.2 | K12: =Canola_Mo!P117 -> 56944.2 | L12: =Canola_Mo!P132 -> 69879.55 | M12: =Canola_Mo!P147 -> 84234.95 | N12: =Canola_Mo!P162 -> 85450.3 | O12: =Canola_Mo!P177 -> 83634.65 | P12: =Canola_Mo!P192 -> 89486.45 | Q12: =Canola_Mo!P207 -> 11934.726 | R12: =Canola_Mo!P222 -> 13116.12 | S12: =Canola_Mo!P237 -> 13252.52 | T12: =Canola_Mo!P252 -> 13542.869 | U12: =Canola_Mo!P267 -> 15084.072 | V12: =Canola_Mo!P282 -> 14845.631 | W12: =Canola_Mo!P297 -> 12647.947 | X12: =Canola_Mo!P312 -> 14420.272 | Y12: =Canola_Mo!P327 -> 15904.693 | Z12: =Canola_Mo!P342 -> 16031.096 | AA12: =Canola_Mo!P357 -> 0
A13: Canola | B13: Crush | C13: KMT | D13: =Canola_Mo!P13 -> 2394.4 | E13: =Canola_Mo!P28 -> 3754.3 | F13: =Canola_Mo!P43 -> 3411.9 | G13: =Canola_Mo!P58 -> 5408.7 | H13: =Canola_Mo!P73 -> 5476.9 | I13: =Canola_Mo!P88 -> 5661.1 | J13: =Canola_Mo!P103 -> 7907.9 | K13: =Canola_Mo!P118 -> 7162.5 | L13: =Canola_Mo!P133 -> 7104.6 | M13: =Canola_Mo!P148 -> 8699 | N13: =Canola_Mo!P163 -> 7301.9 | O13: =Canola_Mo!P178 -> 9095.6 | P13: =Canola_Mo!P193 -> 9163.3 | Q13: =Canola_Mo!P208 -> 10299 | R13: =Canola_Mo!P223 -> 11016.4 | S13: =Canola_Mo!P238 -> 10782.9 | T13: =Canola_Mo!P253 -> 9202 | U13: =Canola_Mo!P268 -> 10039.7 | V13: =Canola_Mo!P283 -> 10588.6 | W13: =Canola_Mo!P298 -> 5245 | X13: =Canola_Mo!P313 -> 7950.1 | Y13: =Canola_Mo!P328 -> 6744.2 | Z13: =Canola_Mo!P343 -> 9379.3 | AA13: =Canola_Mo!P358 -> 0
A14: Canola | B14: FSR | C14: KMT | D14: =Canola_Mo!P14 -> -346.85633 | E14: =Canola_Mo!P29 -> -1198.7467 | F14: =Canola_Mo!P44 -> -1230.5213 | G14: =Canola_Mo!P59 -> 266.61167 | H14: =Canola_Mo!P74 -> 111.92833 | I14: =Canola_Mo!P89 -> -605.54467 | J14: =Canola_Mo!P104 -> -912.372 | K14: =Canola_Mo!P119 -> 405.601 | L14: =Canola_Mo!P134 -> -49.264667 | M14: =Canola_Mo!P149 -> -3465.6693 | N14: =Canola_Mo!P164 -> -5916.1357 | O14: =Canola_Mo!P179 -> -3088.9553 | P14: =Canola_Mo!P194 -> -1331.4023 | Q14: =Canola_Mo!P209 -> 3125.805 | R14: =Canola_Mo!P224 -> 2326.2 | S14: =Canola_Mo!P239 -> 3729.196 | T14: =Canola_Mo!P254 -> 5649.429 | U14: =Canola_Mo!P269 -> 4485.58 | V14: =Canola_Mo!P284 -> 2975.165 | W14: =Canola_Mo!P299 -> 2580.51 | X14: =Canola_Mo!P314 -> 2830.694 | Y14: =Canola_Mo!P329 -> 4141.548 | Z14: =Canola_Mo!P344 -> 2838.835 | AA14: =Canola_Mo!P359 -> 0
A15: Canola | B15: Exports | C15: KMT | D15: =Canola_Mo!P15 -> 0 | E15: =Canola_Mo!P30 -> 0 | F15: =Canola_Mo!P45 -> 0 | G15: =Canola_Mo!P60 -> 0 | H15: =Canola_Mo!P75 -> 0 | I15: =Canola_Mo!P90 -> 0 | J15: =Canola_Mo!P105 -> 0 | K15: =Canola_Mo!P120 -> 0 | L15: =Canola_Mo!P135 -> 0 | M15: =Canola_Mo!P150 -> 0 | N15: =Canola_Mo!P165 -> 0 | O15: =Canola_Mo!P180 -> 0 | P15: =Canola_Mo!P195 -> 0 | Q15: =Canola_Mo!P210 -> 0 | R15: =Canola_Mo!P225 -> 0 | S15: =Canola_Mo!P240 -> 0 | T15: =Canola_Mo!P255 -> 0 | U15: =Canola_Mo!P270 -> 0 | V15: =Canola_Mo!P285 -> 0 | W15: =Canola_Mo!P300 -> 0 | X15: =Canola_Mo!P315 -> 0 | Y15: =Canola_Mo!P330 -> 0 | Z15: =Canola_Mo!P345 -> 0 | AA15: =Canola_Mo!P360 -> 0
A16: Canola
A17: Canola | B17: Ending Stocks | C17: KMT | D17: =Canola_Mo!P17 -> -25709.417 | E17: =Canola_Mo!P32 -> -30493.526 | F17: =Canola_Mo!P47 -> -33584.707 | G17: =Canola_Mo!P62 -> -34863.626 | H17: =Canola_Mo!P77 -> -37495.109 | I17: =Canola_Mo!P92 -> -40759.786 | J17: =Canola_Mo!P107 -> -42542.099 | K17: =Canola_Mo!P122 -> -45713.43 | L17: =Canola_Mo!P137 -> -55903.69 | M17: =Canola_Mo!P152 -> -67526.018 | N17: =Canola_Mo!P167 -> -68726.23 | O17: =Canola_Mo!P182 -> -67104.981 | P17: =Canola_Mo!P197 -> -71917.124 | Q17: =Canola_Mo!P212 -> -8.3844043e-13 | R17: =Canola_Mo!P227 -> 8.0291329e-13 | S17: =Canola_Mo!P242 -> -9.6633812e-13 | T17: =Canola_Mo!P257 -> -8.3844043e-13 | U17: =Canola_Mo!P272 -> 4.6895821e-13 | V17: =Canola_Mo!P287 -> -2.8421709e-14 | W17: =Canola_Mo!P302 -> 3.9790393e-13 | X17: =Canola_Mo!P317 -> 2.8421709e-14 | Y17: =Canola_Mo!P332 -> 1.4210855e-14 | Z17: =Canola_Mo!P347 -> -6.3948846e-13 | AA17: =Canola_Mo!P362 -> 0
A18: Canola | B18: Stocks-to-Use | C18: %
A19: Canola | B19: STU Days | C19: Days
A20: Canola | B20: CHECK | C20: KMT

Sheet Barley_Yr
A1: Barley
A2: Commodity | B2: Metric | C2: Unit | D2: 2002-03 | E2: 2003-04 | F2: 2004-05 | G2: 2005-06 | H2: 2006-07 | I2: 2007-08 | J2: 2008-09 | K2: 2009-10 | L2: 2010-11 | M2: 2011-12 | N2: 2012-13 | O2: 2013-14 | P2: 2014-15 | Q2: 2015-16 | R2: 2016-17 | S2: 2017-18 | T2: 2018-19 | U2: 2019-20 | V2: 2020-21 | W2: 2021-22 | X2: 2022-23 | Y2: 2023-24 | Z2: 2024-25 | AA2: 2025-26
A3: Barley | B3: Planted Area | C3: MLN AC | D3: =Barley_Mo!P3 -> 0 | E3: =Barley_Mo!P18 -> 0 | F3: =Barley_Mo!P33 -> 0 | G3: =Barley_Mo!P48 -> 0 | H3: =Barley_Mo!P63 -> 0 | I3: =Barley_Mo!P78 -> 0 | J3: =Barley_Mo!P93 -> 0 | K3: =Barley_Mo!P108 -> 0 | L3: =Barley_Mo!P123 -> 0 | M3: =Barley_Mo!P138 -> 0 | N3: =Barley_Mo!P153 -> 0 | O3: =Barley_Mo!P168 -> 0 | P3: =Barley_Mo!P183 -> 0 | Q3: =Barley_Mo!P198 -> 0 | R3: =Barley_Mo!P213 -> 0 | S3: =Barley_Mo!P228 -> 0 | T3: =Barley_Mo!P243 -> 0 | U3: =Barley_Mo!P258 -> 0 | V3: =Barley_Mo!P273 -> 0 | W3: =Barley_Mo!P288 -> 0 | X3: =Barley_Mo!P303 -> 0 | Y3: =Barley_Mo!P318 -> 0 | Z3: =Barley_Mo!P333 -> 0 | AA3: =Barley_Mo!P348 -> 0
A4: Barley | B4: Harvested Area | C4: MLN AC | D4: =Barley_Mo!P4 -> 0 | E4: =Barley_Mo!P19 -> 0 | F4: =Barley_Mo!P34 -> 0 | G4: =Barley_Mo!P49 -> 0 | H4: =Barley_Mo!P64 -> 0 | I4: =Barley_Mo!P79 -> 0 | J4: =Barley_Mo!P94 -> 0 | K4: =Barley_Mo!P109 -> 0 | L4: =Barley_Mo!P124 -> 0 | M4: =Barley_Mo!P139 -> 0 | N4: =Barley_Mo!P154 -> 0 | O4: =Barley_Mo!P169 -> 0 | P4: =Barley_Mo!P184 -> 0 | Q4: =Barley_Mo!P199 -> 0 | R4: =Barley_Mo!P214 -> 0 | S4: =Barley_Mo!P229 -> 0 | T4: =Barley_Mo!P244 -> 0 | U4: =Barley_Mo!P259 -> 0 | V4: =Barley_Mo!P274 -> 0 | W4: =Barley_Mo!P289 -> 0 | X4: =Barley_Mo!P304 -> 0 | Y4: =Barley_Mo!P319 -> 0 | Z4: =Barley_Mo!P334 -> 0 | AA4: =Barley_Mo!P349 -> 0
A5: Barley | B5: Proportion Harvested | C5: % | D5: =IF(D3<>0,D4/D3,"") | E5: =IF(E3<>0,E4/E3,"") | F5: =IF(F3<>0,F4/F3,"") | G5: =IF(G3<>0,G4/G3,"") | H5: =IF(H3<>0,H4/H3,"") | I5: =IF(I3<>0,I4/I3,"") | J5: =IF(J3<>0,J4/J3,"") | K5: =IF(K3<>0,K4/K3,"") | ... AA5: =IF(AA3<>0,AA4/AA3,"")
A6: Barley | B6: Yield | C6: BU/AC | D6: =Barley_Mo!O6 -> 0 | E6: =Barley_Mo!O21 -> 0 | F6: =Barley_Mo!O36 -> 0 | G6: =Barley_Mo!O51 -> 0 | H6: =Barley_Mo!O66 -> 0 | I6: =Barley_Mo!O81 -> 0 | J6: =Barley_Mo!O96 -> 0 | K6: =Barley_Mo!O111 -> 0 | L6: =Barley_Mo!O126 -> 0 | M6: =Barley_Mo!O141 -> 0 | N6: =Barley_Mo!O156 -> 0 | O6: =Barley_Mo!O171 -> 0 | P6: =Barley_Mo!O186 -> 0 | Q6: =Barley_Mo!O201 -> 0 | R6: =Barley_Mo!O216 -> 0 | S6: =Barley_Mo!O231 -> 0 | T6: =Barley_Mo!O246 -> 0 | U6: =Barley_Mo!O261 -> 0 | V6: =Barley_Mo!O276 -> 0 | W6: =Barley_Mo!O291 -> 0 | X6: =Barley_Mo!O306 -> 0 | Y6: =Barley_Mo!O321 -> 0 | Z6: =Barley_Mo!O336 -> 0 | AA6: =Barley_Mo!O351 -> 0
A7: Barley
A8: Barley | B8: Beginning Stocks | C8: KMT | D8: =Barley_Mo!P8 -> 258.8 | E8: =Barley_Mo!P23 -> 35.5 | F8: =Barley_Mo!P38 -> 82.6 | G8: =Barley_Mo!P53 -> 45.8 | H8: =Barley_Mo!P68 -> 43.6 | I8: =Barley_Mo!P83 -> 57.8 | J8: =Barley_Mo!P98 -> 41.7 | K8: =Barley_Mo!P113 -> 42.4 | L8: =Barley_Mo!P128 -> 42.7 | M8: =Barley_Mo!P143 -> 13.5 | N8: =Barley_Mo!P158 -> 19 | O8: =Barley_Mo!P173 -> 9 | P8: =Barley_Mo!P188 -> 136.1 | Q8: =Barley_Mo!P203 -> 160.9 | R8: =Barley_Mo!P218 -> 63.6 | S8: =Barley_Mo!P233 -> 58.7 | T8: =Barley_Mo!P248 -> 42.8 | U8: =Barley_Mo!P263 -> 63.1 | V8: =Barley_Mo!P278 -> 293.9 | W8: =Barley_Mo!P293 -> 227.9 | X8: =Barley_Mo!P308 -> 25.1 | Y8: =Barley_Mo!P323 -> 117.3 | Z8: =Barley_Mo!P338 -> 168.7 | AA8: =Barley_Mo!P353 -> 0
A9: Barley | B9: Imports | C9: KMT | D9: =Barley_Mo!P9 -> 7467.7 | E9: =Barley_Mo!P24 -> 12164.2 | F9: =Barley_Mo!P39 -> 12556.7 | G9: =Barley_Mo!P54 -> 11677.6 | H9: =Barley_Mo!P69 -> 9573.1 | I9: =Barley_Mo!P84 -> 10909.8 | J9: =Barley_Mo!P99 -> 11785.8 | K9: =Barley_Mo!P114 -> 9528.2 | L9: =Barley_Mo!P129 -> 7627.2 | M9: =Barley_Mo!P144 -> 7891.5 | N9: =Barley_Mo!P159 -> 8012.3 | O9: =Barley_Mo!P174 -> 10281.6 | P9: =Barley_Mo!P189 -> 7116.8 | Q9: =Barley_Mo!P204 -> 8256.6 | R9: =Barley_Mo!P219 -> 8839.4 | S9: =Barley_Mo!P234 -> 7891.3 | T9: =Barley_Mo!P249 -> 8379.7 | U9: =Barley_Mo!P264 -> 10382.6 | V9: =Barley_Mo!P279 -> 10740.6 | W9: =Barley_Mo!P294 -> 6983.9 | X9: =Barley_Mo!P309 -> 9986.7 | Y9: =Barley_Mo!P324 -> 8905.4 | Z9: =Barley_Mo!P339 -> 8143.9 | AA9: =Barley_Mo!P354 -> 0
A10: Barley | B10: Production | C10: KMT | D10: =Barley_Mo!P10 -> 6.1 | E10: =Barley_Mo!P25 -> 9 | F10: =Barley_Mo!P40 -> 9.5 | G10: =Barley_Mo!P55 -> 13.5 | H10: =Barley_Mo!P70 -> 21.5 | I10: =Barley_Mo!P85 -> 15.7 | J10: =Barley_Mo!P100 -> 15.6 | K10: =Barley_Mo!P115 -> 10.1 | L10: =Barley_Mo!P130 -> 27.9 | M10: =Barley_Mo!P145 -> 23.6 | N10: =Barley_Mo!P160 -> 24.9 | O10: =Barley_Mo!P175 -> 23.9 | P10: =Barley_Mo!P190 -> 18.4 | Q10: =Barley_Mo!P205 -> 10.2 | R10: =Barley_Mo!P220 -> 17.5 | S10: =Barley_Mo!P235 -> 21.1 | T10: =Barley_Mo!P250 -> 16.3 | U10: =Barley_Mo!P265 -> 18.3 | V10: =Barley_Mo!P280 -> 18.6 | W10: =Barley_Mo!P295 -> 17.7 | X10: =Barley_Mo!P310 -> 18.5 | Y10: =Barley_Mo!P325 -> 18.6 | Z10: =Barley_Mo!P340 -> 18.6 | AA10: =Barley_Mo!P355 -> 0
A11: Barley
A12: Barley | B12: Food | C12: KMT | D12: =Barley_Mo!P12 -> 7036.6 | E12: =Barley_Mo!P27 -> 8804.8 | F12: =Barley_Mo!P42 -> 9175.9 | G12: =Barley_Mo!P57 -> 8727.9 | H12: =Barley_Mo!P72 -> 9195.1 | I12: =Barley_Mo!P87 -> 6822.7 | J12: =Barley_Mo!P102 -> 7874.2 | K12: =Barley_Mo!P117 -> 7748.3 | L12: =Barley_Mo!P132 -> 6497.9 | M12: =Barley_Mo!P147 -> 6033 | N12: =Barley_Mo!P162 -> 5925 | O12: =Barley_Mo!P177 -> 6827 | P12: =Barley_Mo!P192 -> 5335.5 | Q12: =Barley_Mo!P207 -> 6063.5 | R12: =Barley_Mo!P222 -> 5809.5 | S12: =Barley_Mo!P237 -> 5943.1 | T12: =Barley_Mo!P252 -> 5429.1 | U12: =Barley_Mo!P267 -> 7122.1 | V12: =Barley_Mo!P282 -> 6704.3 | W12: =Barley_Mo!P297 -> 4422.3 | X12: =Barley_Mo!P312 -> 5851.9 | Y12: =Barley_Mo!P327 -> 5426.7 | Z12: =Barley_Mo!P342 -> 5280.4 | AA12: =Barley_Mo!P357 -> 0
A13: Barley | B13: Industrial | C13: KMT | D13: =Barley_Mo!P13 -> 945 | E13: =Barley_Mo!P28 -> 2480.8 | F13: =Barley_Mo!P43 -> 1863.2 | G13: =Barley_Mo!P58 -> 2975.1 | H13: =Barley_Mo!P73 -> 2028.3 | I13: =Barley_Mo!P88 -> 3911.2 | J13: =Barley_Mo!P103 -> 2398.7 | K13: =Barley_Mo!P118 -> 2149.2 | L13: =Barley_Mo!P133 -> 2016.7 | M13: =Barley_Mo!P148 -> 2058.6 | N13: =Barley_Mo!P163 -> 2184.3 | O13: =Barley_Mo!P178 -> 2390.9 | P13: =Barley_Mo!P193 -> 2463 | Q13: =Barley_Mo!P208 -> 1992.3 | R13: =Barley_Mo!P223 -> 2322.7 | S13: =Barley_Mo!P238 -> 2822.7 | T13: =Barley_Mo!P253 -> 3058 | U13: =Barley_Mo!P268 -> 2951.7 | V13: =Barley_Mo!P283 -> 4277.4 | W13: =Barley_Mo!P298 -> 2673.2 | X13: =Barley_Mo!P313 -> 3889.6 | Y13: =Barley_Mo!P328 -> 3063.2 | Z13: =Barley_Mo!P343 -> 2842.2 | AA13: =Barley_Mo!P358 -> 0
A14: Barley | B14: FSR | C14: KMT | D14: =Barley_Mo!P14 -> 1474.8 | E14: =Barley_Mo!P29 -> 2102 | F14: =Barley_Mo!P44 -> 3435.1 | G14: =Barley_Mo!P59 -> 3288.7 | H14: =Barley_Mo!P74 -> 1490.7 | I14: =Barley_Mo!P89 -> 1568.4 | J14: =Barley_Mo!P104 -> 2963.6 | K14: =Barley_Mo!P119 -> 2501.6 | L14: =Barley_Mo!P134 -> 1501.9 | M14: =Barley_Mo!P149 -> 1195.4 | N14: =Barley_Mo!P164 -> 983.4 | O14: =Barley_Mo!P179 -> 1942 | P14: =Barley_Mo!P194 -> 1217.3 | Q14: =Barley_Mo!P209 -> 1442.7 | R14: =Barley_Mo!P224 -> 2121.8 | S14: =Barley_Mo!P239 -> 1244.4 | T14: =Barley_Mo!P254 -> 862.6 | U14: =Barley_Mo!P269 -> 956.5 | V14: =Barley_Mo!P284 -> 710.8 | W14: =Barley_Mo!P299 -> 542.8 | X14: =Barley_Mo!P314 -> 708.5 | Y14: =Barley_Mo!P329 -> 1151.6 | Z14: =Barley_Mo!P344 -> 1248.7 | AA14: =Barley_Mo!P359 -> 0
A15: Barley | B15: Exports | C15: KMT | D15: =Barley_Mo!P15 -> 0 | E15: =Barley_Mo!P30 -> 0 | F15: =Barley_Mo!P45 -> 0 | G15: =Barley_Mo!P60 -> 0 | H15: =Barley_Mo!P75 -> 0 | I15: =Barley_Mo!P90 -> 0 | J15: =Barley_Mo!P105 -> 0 | K15: =Barley_Mo!P120 -> 0 | L15: =Barley_Mo!P135 -> 0 | M15: =Barley_Mo!P150 -> 0 | N15: =Barley_Mo!P165 -> 0 | O15: =Barley_Mo!P180 -> 0 | P15: =Barley_Mo!P195 -> 0 | Q15: =Barley_Mo!P210 -> 0 | R15: =Barley_Mo!P225 -> 0 | S15: =Barley_Mo!P240 -> 0 | T15: =Barley_Mo!P255 -> 0 | U15: =Barley_Mo!P270 -> 0 | V15: =Barley_Mo!P285 -> 0 | W15: =Barley_Mo!P300 -> 0 | X15: =Barley_Mo!P315 -> 0 | Y15: =Barley_Mo!P330 -> 0 | Z15: =Barley_Mo!P345 -> 0 | AA15: =Barley_Mo!P360 -> 0
A16: Barley
A17: Barley | B17: Ending Stocks | C17: KMT | D17: =Barley_Mo!P17 -> 2.2737368e-13 | E17: =Barley_Mo!P32 -> 9.094947e-13 | F17: =Barley_Mo!P47 -> 1.3642421e-12 | G17: =Barley_Mo!P62 -> -4.5474735e-13 | H17: =Barley_Mo!P77 -> 1.8189894e-12 | I17: =Barley_Mo!P92 -> 4.5474735e-13 | J17: =Barley_Mo!P107 -> 1.3642421e-12 | K17: =Barley_Mo!P122 -> -4.5474735e-13 | L17: =Barley_Mo!P137 -> 2.2737368e-13 | M17: =Barley_Mo!P152 -> 0 | N17: =Barley_Mo!P167 -> -3.4106051e-13 | O17: =Barley_Mo!P182 -> -4.5474735e-13 | P17: =Barley_Mo!P197 -> 2.2737368e-13 | Q17: =Barley_Mo!P212 -> -9.094947e-13 | R17: =Barley_Mo!P227 -> -9.094947e-13 | S17: =Barley_Mo!P242 -> -1.3642421e-12 | T17: =Barley_Mo!P257 -> 1.2505552e-12 | U17: =Barley_Mo!P272 -> 0 | V17: =Barley_Mo!P287 -> 2.2737368e-13 | W17: =Barley_Mo!P302 -> 2.2737368e-13 | X17: =Barley_Mo!P317 -> -4.5474735e-13 | Y17: =Barley_Mo!P332 -> -4.5474735e-13 | Z17: =Barley_Mo!P347 -> 6.8212103e-13 | AA17: =Barley_Mo!P362 -> 0
A18: Barley | B18: Stocks-to-Use | C18: %
A19: Barley | B19: STU Days | C19: Days
A20: Barley | B20: CHECK | C20: KMT | D20: =D8+D10+D9-D12-D13-D14-D15-D17 -> -1723.8 | E20: =E8+E10+E9-E12-E13-E14-E15-E17 -> -1178.9 | F20: =F8+F10+F9-F12-F13-F14-F15-F17 -> -1825.4 | G20: =G8+G10+G9-G12-G13-G14-G15-G17 -> -3254.8 | H20: =H8+H10+H9-H12-H13-H14-H15-H17 -> -3075.9 | I20: =I8+I10+I9-I12-I13-I14-I15-I17 -> -1319 | J20: =J8+J10+J9-J12-J13-J14-J15-J17 -> -1393.4 | K20: =K8+K10+K9-K12-K13-K14-K15-K17 -> -2818.4 | ... AA20: =AA8+AA10+AA9-AA12-AA13-AA14-AA15-AA17 -> 0

Sheet Oats_Yr
A1: Oats
A2: Commodity | B2: Metric | C2: Unit | D2: 2002-03 | E2: 2003-04 | F2: 2004-05 | G2: 2005-06 | H2: 2006-07 | I2: 2007-08 | J2: 2008-09 | K2: 2009-10 | L2: 2010-11 | M2: 2011-12 | N2: 2012-13 | O2: 2013-14 | P2: 2014-15 | Q2: 2015-16 | R2: 2016-17 | S2: 2017-18 | T2: 2018-19 | U2: 2019-20 | V2: 2020-21 | W2: 2021-22 | X2: 2022-23 | Y2: 2023-24 | Z2: 2024-25 | AA2: 2025-26
A3: Oats | B3: Planted Area | C3: MLN AC | D3: =Oats_Mo!P3 -> 0 | E3: =Oats_Mo!P18 -> 0 | F3: =Oats_Mo!P33 -> 0 | G3: =Oats_Mo!P48 -> 0 | H3: =Oats_Mo!P63 -> 0 | I3: =Oats_Mo!P78 -> 0 | J3: =Oats_Mo!P93 -> 0 | K3: =Oats_Mo!P108 -> 0 | L3: =Oats_Mo!P123 -> 0 | M3: =Oats_Mo!P138 -> 0 | N3: =Oats_Mo!P153 -> 0 | O3: =Oats_Mo!P168 -> 0 | P3: =Oats_Mo!P183 -> 0 | Q3: =Oats_Mo!P198 -> 0 | R3: =Oats_Mo!P213 -> 0 | S3: =Oats_Mo!P228 -> 0 | T3: =Oats_Mo!P243 -> 0 | U3: =Oats_Mo!P258 -> 0 | V3: =Oats_Mo!P273 -> 0 | W3: =Oats_Mo!P288 -> 0 | X3: =Oats_Mo!P303 -> 0 | Y3: =Oats_Mo!P318 -> 0 | Z3: =Oats_Mo!P333 -> 0 | AA3: =Oats_Mo!P348 -> 0
A4: Oats | B4: Harvested Area | C4: MLN AC | D4: =Oats_Mo!P4 -> 0 | E4: =Oats_Mo!P19 -> 0 | F4: =Oats_Mo!P34 -> 0 | G4: =Oats_Mo!P49 -> 0 | H4: =Oats_Mo!P64 -> 0 | I4: =Oats_Mo!P79 -> 0 | J4: =Oats_Mo!P94 -> 0 | K4: =Oats_Mo!P109 -> 0 | L4: =Oats_Mo!P124 -> 0 | M4: =Oats_Mo!P139 -> 0 | N4: =Oats_Mo!P154 -> 0 | O4: =Oats_Mo!P169 -> 0 | P4: =Oats_Mo!P184 -> 0 | Q4: =Oats_Mo!P199 -> 0 | R4: =Oats_Mo!P214 -> 0 | S4: =Oats_Mo!P229 -> 0 | T4: =Oats_Mo!P244 -> 0 | U4: =Oats_Mo!P259 -> 0 | V4: =Oats_Mo!P274 -> 0 | W4: =Oats_Mo!P289 -> 0 | X4: =Oats_Mo!P304 -> 0 | Y4: =Oats_Mo!P319 -> 0 | Z4: =Oats_Mo!P334 -> 0 | AA4: =Oats_Mo!P349 -> 0
A5: Oats | B5: Proportion Harvested | C5: % | D5: =IF(D3<>0,D4/D3,"") | E5: =IF(E3<>0,E4/E3,"") | F5: =IF(F3<>0,F4/F3,"") | G5: =IF(G3<>0,G4/G3,"") | H5: =IF(H3<>0,H4/H3,"") | I5: =IF(I3<>0,I4/I3,"") | J5: =IF(J3<>0,J4/J3,"") | K5: =IF(K3<>0,K4/K3,"") | ... AA5: =IF(AA3<>0,AA4/AA3,"")
A6: Oats | B6: Yield | C6: BU/AC | D6: =Oats_Mo!O6 -> 0 | E6: =Oats_Mo!O21 -> 0 | F6: =Oats_Mo!O36 -> 0 | G6: =Oats_Mo!O51 -> 0 | H6: =Oats_Mo!O66 -> 0 | I6: =Oats_Mo!O81 -> 0 | J6: =Oats_Mo!O96 -> 0 | K6: =Oats_Mo!O111 -> 0 | L6: =Oats_Mo!O126 -> 0 | M6: =Oats_Mo!O141 -> 0 | N6: =Oats_Mo!O156 -> 0 | O6: =Oats_Mo!O171 -> 0 | P6: =Oats_Mo!O186 -> 0 | Q6: =Oats_Mo!O201 -> 0 | R6: =Oats_Mo!O216 -> 0 | S6: =Oats_Mo!O231 -> 0 | T6: =Oats_Mo!O246 -> 0 | U6: =Oats_Mo!O261 -> 0 | V6: =Oats_Mo!O276 -> 0 | W6: =Oats_Mo!O291 -> 0 | X6: =Oats_Mo!O306 -> 0 | Y6: =Oats_Mo!O321 -> 0 | Z6: =Oats_Mo!O336 -> 0 | AA6: =Oats_Mo!O351 -> 0
A7: Oats
A8: Oats | B8: Beginning Stocks | C8: KMT | D8: =Oats_Mo!P8 -> 20.7 | E8: =Oats_Mo!P23 -> 18.9 | F8: =Oats_Mo!P38 -> 25.7 | G8: =Oats_Mo!P53 -> 20.2 | H8: =Oats_Mo!P68 -> 17.5 | I8: =Oats_Mo!P83 -> 16.7 | J8: =Oats_Mo!P98 -> 17.4 | K8: =Oats_Mo!P113 -> 16.5 | L8: =Oats_Mo!P128 -> 25.1 | M8: =Oats_Mo!P143 -> 12.1 | N8: =Oats_Mo!P158 -> 18.4 | O8: =Oats_Mo!P173 -> 29.6 | P8: =Oats_Mo!P188 -> 19.3 | Q8: =Oats_Mo!P203 -> 19.7 | R8: =Oats_Mo!P218 -> 20.9 | S8: =Oats_Mo!P233 -> 13.8 | T8: =Oats_Mo!P248 -> 10.5 | U8: =Oats_Mo!P263 -> 13.6 | V8: =Oats_Mo!P278 -> 17.1 | W8: =Oats_Mo!P293 -> 25 | X8: =Oats_Mo!P308 -> 24.6 | Y8: =Oats_Mo!P323 -> 15.3 | Z8: =Oats_Mo!P338 -> 15.9 | AA8: =Oats_Mo!P353 -> 0
A9: Oats | B9: Imports | C9: KMT | D9: =Oats_Mo!P9 -> 2910.7 | E9: =Oats_Mo!P24 -> 3376.7 | F9: =Oats_Mo!P39 -> 3467.2 | G9: =Oats_Mo!P54 -> 3282.7 | H9: =Oats_Mo!P69 -> 3852.2 | I9: =Oats_Mo!P84 -> 4618.4 | J9: =Oats_Mo!P99 -> 4272.6 | K9: =Oats_Mo!P114 -> 2911.5 | L9: =Oats_Mo!P129 -> 2451.4 | M9: =Oats_Mo!P144 -> 3157.6 | N9: =Oats_Mo!P159 -> 2829.6 | O9: =Oats_Mo!P174 -> 3927.6 | P9: =Oats_Mo!P189 -> 2976.8 | Q9: =Oats_Mo!P204 -> 3425 | R9: =Oats_Mo!P219 -> 3231.2 | S9: =Oats_Mo!P234 -> 3733 | T9: =Oats_Mo!P249 -> 3436 | U9: =Oats_Mo!P264 -> 4227.3 | V9: =Oats_Mo!P279 -> 4575.8 | W9: =Oats_Mo!P294 -> 2898.6 | X9: =Oats_Mo!P309 -> 5226.5 | Y9: =Oats_Mo!P324 -> 2643.1 | Z9: =Oats_Mo!P339 -> 3357.6 | AA9: =Oats_Mo!P354 -> 0
A10: Oats | B10: Production | C10: KMT | D10: =Oats_Mo!P10 -> 132.1 | E10: =Oats_Mo!P25 -> 139.8 | F10: =Oats_Mo!P40 -> 117.5 | G10: =Oats_Mo!P55 -> 78.7 | H10: =Oats_Mo!P70 -> 92.1 | I10: =Oats_Mo!P85 -> 70.2 | J10: =Oats_Mo!P100 -> 69.3 | K10: =Oats_Mo!P115 -> 59.8 | L10: =Oats_Mo!P130 -> 86.2 | M10: =Oats_Mo!P145 -> 123.3 | N10: =Oats_Mo!P160 -> 117.2 | O10: =Oats_Mo!P175 -> 83.5 | P10: =Oats_Mo!P190 -> 147 | Q10: =Oats_Mo!P205 -> 184.3 | R10: =Oats_Mo!P220 -> 125.2 | S10: =Oats_Mo!P235 -> 112.2 | T10: =Oats_Mo!P250 -> 122.4 | U10: =Oats_Mo!P265 -> 143.4 | V10: =Oats_Mo!P280 -> 104.1 | W10: =Oats_Mo!P295 -> 97.6 | X10: =Oats_Mo!P310 -> 90.3 | Y10: =Oats_Mo!P325 -> 78.8 | Z10: =Oats_Mo!P340 -> 75.2 | AA10: =Oats_Mo!P355 -> 0
A11: Oats
A12: Oats | B12: Food | C12: KMT | D12: =Oats_Mo!P12 -> 1448.4 | E12: =Oats_Mo!P27 -> 1434 | F12: =Oats_Mo!P42 -> 1514.2 | G12: =Oats_Mo!P57 -> 1457.5 | H12: =Oats_Mo!P72 -> 1789 | I12: =Oats_Mo!P87 -> 1366.5 | J12: =Oats_Mo!P102 -> 1212.6 | K12: =Oats_Mo!P117 -> 1158.1 | L12: =Oats_Mo!P132 -> 884.8 | M12: =Oats_Mo!P147 -> 780.2 | N12: =Oats_Mo!P162 -> 916.3 | O12: =Oats_Mo!P177 -> 1007.2 | P12: =Oats_Mo!P192 -> 888.4 | Q12: =Oats_Mo!P207 -> 760.8 | R12: =Oats_Mo!P222 -> 1084.3 | S12: =Oats_Mo!P237 -> 1191.5 | T12: =Oats_Mo!P252 -> 1230.9 | U12: =Oats_Mo!P267 -> 1458.1 | V12: =Oats_Mo!P282 -> 1286.2 | W12: =Oats_Mo!P297 -> 835.8 | X12: =Oats_Mo!P312 -> 1320.5 | Y12: =Oats_Mo!P327 -> 1046.5 | Z12: =Oats_Mo!P342 -> 896.6 | AA12: =Oats_Mo!P357 -> 0
A13: Oats | B13: Industrial | C13: KMT | D13: =Oats_Mo!P13 -> 1189.8 | E13: =Oats_Mo!P28 -> 1557.6 | F13: =Oats_Mo!P43 -> 1674.9 | G13: =Oats_Mo!P58 -> 1869.4 | H13: =Oats_Mo!P73 -> 2304.1 | I13: =Oats_Mo!P88 -> 2805.1 | J13: =Oats_Mo!P103 -> 2430.4 | K13: =Oats_Mo!P118 -> 2075.5 | L13: =Oats_Mo!P133 -> 1934.7 | M13: =Oats_Mo!P148 -> 2194.3 | N13: =Oats_Mo!P163 -> 2173.2 | O13: =Oats_Mo!P178 -> 2243.3 | P13: =Oats_Mo!P193 -> 2328.8 | Q13: =Oats_Mo!P208 -> 2233.5 | R13: =Oats_Mo!P223 -> 2306.1 | S13: =Oats_Mo!P238 -> 2368.2 | T13: =Oats_Mo!P253 -> 2474.7 | U13: =Oats_Mo!P268 -> 2610.7 | V13: =Oats_Mo!P283 -> 2971.7 | W13: =Oats_Mo!P298 -> 2314.1 | X13: =Oats_Mo!P313 -> 2669.9 | Y13: =Oats_Mo!P328 -> 2365.7 | Z13: =Oats_Mo!P343 -> 2565.4 | AA13: =Oats_Mo!P358 -> 0
A14: Oats | B14: FSR | C14: KMT | D14: =Oats_Mo!P14 -> 523.9 | E14: =Oats_Mo!P29 -> 788.1 | F14: =Oats_Mo!P44 -> 974.4 | G14: =Oats_Mo!P59 -> 871.7 | H14: =Oats_Mo!P74 -> 556.2 | I14: =Oats_Mo!P89 -> 949.5 | J14: =Oats_Mo!P104 -> 1527.2 | K14: =Oats_Mo!P119 -> 1161.8 | L14: =Oats_Mo!P134 -> 732.6 | M14: =Oats_Mo!P149 -> 804.5 | N14: =Oats_Mo!P164 -> 445.8 | O14: =Oats_Mo!P179 -> 1069 | P14: =Oats_Mo!P194 -> 700.9 | Q14: =Oats_Mo!P209 -> 967 | R14: =Oats_Mo!P224 -> 703.5 | S14: =Oats_Mo!P239 -> 778.4 | T14: =Oats_Mo!P254 -> 396.9 | U14: =Oats_Mo!P269 -> 425.6 | V14: =Oats_Mo!P284 -> 656.5 | W14: =Oats_Mo!P299 -> 332.6 | X14: =Oats_Mo!P314 -> 1503 | Y14: =Oats_Mo!P329 -> 670.4 | Z14: =Oats_Mo!P344 -> 506.7 | AA14: =Oats_Mo!P359 -> 0
A15: Oats | B15: Exports | C15: KMT | D15: =Oats_Mo!P15 -> 0 | E15: =Oats_Mo!P30 -> 0 | F15: =Oats_Mo!P45 -> 0 | G15: =Oats_Mo!P60 -> 0 | H15: =Oats_Mo!P75 -> 0 | I15: =Oats_Mo!P90 -> 0 | J15: =Oats_Mo!P105 -> 0 | K15: =Oats_Mo!P120 -> 0 | L15: =Oats_Mo!P135 -> 0 | M15: =Oats_Mo!P150 -> 0 | N15: =Oats_Mo!P165 -> 0 | O15: =Oats_Mo!P180 -> 0 | P15: =Oats_Mo!P195 -> 0 | Q15: =Oats_Mo!P210 -> 0 | R15: =Oats_Mo!P225 -> 0 | S15: =Oats_Mo!P240 -> 0 | T15: =Oats_Mo!P255 -> 0 | U15: =Oats_Mo!P270 -> 0 | V15: =Oats_Mo!P285 -> 0 | W15: =Oats_Mo!P300 -> 0 | X15: =Oats_Mo!P315 -> 0 | Y15: =Oats_Mo!P330 -> 0 | Z15: =Oats_Mo!P345 -> 0 | AA15: =Oats_Mo!P360 -> 0
A16: Oats
A17: Oats | B17: Ending Stocks | C17: KMT | D17: =Oats_Mo!P17 -> -1.1368684e-13 | E17: =Oats_Mo!P32 -> -5.6843419e-13 | F17: =Oats_Mo!P47 -> 1.1368684e-13 | G17: =Oats_Mo!P62 -> 2.2737368e-13 | H17: =Oats_Mo!P77 -> -6.8212103e-13 | I17: =Oats_Mo!P92 -> 0 | J17: =Oats_Mo!P107 -> 2.2737368e-13 | K17: =Oats_Mo!P122 -> 2.2737368e-13 | L17: =Oats_Mo!P137 -> 1.1368684e-13 | M17: =Oats_Mo!P152 -> 0 | N17: =Oats_Mo!P167 -> 1.7053026e-13 | O17: =Oats_Mo!P182 -> 0 | P17: =Oats_Mo!P197 -> 1.1368684e-13 | Q17: =Oats_Mo!P212 -> 0 | R17: =Oats_Mo!P227 -> 0 | S17: =Oats_Mo!P242 -> 1.1368684e-13 | T17: =Oats_Mo!P257 -> 5.6843419e-13 | U17: =Oats_Mo!P272 -> 3.4106051e-13 | V17: =Oats_Mo!P287 -> -4.5474735e-13 | W17: =Oats_Mo!P302 -> -1.1368684e-13 | X17: =Oats_Mo!P317 -> -4.5474735e-13 | Y17: =Oats_Mo!P332 -> 1.1368684e-13 | Z17: =Oats_Mo!P347 -> 2.8421709e-13 | AA17: =Oats_Mo!P362 -> 0
A18: Oats | B18: Stocks-to-Use | C18: %
A19: Oats | B19: STU Days | C19: Days
A20: Oats | B20: CHECK | C20: KMT | D20: =D8+D10+D9-D12-D13-D14-D15-D17 -> -98.6 | E20: =E8+E10+E9-E12-E13-E14-E15-E17 -> -244.3 | F20: =F8+F10+F9-F12-F13-F14-F15-F17 -> -553.1 | G20: =G8+G10+G9-G12-G13-G14-G15-G17 -> -817 | H20: =H8+H10+H9-H12-H13-H14-H15-H17 -> -687.5 | I20: =I8+I10+I9-I12-I13-I14-I15-I17 -> -415.8 | J20: =J8+J10+J9-J12-J13-J14-J15-J17 -> -810.9 | K20: =K8+K10+K9-K12-K13-K14-K15-K17 -> -1407.6 | ... AA20: =AA8+AA10+AA9-AA12-AA13-AA14-AA15-AA17 -> 0

Sheet Soybeans_Mo
A1: Soybeans
A2: Commodity | B2: Metric | C2: Crop Year | D2: 09 | E2: 10 | F2: 11 | G2: 12 | H2: 01 | I2: 02 | J2: 03 | K2: 04 | L2: 05 | M2: 06 | N2: 07 | O2: 08 | P2: Total
A3: Soybeans | B3: Planted Area | C3: 2002-03 | P3: =SUM(D3:O3) -> 0
A4: Soybeans | B4: Harvested Area | C4: 2002-03 | P4: =SUM(D4:O4) -> 0
A5: Soybeans | B5: Proportion Harvested | C5: 2002-03 | P5: =SUM(D5:O5) -> 0
A6: Soybeans | B6: Yield | C6: 2002-03 | P6: =SUM(D6:O6) -> 0
A7: Soybeans | C7: 2002-03
A8: Soybeans | B8: Beginning Stocks | C8: 2002-03 | N8: 171.8 | P8: =SUM(D8:O8) -> 171.8
A9: Soybeans | B9: Imports | C9: 2002-03 | N9: 651 | P9: =SUM(D9:O9) -> 651
A10: Soybeans | B10: Production | C10: 2002-03 | N10: 2335.7 | P10: =SUM(D10:O10) -> 2335.7
A11: Soybeans | C11: 2002-03
A12: Soybeans | B12: Food | C12: 2002-03 | N12: 418.8 | P12: =SUM(D12:O12) -> 418.8
A13: Soybeans | B13: Crush | C13: 2002-03 | P13: =SUM(D13:O13) -> 0
A14: Soybeans | B14: FSR | C14: 2002-03 | N14: 1871.5 | P14: =SUM(D14:O14) -> 1871.5
A15: Soybeans | B15: Exports | C15: 2002-03 | N15: 723.2 | P15: =SUM(D15:O15) -> 723.2
A16: Soybeans | C16: 2002-03
A17: Soybeans | B17: Ending Stocks | C17: 2002-03 | N17: 145 | P17: =SUM(D17:O17) -> 145
A18: Soybeans | B18: Stocks-to-Use | C18: 2002-03 | N18: 0.048116808 | P18: =SUM(D18:O18) -> 0.048116808
A19: Soybeans | B19: STU Days | C19: 2002-03 | N19: 17.562635 | P19: =SUM(D19:O19) -> 17.562635
A20: Soybeans | B20: CHECK | C20: 2002-03 | N20: -2.2737368e-13 | P20: =SUM(D20:O20) -> -2.2737368e-13
A21: Soybeans | B21: Planted Area | C21: 2003-04 | P21: =SUM(D21:O21) -> 0
A22: Soybeans | B22: Harvested Area | C22: 2003-04 | P22: =SUM(D22:O22) -> 0
A23: Soybeans | B23: Proportion Harvested | C23: 2003-04 | P23: =SUM(D23:O23) -> 0
A24: Soybeans | B24: Yield | C24: 2003-04 | P24: =SUM(D24:O24) -> 0
A25: Soybeans | C25: 2003-04
A26: Soybeans | B26: Beginning Stocks | C26: 2003-04 | N26: 145 | P26: =SUM(D26:O26) -> 145
A27: Soybeans | B27: Imports | C27: 2003-04 | N27: 586.7 | P27: =SUM(D27:O27) -> 586.7
A28: Soybeans | B28: Production | C28: 2003-04 | N28: 2273.3 | P28: =SUM(D28:O28) -> 2273.3
A29: Soybeans | C29: 2003-04
A30: Soybeans | B30: Food | C30: 2003-04 | N30: 324.1 | P30: =SUM(D30:O30) -> 324.1
A31: Soybeans | B31: Crush | C31: 2003-04 | P31: =SUM(D31:O31) -> 0
A32: Soybeans | B32: FSR | C32: 2003-04 | N32: 1627.3 | P32: =SUM(D32:O32) -> 1627.3
A33: Soybeans | B33: Exports | C33: 2003-04 | N33: 913.6 | P33: =SUM(D33:O33) -> 913.6
A34: Soybeans | C34: 2003-04
A35: Soybeans | B35: Ending Stocks | C35: 2003-04 | N35: 140 | P35: =SUM(D35:O35) -> 140
A36: Soybeans | B36: Stocks-to-Use | C36: 2003-04 | N36: 0.04886562 | P36: =SUM(D36:O36) -> 0.04886562
A37: Soybeans | B37: STU Days | C37: 2003-04 | N37: 17.835951 | P37: =SUM(D37:O37) -> 17.835951
A38: Soybeans | B38: CHECK | C38: 2003-04 | N38: 1.1368684e-13 | P38: =SUM(D38:O38) -> 1.1368684e-13
A39: Soybeans | B39: Planted Area | C39: 2004-05 | P39: =SUM(D39:O39) -> 0
A40: Soybeans | B40: Harvested Area | C40: 2004-05 | P40: =SUM(D40:O40) -> 0
...

Sheet Soybeans_Yr
A1: Soybeans
