Workbook

Sheet Wheat_Mo
A1: Commodity | B1: Metric | C1: Crop Year | D1: AUG | E1: SEP | F1: OCT | G1: NOV | H1: DEC | I1: JAN | J1: FEB | K1: MAR | L1: APR | M1: MAY | N1: JUN | O1: JUL | P1: AUG/JUL
A2: Wheat, excluding durum | B2: Planted Area | C2: 02-03 | D2: 19.5012 | P2: =D2 -> 19.5012
A3: Wheat, excluding durum | B3: Planted Area | C3: 03-04 | D3: 19.7719 | P3: =D3 -> 19.7719
A4: Wheat, excluding durum | B4: Planted Area | C4: 04-05 | D4: 19.1433 | P4: =D4 -> 19.1433
A5: Wheat, excluding durum | B5: Planted Area | C5: 05-06 | D5: 18.1559 | P5: =D5 -> 18.1559
A6: Wheat, excluding durum | B6: Planted Area | C6: 06-07 | D6: 20.549875 | P6: =D6 -> 20.549875
A7: Wheat, excluding durum | B7: Planted Area | C7: 07-08 | D7: 16.9631 | P7: =D7 -> 16.9631
A8: Wheat, excluding durum | B8: Planted Area | C8: 08-09 | D8: 19.111 | P8: =D8 -> 19.111
A9: Wheat, excluding durum | B9: Planted Area | C9: 09-10 | D9: 19.2571 | P9: =D9 -> 19.2571
A10: Wheat, excluding durum | B10: Planted Area | C10: 10-11 | D10: 17.9841 | P10: =D10 -> 17.9841
A11: Wheat, excluding durum | B11: Planted Area | C11: 11-12 | D11: 17.551812 | P11: =D11 -> 17.551812
A12: Wheat, excluding durum | B12: Planted Area | C12: 12-13 | D12: 19.0678 | P12: =D12 -> 19.0678
A13: Wheat, excluding durum | B13: Planted Area | C13: 13-14 | D13: 21.2865 | P13: =D13 -> 21.2865
... A93: Wheat, excluding durum | B93: Production | C93: 24-25 | D93: 29558.5 | P93: =D93 -> 29558.5
A94: Wheat, excluding durum | B94: Exports | C94: 02-03 | D94: 701.344 | E94: 487.3 | F94: 646.784 | G94: 412.44 | H94: 435.044 | I94: 291.912 | J94: 353.22 | K94: 397.448 | L94: 452.05 | M94: 692.208 | N94: 511.644 | O94: 694.858 | P94: =SUM(D94:O94) -> 6076.252
A95: Wheat, excluding durum | B95: Exports | C95: 03-04 | D95: 701.158 | E95: 1093.95 | F95: 1201.09 | G95: 954.188 | H95: 1072.484 | I95: 787.754 | J95: 718.62 | K95: 898.348 | L95: 991.478 | M95: 1396.122 | N95: 1380.392 | O95: 858.434 | P95: =SUM(D95:O95) -> 12054.018
A96: Wheat, excluding durum | B96: Exports | C96: 04-05 | D96: 1222.426 | E96: 773.544 | F96: 666.2 | G96: 1037.526 | H96: 1158.662 | I96: 945.51 | J96: 1066.98 | K96: 941.944 | L96: 874.31 | M96: 1014.712 | N96: 765.67 | O96: 863.402 | P96: =SUM(D96:O96) -> 11330.886
A97: Wheat, excluding durum | B97: Exports | C97: 05-06 | D97: 783.01 | E97: 751.02 | F97: 914.162 | G97: 820.976 | H97: 706.172 | I97: 812.806 | J97: 855.336 | K97: 907.23 | L97: 1340.388 | M97: 1440.598 | N97: 866.178 | O97: 1296.332 | P97: =SUM(D97:O97) -> 11494.208
A98: Wheat, excluding durum | B98: Exports | C98: 06-07 | D98: 1256.282 | E98: 1324.462 | F98: 1358.534 | G98: 1226.478 | H98: 1247.462 | I98: 894.63 | J98: 1017.052 | K98: 1029.12 | L98: 1199.298 | M98: 1302.562 | N98: 1408.052 | O98: 1327.688 | P98: =SUM(D98:O98) -> 14591.62
A99: Wheat, excluding durum | B99: Exports | C99: 07-08 | D99: 1284.764 | E99: 1275.328 | F99: 1198.408 | G99: 982.368 | H99: 845.644 | I99: 854.148 | J99: 812.04 | K99: 995.696 | L99: 1071.748 | M99: 1338.21 | N99: 878.194 | O99: 1089.474 | P99: =SUM(D99:O99) -> 12626.022
A100: Wheat, excluding durum | B100: Exports | C100: 08-09 | D100: 950.918 | E100: 1054.024 | F100: 1142.656 | G100: 1270.242 | H100: 1123.01 | I100: 1435.994 | J100: 1170.478 | K100: 1273.318 | L100: 1509.198 | M100: 1565.472 | N100: 1245.03 | O100: 1215.312 | P100: =SUM(D100:O100) -> 14955.652
A101: Wheat, excluding durum | B101: Exports | C101: 09-10 | D101: 1469.288 | E101: 1123.17 | F101: 1239.336 | G101: 1244.4 | H101: 967.658 | I101: 1326.686 | J101: 1179.858 | K101: 1368.798 | L101: 1388.4 | M101: 1716.994 | N101: 1510.97 | O101: 1340.948 | P101: =SUM(D101:O101) -> 15876.506
A102: Wheat, excluding durum | B102: Exports | C102: 10-11 | D102: 1127.824 | E102: 1044.008 | F102: 1242.1 | G102: 1047.298 | H102: 1221.992 | I102: 830.172 | J102: 765.952 | K102: 1120.886 | L102: 1267.722 | M102: 1326.548 | N102: 1345.554 | O102: 964.912 | P102: =SUM(D102:O102) -> 13304.968
A103: Wheat, excluding durum | B103: Exports | C103: 11-12 | D103: 1205.268 | E103: 1040.786 | F103: 1148.538 | G103: 1029.134 | H103: 1298.916 | I103: 967.217 | J103: 1109.288 | K103: 1326.39 | L103: 1484.231 | M103: 1422.112 | N103: 839.678 | O103: 844.53 | P103: =SUM(D103:O103) -> 13716.088
A104: Wheat, excluding durum | B104: Exports | C104: 12-13 | D104: 1270.791 | E104: 1190.805 | F104: 1105.744 | G104: 1074.88 | H104: 1319.481 | I104: 1298.535 | J104: 1101.571 | K104: 1250.516 | L104: 1320.83 | M104: 1439.526 | N104: 846.2 | O104: 1156.051 | P104: =SUM(D104:O104) -> 14374.93
A105: Wheat, excluding durum | B105: Exports | C105: 13-14 | D105: 1255.348 | E105: 1338.953 | F105: 1480.882 | G105: 1628.411 | H105: 1212.051 | I105: 1349.718 | J105: 1299.82 | K105: 1263.383 | L105: 1456.8 | M105: 2137.037 | N105: 1674.239 | O105: 1863.362 | P105: =SUM(D105:O105) -> 17960.004
... A208: Wheat, excluding durum | B208: Seed | C208: 24-25 | D208: 0 | E208: 0 | F208: 0 | G208: 0 | H208: 0 | I208: 0 | J208: 0 | K208: 0 | L208: 0 | M208: 0 | N208: 0 | O208: 0 | P208: =SUM(D208:O208) -> 0
A209: Wheat, excluding durum | B209: Food & Processing | C209: 02-03 | D209: =D140+D163 -> 233.03333 | E209: =E140+E163 -> 233.03333 | F209: =F140+F163 -> 233.03333 | G209: =G140+G163 -> 233.03333 | H209: =H140+H163 -> 233.03333 | I209: =I140+I163 -> 233.03333 | J209: =J140+J163 -> 233.03333 | K209: =K140+K163 -> 233.03333 | ... O209: =O140+O163 -> 233.03333 | P209: =SUM(D209:O209) -> 2796.4
A210: Wheat, excluding durum | B210: Food & Processing | C210: 03-04 | D210: =D141+D164 -> 231.25 | E210: =E141+E164 -> 231.25 | F210: =F141+F164 -> 231.25 | G210: =G141+G164 -> 231.25 | H210: =H141+H164 -> 231.25 | I210: =I141+I164 -> 231.25 | J210: =J141+J164 -> 231.25 | K210: =K141+K164 -> 231.25 | ... O210: =O141+O164 -> 231.25 | P210: =SUM(D210:O210) -> 2775
A211: Wheat, excluding durum | B211: Food & Processing | C211: 04-05 | D211: =D142+D165 -> 237.04167 | E211: =E142+E165 -> 237.04167 | F211: =F142+F165 -> 237.04167 | G211: =G142+G165 -> 237.04167 | H211: =H142+H165 -> 237.04167 | I211: =I142+I165 -> 237.04167 | J211: =J142+J165 -> 237.04167 | K211: =K142+K165 -> 237.04167 | ... O211: =O142+O165 -> 237.04167 | P211: =SUM(D211:O211) -> 2844.5
A212: Wheat, excluding durum | B212: Food & Processing | C212: 05-06 | D212: =D143+D166 -> 243.33333 | E212: =E143+E166 -> 243.33333 | F212: =F143+F166 -> 243.33333 | G212: =G143+G166 -> 243.33333 | H212: =H143+H166 -> 243.33333 | I212: =I143+I166 -> 243.33333 | J212: =J143+J166 -> 243.33333 | K212: =K143+K166 -> 243.33333 | ... O212: =O143+O166 -> 243.33333 | P212: =SUM(D212:O212) -> 2920
A213: Wheat, excluding durum | B213: Food & Processing | C213: 06-07 | D213: =D144+D167 -> 259.5 | E213: =E144+E167 -> 259.5 | F213: =F144+F167 -> 259.5 | G213: =G144+G167 -> 259.5 | H213: =H144+H167 -> 259.5 | I213: =I144+I167 -> 259.5 | J213: =J144+J167 -> 259.5 | K213: =K144+K167 -> 259.5 | ... O213: =O144+O167 -> 259.5 | P213: =SUM(D213:O213) -> 3114
A214: Wheat, excluding durum | B214: Food & Processing | C214: 07-08 | D214: =D145+D168 -> 251.85833 | E214: =E145+E168 -> 251.85833 | F214: =F145+F168 -> 251.85833 | G214: =G145+G168 -> 251.85833 | H214: =H145+H168 -> 251.85833 | I214: =I145+I168 -> 251.85833 | J214: =J145+J168 -> 251.85833 | K214: =K145+K168 -> 251.85833 | ... O214: =O145+O168 -> 251.85833 | P214: =SUM(D214:O214) -> 3022.3
A215: Wheat, excluding durum | B215: Food & Processing | C215: 08-09 | D215: =D146+D169 -> 262.93333 | E215: =E146+E169 -> 262.93333 | F215: =F146+F169 -> 262.93333 | G215: =G146+G169 -> 262.93333 | H215: =H146+H169 -> 262.93333 | I215: =I146+I169 -> 262.93333 | J215: =J146+J169 -> 262.93333 | K215: =K146+K169 -> 262.93333 | ... O215: =O146+O169 -> 262.93333 | P215: =SUM(D215:O215) -> 3155.2
A216: Wheat, excluding durum | B216: Food & Processing | C216: 09-10 | D216: =D147+D170 -> 274.9 | E216: =E147+E170 -> 274.9 | F216: =F147+F170 -> 274.9 | G216: =G147+G170 -> 274.9 | H216: =H147+H170 -> 274.9 | I216: =I147+I170 -> 274.9 | J216: =J147+J170 -> 274.9 | K216: =K147+K170 -> 274.9 | ... O216: =O147+O170 -> 274.9 | P216: =SUM(D216:O216) -> 3298.8
A217: Wheat, excluding durum | B217: Food & Processing | C217: 10-11 | D217: =D148+D171 -> 279.925 | E217: =E148+E171 -> 279.925 | F217: =F148+F171 -> 279.925 | G217: =G148+G171 -> 279.925 | H217: =H148+H171 -> 279.925 | I217: =I148+I171 -> 279.925 | J217: =J148+J171 -> 279.925 | K217: =K148+K171 -> 279.925 | ... O217: =O148+O171 -> 279.925 | P217: =SUM(D217:O217) -> 3359.1
A218: Wheat, excluding durum | B218: Food & Processing | C218: 11-12 | D218: =D149+D172 -> 294.95 | E218: =E149+E172 -> 294.95 | F218: =F149+F172 -> 294.95 | G218: =G149+G172 -> 294.95 | H218: =H149+H172 -> 294.95 | I218: =I149+I172 -> 294.95 | J218: =J149+J172 -> 294.95 | K218: =K149+K172 -> 294.95 | ... O218: =O149+O172 -> 294.95 | P218: =SUM(D218:O218) -> 3539.4
A219: Wheat, excluding durum | B219: Food & Processing | C219: 12-13 | D219: =D150+D173 -> 273.86667 | E219: =E150+E173 -> 273.86667 | F219: =F150+F173 -> 273.86667 | G219: =G150+G173 -> 273.86667 | H219: =H150+H173 -> 273.86667 | I219: =I150+I173 -> 273.86667 | J219: =J150+J173 -> 273.86667 | K219: =K150+K173 -> 273.86667 | ... O219: =O150+O173 -> 273.86667 | P219: =SUM(D219:O219) -> 3286.4
A220: Wheat, excluding durum | B220: Food & Processing | C220: 13-14 | D220: =D151+D174 -> 285.55833 | E220: =E151+E174 -> 285.55833 | F220: =F151+F174 -> 285.55833 | G220: =G151+G174 -> 285.55833 | H220: =H151+H174 -> 285.55833 | I220: =I151+I174 -> 285.55833 | J220: =J151+J174 -> 285.55833 | K220: =K151+K174 -> 285.55833 | ... O220: =O151+O174 -> 285.55833 | P220: =SUM(D220:O220) -> 3426.7
... A231: Wheat, excluding durum | B231: Food & Processing | C231: 24-25 | D231: =D162+D185 -> 275.04167 | E231: =E162+E185 -> 275.04167 | F231: =F162+F185 -> 275.04167 | G231: =G162+G185 -> 275.04167 | H231: =H162+H185 -> 275.04167 | I231: =I162+I185 -> 275.04167 | J231: =J162+J185 -> 275.04167 | K231: =K162+K185 -> 275.04167 | ... O231: =O162+O185 -> 275.04167 | P231: =SUM(D231:O231) -> 3300.5
...

Sheet Wheat_Yr
A1: Wheat Ex-Durum
A2: Commodity | B2: Metric | C2: Unit | D2: 02-03 | E2: 03-04 | F2: 04-05 | G2: 05-06 | H2: 06-07 | I2: 07-08 | J2: 08-09 | K2: 09-10 | L2: 10-11 | M2: 11-12 | N2: 12-13 | O2: 13-14 | P2: 14-15 | Q2: 15-16 | R2: 16-17 | S2: 17-18 | T2: 18-19 | U2: 19-20 | V2: 20-21 | W2: 21-22 | X2: 22-23 | Y2: 23-24 | Z2: 24-25
A3: Wheat Ex-Durum | B3: Planted Area | C3: MLN AC | D3: =SUMIFS(Wheat_Mo!$P:$P,Wheat_Mo!$B:$B,"Planted Area",Wheat_Mo!$C:$C,RIGHT(D$2,5)) -> 19.5012 | E3: =SUMIFS(Wheat_Mo!$P:$P,Wheat_Mo!$B:$B,"Planted Area",Wheat_Mo!$C:$C,RIGHT(E$2,5)) -> 19.7719 | F3: =SUMIFS(Wheat_Mo!$P:$P,Wheat_Mo!$B:$B,"Planted Area",Wheat_Mo!$C:$C,RIGHT(F$2,5)) -> 19.1433 | G3: =SUMIFS(Wheat_Mo!$P:$P,Wheat_Mo!$B:$B,"Planted Area",Wheat_Mo!$C:$C,RIGHT(G$2,5)) -> 18.1559 | H3: =SUMIFS(Wheat_Mo!$P:$P,Wheat_Mo!$B:$B,"Planted Area",Wheat_Mo!$C:$C,RIGHT(H$2,5)) -> 20.549875 | I3: =SUMIFS(Wheat_Mo!$P:$P,Wheat_Mo!$B:$B,"Planted Area",Wheat_Mo!$C:$C,RIGHT(I$2,5)) -> 16.9631 | J3: =SUMIFS(Wheat_Mo!$P:$P,Wheat_Mo!$B:$B,"Planted Area",Wheat_Mo!$C:$C,RIGHT(J$2,5)) -> 19.111 | K3: =SUMIFS(Wheat_Mo!$P:$P,Wheat_Mo!$B:$B,"Planted Area",Wheat_Mo!$C:$C,RIGHT(K$2,5)) -> 19.2571 | ... Z3: =SUMIFS(Wheat_Mo!$P:$P,Wheat_Mo!$B:$B,"Planted Area",Wheat_Mo!$C:$C,RIGHT(Z$2,5)) -> 20.4091
A4: Wheat Ex-Durum | B4: Harvested Area | C4: MLN AC | D4: =SUMIFS(Wheat_Mo!$P:$P,Wheat_Mo!$B:$B,"Harvested Area",Wheat_Mo!$C:$C,RIGHT(D$2,5)) -> 15.9745 | E4: =SUMIFS(Wheat_Mo!$P:$P,Wheat_Mo!$B:$B,"Harvested Area",Wheat_Mo!$C:$C,RIGHT(E$2,5)) -> 19.3261 | F4: =SUMIFS(Wheat_Mo!$P:$P,Wheat_Mo!$B:$B,"Harvested Area",Wheat_Mo!$C:$C,RIGHT(F$2,5)) -> 18.1311 | G4: =SUMIFS(Wheat_Mo!$P:$P,Wheat_Mo!$B:$B,"Harvested Area",Wheat_Mo!$C:$C,RIGHT(G$2,5)) -> 17.6074 | H4: =SUMIFS(Wheat_Mo!$P:$P,Wheat_Mo!$B:$B,"Harvested Area",Wheat_Mo!$C:$C,RIGHT(H$2,5)) -> 20.1745 | I4: =SUMIFS(Wheat_Mo!$P:$P,Wheat_Mo!$B:$B,"Harvested Area",Wheat_Mo!$C:$C,RIGHT(I$2,5)) -> 16.5812 | J4: =SUMIFS(Wheat_Mo!$P:$P,Wheat_Mo!$B:$B,"Harvested Area",Wheat_Mo!$C:$C,RIGHT(J$2,5)) -> 18.779 | K4: =SUMIFS(Wheat_Mo!$P:$P,Wheat_Mo!$B:$B,"Harvested Area",Wheat_Mo!$C:$C,RIGHT(K$2,5)) -> 18.3619 | ... Z4: =SUMIFS(Wheat_Mo!$P:$P,Wheat_Mo!$B:$B,"Harvested Area",Wheat_Mo!$C:$C,RIGHT(Z$2,5)) -> 19.9824
A5: Wheat Ex-Durum | B5: Proportion Harvested | C5: % | D5: =IF(D3<>0,D4/D3,"") -> 0.81915472 | E5: =IF(E3<>0,E4/E3,"") -> 0.97745285 | F5: =IF(F3<>0,F4/F3,"") -> 0.9471251 | G5: =IF(G3<>0,G4/G3,"") -> 0.96978943 | H5: =IF(H3<>0,H4/H3,"") -> 0.98173347 | I5: =IF(I3<>0,I4/I3,"") -> 0.97748643 | J5: =IF(J3<>0,J4/J3,"") -> 0.98262781 | K5: =IF(K3<>0,K4/K3,"") -> 0.95351325 | ... Z5: =IF(Z3<>0,Z4/Z3,"") -> 0.97909266
A6: Wheat Ex-Durum | B6: Yield | C6: BU/AC | D6: =SUMIFS(Wheat_Mo!$P:$P,Wheat_Mo!$B:$B,"Yield",Wheat_Mo!$C:$C,RIGHT(D$2,5)) -> 27.795898 | E6: =SUMIFS(Wheat_Mo!$P:$P,Wheat_Mo!$B:$B,"Yield",Wheat_Mo!$C:$C,RIGHT(E$2,5)) -> 35.8138 | F6: =SUMIFS(Wheat_Mo!$P:$P,Wheat_Mo!$B:$B,"Yield",Wheat_Mo!$C:$C,RIGHT(F$2,5)) -> 40.519175 | G6: =SUMIFS(Wheat_Mo!$P:$P,Wheat_Mo!$B:$B,"Yield",Wheat_Mo!$C:$C,RIGHT(G$2,5)) -> 41.389199 | H6: =SUMIFS(Wheat_Mo!$P:$P,Wheat_Mo!$B:$B,"Yield",Wheat_Mo!$C:$C,RIGHT(H$2,5)) -> 39.921312 | I6: =SUMIFS(Wheat_Mo!$P:$P,Wheat_Mo!$B:$B,"Yield",Wheat_Mo!$C:$C,RIGHT(I$2,5)) -> 36.362107 | J6: =SUMIFS(Wheat_Mo!$P:$P,Wheat_Mo!$B:$B,"Yield",Wheat_Mo!$C:$C,RIGHT(J$2,5)) -> 45.198136 | K6: =SUMIFS(Wheat_Mo!$P:$P,Wheat_Mo!$B:$B,"Yield",Wheat_Mo!$C:$C,RIGHT(K$2,5)) -> 43.123955 | ... Z6: =SUMIFS(Wheat_Mo!$P:$P,Wheat_Mo!$B:$B,"Yield",Wheat_Mo!$C:$C,RIGHT(Z$2,5)) -> 54.352263
A8: Wheat Ex-Durum | B8: Beginning Stocks | C8: KMT | D8: =SUMIFS(Wheat_Mo!$D:$D,Wheat_Mo!$B:$B,"STOCKS",Wheat_Mo!$C:$C,RIGHT(D$2,5))-SUMIFS(Wheat_Mo!$D:$D,Wheat_Mo!$B:$B,"Production",Wheat_Mo!$C:$C,RIGHT(D$2,5))-SUMIFS(Wheat_Mo!$D:$D,Wheat_Mo!$B:$B,"Imports",Wheat_Mo!$C:$C,RIGHT(D$2,5))+SUMIFS(Wheat_Mo!$D:$D,Wheat_Mo!$B:$B,"Exports",Wheat_Mo!$C:$C,RIGHT(D$2,5))+SUMIFS(Wheat_Mo!$D:$D,Wheat_Mo!$B:$B,"Food & Processing",Wheat_Mo!$C:$C,RIGHT(D$2,5))+SUMIFS(Wheat_Mo!$D:$D,Wheat_Mo!$B:$B,"FSR",Wheat_Mo!$C:$C,RIGHT(D$2,5))+SUMIFS(Wheat_Mo!$D:$D,Wheat_Mo!$B:$B,"Seed",Wheat_Mo!$C:$C,RIGHT(D$2,5)) -> 5184.5 | E8: =D19 -> 4106.5 | F8: =E19 -> 4211.1 | G8: =F19 -> 5435.1 | H8: =G19 -> 6424.1 | I8: =H19 -> 5608.2 | J8: =I19 -> 3557.4 | K8: =J19 -> 4641.7 | L8: =K19 -> 5049 | ... Z8: =Y19 -> 4640.5
A9: Wheat Ex-Durum | B9: Imports | C9: KMT | D9: =SUMIFS(Wheat_Mo!$P:$P,Wheat_Mo!$B:$B,"Imports",Wheat_Mo!$C:$C,RIGHT(D$2,5)) -> 172.652 | E9: =SUMIFS(Wheat_Mo!$P:$P,Wheat_Mo!$B:$B,"Imports",Wheat_Mo!$C:$C,RIGHT(E$2,5)) -> 16.312 | F9: =SUMIFS(Wheat_Mo!$P:$P,Wheat_Mo!$B:$B,"Imports",Wheat_Mo!$C:$C,RIGHT(F$2,5)) -> 13.274 | G9: =SUMIFS(Wheat_Mo!$P:$P,Wheat_Mo!$B:$B,"Imports",Wheat_Mo!$C:$C,RIGHT(G$2,5)) -> 22.732 | H9: =SUMIFS(Wheat_Mo!$P:$P,Wheat_Mo!$B:$B,"Imports",Wheat_Mo!$C:$C,RIGHT(H$2,5)) -> 24.774 | I9: =SUMIFS(Wheat_Mo!$P:$P,Wheat_Mo!$B:$B,"Imports",Wheat_Mo!$C:$C,RIGHT(I$2,5)) -> 20.478 | J9: =SUMIFS(Wheat_Mo!$P:$P,Wheat_Mo!$B:$B,"Imports",Wheat_Mo!$C:$C,RIGHT(J$2,5)) -> 23.074 | K9: =SUMIFS(Wheat_Mo!$P:$P,Wheat_Mo!$B:$B,"Imports",Wheat_Mo!$C:$C,RIGHT(K$2,5)) -> 114.97 | ... Z9: =SUMIFS(Wheat_Mo!$P:$P,Wheat_Mo!$B:$B,"Imports",Wheat_Mo!$C:$C,RIGHT(Z$2,5)) -> 80.139
A10: Wheat Ex-Durum | B10: Production | C10: KMT | D10: =SUMIFS(Wheat_Mo!$P:$P,Wheat_Mo!$B:$B,"Production",Wheat_Mo!$C:$C,RIGHT(D$2,5)) -> 12084.4 | E10: =SUMIFS(Wheat_Mo!$P:$P,Wheat_Mo!$B:$B,"Production",Wheat_Mo!$C:$C,RIGHT(E$2,5)) -> 18837 | F10: =SUMIFS(Wheat_Mo!$P:$P,Wheat_Mo!$B:$B,"Production",Wheat_Mo!$C:$C,RIGHT(F$2,5)) -> 19994.1 | G10: =SUMIFS(Wheat_Mo!$P:$P,Wheat_Mo!$B:$B,"Production",Wheat_Mo!$C:$C,RIGHT(G$2,5)) -> 19833.5 | H10: =SUMIFS(Wheat_Mo!$P:$P,Wheat_Mo!$B:$B,"Production",Wheat_Mo!$C:$C,RIGHT(H$2,5)) -> 21919.2 | I10: =SUMIFS(Wheat_Mo!$P:$P,Wheat_Mo!$B:$B,"Production",Wheat_Mo!$C:$C,RIGHT(I$2,5)) -> 16409 | J10: =SUMIFS(Wheat_Mo!$P:$P,Wheat_Mo!$B:$B,"Production",Wheat_Mo!$C:$C,RIGHT(J$2,5)) -> 23099.9 | K10: =SUMIFS(Wheat_Mo!$P:$P,Wheat_Mo!$B:$B,"Production",Wheat_Mo!$C:$C,RIGHT(K$2,5)) -> 21550.3 | ... Z10: =SUMIFS(Wheat_Mo!$P:$P,Wheat_Mo!$B:$B,"Production",Wheat_Mo!$C:$C,RIGHT(Z$2,5)) -> 29558.5
A11: Wheat Ex-Durum | B11: Total Supply | C11: KMT | D11: =D8+D9+D10 -> 17441.552 | E11: =E8+E9+E10 -> 22959.812 | F11: =F8+F9+F10 -> 24218.474 | G11: =G8+G9+G10 -> 25291.332 | H11: =H8+H9+H10 -> 28368.074 | I11: =I8+I9+I10 -> 22037.678 | J11: =J8+J9+J10 -> 26680.374 | K11: =K8+K9+K10 -> 26306.97 | ... Z11: =Z8+Z9+Z10 -> 34279.139
A13: Wheat Ex-Durum | B13: Food | C13: KMT | D13: =SUMIFS(Wheat_Mo!$P:$P,Wheat_Mo!$B:$B,"Food",Wheat_Mo!$C:$C,RIGHT(D$2,5)) -> 2687.4 | E13: =SUMIFS(Wheat_Mo!$P:$P,Wheat_Mo!$B:$B,"Food",Wheat_Mo!$C:$C,RIGHT(E$2,5)) -> 2656 | F13: =SUMIFS(Wheat_Mo!$P:$P,Wheat_Mo!$B:$B,"Food",Wheat_Mo!$C:$C,RIGHT(F$2,5)) -> 2710.5 | G13: =SUMIFS(Wheat_Mo!$P:$P,Wheat_Mo!$B:$B,"Food",Wheat_Mo!$C:$C,RIGHT(G$2,5)) -> 2742 | H13: =SUMIFS(Wheat_Mo!$P:$P,Wheat_Mo!$B:$B,"Food",Wheat_Mo!$C:$C,RIGHT(H$2,5)) -> 2703 | I13: =SUMIFS(Wheat_Mo!$P:$P,Wheat_Mo!$B:$B,"Food",Wheat_Mo!$C:$C,RIGHT(I$2,5)) -> 2628.3 | J13: =SUMIFS(Wheat_Mo!$P:$P,Wheat_Mo!$B:$B,"Food",Wheat_Mo!$C:$C,RIGHT(J$2,5)) -> 2509.2 | K13: =SUMIFS(Wheat_Mo!$P:$P,Wheat_Mo!$B:$B,"Food",Wheat_Mo!$C:$C,RIGHT(K$2,5)) -> 2569.8 | ... Z13: =SUMIFS(Wheat_Mo!$P:$P,Wheat_Mo!$B:$B,"Food",Wheat_Mo!$C:$C,RIGHT(Z$2,5)) -> 2944.5
A14: Wheat Ex-Durum | B14: Industrial | C14: KMT | D14: =SUMIFS(Wheat_Mo!$P:$P,Wheat_Mo!$B:$B,"Industrial",Wheat_Mo!$C:$C,RIGHT(D$2,5)) -> 109 | E14: =SUMIFS(Wheat_Mo!$P:$P,Wheat_Mo!$B:$B,"Industrial",Wheat_Mo!$C:$C,RIGHT(E$2,5)) -> 119 | F14: =SUMIFS(Wheat_Mo!$P:$P,Wheat_Mo!$B:$B,"Industrial",Wheat_Mo!$C:$C,RIGHT(F$2,5)) -> 134 | G14: =SUMIFS(Wheat_Mo!$P:$P,Wheat_Mo!$B:$B,"Industrial",Wheat_Mo!$C:$C,RIGHT(G$2,5)) -> 178 | H14: =SUMIFS(Wheat_Mo!$P:$P,Wheat_Mo!$B:$B,"Industrial",Wheat_Mo!$C:$C,RIGHT(H$2,5)) -> 411 | I14: =SUMIFS(Wheat_Mo!$P:$P,Wheat_Mo!$B:$B,"Industrial",Wheat_Mo!$C:$C,RIGHT(I$2,5)) -> 394 | J14: =SUMIFS(Wheat_Mo!$P:$P,Wheat_Mo!$B:$B,"Industrial",Wheat_Mo!$C:$C,RIGHT(J$2,5)) -> 646 | K14: =SUMIFS(Wheat_Mo!$P:$P,Wheat_Mo!$B:$B,"Industrial",Wheat_Mo!$C:$C,RIGHT(K$2,5)) -> 729 | ... Z14: =SUMIFS(Wheat_Mo!$P:$P,Wheat_Mo!$B:$B,"Industrial",Wheat_Mo!$C:$C,RIGHT(Z$2,5)) -> 356
A15: Wheat Ex-Durum | B15: FSR | C15: KMT | D15: =SUMIFS(Wheat_Mo!$P:$P,Wheat_Mo!$B:$B,"FSR",Wheat_Mo!$C:$C,RIGHT(D$2,5))+SUMIFS(Wheat_Mo!$P:$P,Wheat_Mo!$B:$B,"Seed",Wheat_Mo!$C:$C,RIGHT(D$2,5)) -> 4462.4 | E15: =SUMIFS(Wheat_Mo!$P:$P,Wheat_Mo!$B:$B,"FSR",Wheat_Mo!$C:$C,RIGHT(E$2,5))+SUMIFS(Wheat_Mo!$P:$P,Wheat_Mo!$B:$B,"Seed",Wheat_Mo!$C:$C,RIGHT(E$2,5)) -> 3919.694 | F15: =SUMIFS(Wheat_Mo!$P:$P,Wheat_Mo!$B:$B,"FSR",Wheat_Mo!$C:$C,RIGHT(F$2,5))+SUMIFS(Wheat_Mo!$P:$P,Wheat_Mo!$B:$B,"Seed",Wheat_Mo!$C:$C,RIGHT(F$2,5)) -> 4607.988 | G15: =SUMIFS(Wheat_Mo!$P:$P,Wheat_Mo!$B:$B,"FSR",Wheat_Mo!$C:$C,RIGHT(G$2,5))+SUMIFS(Wheat_Mo!$P:$P,Wheat_Mo!$B:$B,"Seed",Wheat_Mo!$C:$C,RIGHT(G$2,5)) -> 4453.024 | H15: =SUMIFS(Wheat_Mo!$P:$P,Wheat_Mo!$B:$B,"FSR",Wheat_Mo!$C:$C,RIGHT(H$2,5))+SUMIFS(Wheat_Mo!$P:$P,Wheat_Mo!$B:$B,"Seed",Wheat_Mo!$C:$C,RIGHT(H$2,5)) -> 5054.254 | I15: =SUMIFS(Wheat_Mo!$P:$P,Wheat_Mo!$B:$B,"FSR",Wheat_Mo!$C:$C,RIGHT(I$2,5))+SUMIFS(Wheat_Mo!$P:$P,Wheat_Mo!$B:$B,"Seed",Wheat_Mo!$C:$C,RIGHT(I$2,5)) -> 2831.956 | J15: =SUMIFS(Wheat_Mo!$P:$P,Wheat_Mo!$B:$B,"FSR",Wheat_Mo!$C:$C,RIGHT(J$2,5))+SUMIFS(Wheat_Mo!$P:$P,Wheat_Mo!$B:$B,"Seed",Wheat_Mo!$C:$C,RIGHT(J$2,5)) -> 3927.822 | K15: =SUMIFS(Wheat_Mo!$P:$P,Wheat_Mo!$B:$B,"FSR",Wheat_Mo!$C:$C,RIGHT(K$2,5))+SUMIFS(Wheat_Mo!$P:$P,Wheat_Mo!$B:$B,"Seed",Wheat_Mo!$C:$C,RIGHT(K$2,5)) -> 2082.664 | ... Z15: =SUMIFS(Wheat_Mo!$P:$P,Wheat_Mo!$B:$B,"FSR",Wheat_Mo!$C:$C,RIGHT(Z$2,5))+SUMIFS(Wheat_Mo!$P:$P,Wheat_Mo!$B:$B,"Seed",Wheat_Mo!$C:$C,RIGHT(Z$2,5)) -> 4041.738
A16: Wheat Ex-Durum | B16: Exports | C16: KMT | D16: =SUMIFS(Wheat_Mo!$P:$P,Wheat_Mo!$B:$B,"Exports",Wheat_Mo!$C:$C,RIGHT(D$2,5)) -> 6076.252 | E16: =SUMIFS(Wheat_Mo!$P:$P,Wheat_Mo!$B:$B,"Exports",Wheat_Mo!$C:$C,RIGHT(E$2,5)) -> 12054.018 | F16: =SUMIFS(Wheat_Mo!$P:$P,Wheat_Mo!$B:$B,"Exports",Wheat_Mo!$C:$C,RIGHT(F$2,5)) -> 11330.886 | G16: =SUMIFS(Wheat_Mo!$P:$P,Wheat_Mo!$B:$B,"Exports",Wheat_Mo!$C:$C,RIGHT(G$2,5)) -> 11494.208 | H16: =SUMIFS(Wheat_Mo!$P:$P,Wheat_Mo!$B:$B,"Exports",Wheat_Mo!$C:$C,RIGHT(H$2,5)) -> 14591.62 | I16: =SUMIFS(Wheat_Mo!$P:$P,Wheat_Mo!$B:$B,"Exports",Wheat_Mo!$C:$C,RIGHT(I$2,5)) -> 12626.022 | J16: =SUMIFS(Wheat_Mo!$P:$P,Wheat_Mo!$B:$B,"Exports",Wheat_Mo!$C:$C,RIGHT(J$2,5)) -> 14955.652 | K16: =SUMIFS(Wheat_Mo!$P:$P,Wheat_Mo!$B:$B,"Exports",Wheat_Mo!$C:$C,RIGHT(K$2,5)) -> 15876.506 | ... Z16: =SUMIFS(Wheat_Mo!$P:$P,Wheat_Mo!$B:$B,"Exports",Wheat_Mo!$C:$C,RIGHT(Z$2,5)) -> 23208.901
A17: Wheat Ex-Durum | B17: Total Disposition | C17: KMT | D17: =D13+D14+D15+D16 -> 13335.052 | E17: =E13+E14+E15+E16 -> 18748.712 | F17: =F13+F14+F15+F16 -> 18783.374 | G17: =G13+G14+G15+G16 -> 18867.232 | H17: =H13+H14+H15+H16 -> 22759.874 | I17: =I13+I14+I15+I16 -> 18480.278 | J17: =J13+J14+J15+J16 -> 22038.674 | K17: =K13+K14+K15+K16 -> 21257.97 | ... Z17: =Z13+Z14+Z15+Z16 -> 30551.139
A19: Wheat Ex-Durum | B19: Ending Stocks | C19: KMT | D19: =D11-D17 -> 4106.5 | E19: =E11-E17 -> 4211.1 | F19: =F11-F17 -> 5435.1 | G19: =G11-G17 -> 6424.1 | H19: =H11-H17 -> 5608.2 | I19: =I11-I17 -> 3557.4 | J19: =J11-J17 -> 4641.7 | K19: =K11-K17 -> 5049 | ... Z19: =Z11-Z17 -> 3728
A20: Wheat Ex-Durum | B20: Stocks-to-Use | C20: % | D20: =IF(D17<>0,D19/D17,"") -> 0.30794781 | E20: =IF(E17<>0,E19/E17,"") -> 0.22460743 | F20: =IF(F17<>0,F19/F17,"") -> 0.28935696 | G20: =IF(G17<>0,G19/G17,"") -> 0.3404898 | H20: =IF(H17<>0,H19/H17,"") -> 0.24640734 | I20: =IF(I17<>0,I19/I17,"") -> 0.1924971 | J20: =IF(J17<>0,J19/J17,"") -> 0.21061612 | K20: =IF(K17<>0,K19/K17,"") -> 0.23751092 | ... Z20: =IF(Z17<>0,Z19/Z17,"") -> 0.12202491
A21: Wheat Ex-Durum | B21: STU Days | C21: Days | D21: =IF(D17<>0,D19/D17*365,"") -> 112.40095 | E21: =IF(E17<>0,E19/E17*365,"") -> 81.981712 | F21: =IF(F17<>0,F19/F17*365,"") -> 105.61529 | G21: =IF(G17<>0,G19/G17*365,"") -> 124.27878 | H21: =IF(H17<>0,H19/H17*365,"") -> 89.938679 | I21: =IF(I17<>0,I19/I17*365,"") -> 70.261443 | J21: =IF(J17<>0,J19/J17*365,"") -> 76.874884 | K21: =IF(K17<>0,K19/K17*365,"") -> 86.691486 | ... Z21: =IF(Z17<>0,Z19/Z17*365,"") -> 44.539092
A22: Wheat Ex-Durum | B22: CHECK | C22: KMT | D22: =D19-SUMIFS(Wheat_Mo!$P:$P,Wheat_Mo!$B:$B,"STOCKS",Wheat_Mo!$C:$C,RIGHT(D$2,5)) -> 0 | E22: =E19-SUMIFS(Wheat_Mo!$P:$P,Wheat_Mo!$B:$B,"STOCKS",Wheat_Mo!$C:$C,RIGHT(E$2,5)) -> 1.4551915e-11 | F22: =F19-SUMIFS(Wheat_Mo!$P:$P,Wheat_Mo!$B:$B,"STOCKS",Wheat_Mo!$C:$C,RIGHT(F$2,5)) -> 2.0918378e-11 | G22: =G19-SUMIFS(Wheat_Mo!$P:$P,Wheat_Mo!$B:$B,"STOCKS",Wheat_Mo!$C:$C,RIGHT(G$2,5)) -> 9.094947e-12 | H22: =H19-SUMIFS(Wheat_Mo!$P:$P,Wheat_Mo!$B:$B,"STOCKS",Wheat_Mo!$C:$C,RIGHT(H$2,5)) -> 0 | I22: =I19-SUMIFS(Wheat_Mo!$P:$P,Wheat_Mo!$B:$B,"STOCKS",Wheat_Mo!$C:$C,RIGHT(I$2,5)) -> 0 | J22: =J19-SUMIFS(Wheat_Mo!$P:$P,Wheat_Mo!$B:$B,"STOCKS",Wheat_Mo!$C:$C,RIGHT(J$2,5)) -> 1.2732926e-11 | K22: =K19-SUMIFS(Wheat_Mo!$P:$P,Wheat_Mo!$B:$B,"STOCKS",Wheat_Mo!$C:$C,RIGHT(K$2,5)) -> 3.3651304e-11 | ... Z22: =Z19-SUMIFS(Wheat_Mo!$P:$P,Wheat_Mo!$B:$B,"STOCKS",Wheat_Mo!$C:$C,RIGHT(Z$2,5)) -> 6.5483619e-11
A25: =A22 -> Wheat Ex-Durum | B25: FS/Prod | D25: {=SUM(D13:D14/D$10)} -> 0.23140578 | E25: {=SUM(E13:E14/E$10)} -> 0.14731645 | F25: {=SUM(F13:F14/F$10)} -> 0.14226697 | G25: {=SUM(G13:G14/G$10)} -> 0.14722565 | H25: {=SUM(H13:H14/H$10)} -> 0.14206723 | I25: {=SUM(I13:I14/I$10)} -> 0.18418551 | J25: {=SUM(J13:J14/J$10)} -> 0.13658934 | K25: {=SUM(K13:K14/K$10)} -> 0.15307444 | ... Z25: {=SUM(Z13:Z14/Z$10)} -> 0.11165993
A26: =A25 -> Wheat Ex-Durum | B26: FSR/Prod | D26: =D15/D$10 -> 0.36926947 | E26: =E15/E$10 -> 0.20808483 | F26: =F15/F$10 -> 0.23046739 | G26: =G15/G$10 -> 0.22452033 | H26: =H15/H$10 -> 0.2305857 | I26: =I15/I$10 -> 0.17258553 | J26: =J15/J$10 -> 0.17003632 | K26: =K15/K$10 -> 0.096641996 | ... Z26: =Z15/Z$10 -> 0.13673691
A27: =A26 -> Wheat Ex-Durum | B27: Exp/Prod | D27: =D16/D$10 -> 0.50281785 | E27: =E16/E$10 -> 0.63991177 | F27: =F16/F$10 -> 0.56671148 | G27: =G16/G$10 -> 0.57953503 | H27: =H16/H$10 -> 0.66570039 | I27: =I16/I$10 -> 0.76945713 | J27: =J16/J$10 -> 0.64743363 | K27: =K16/K$10 -> 0.73671856 | ... Z27: =Z16/Z$10 -> 0.78518534
D29: =(D13-C13)/C13 -> #VALUE! | E29: =(E13-D13)/D13 -> -0.011684156 | F29: =(F13-E13)/E13 -> 0.020519578 | G29: =(G13-F13)/F13 -> 0.011621472 | H29: =(H13-G13)/G13 -> -0.014223195 | I29: =(I13-H13)/H13 -> -0.02763596 | J29: =(J13-I13)/I13 -> -0.045314462 | K29: =(K13-J13)/J13 -> 0.024151124 | ... Z29: =(Z13-Y13)/Y13 -> 0.009289093
D30: =(D14-C14)/C14 -> #VALUE! | E30: =(E14-D14)/D14 -> 0.091743119 | F30: =(F14-E14)/E14 -> 0.12605042 | G30: =(G14-F14)/F14 -> 0.32835821 | H30: =(H14-G14)/G14 -> 1.3089888 | I30: =(I14-H14)/H14 -> -0.04136253 | J30: =(J14-I14)/I14 -> 0.63959391 | K30: =(K14-J14)/J14 -> 0.12848297 | ... Z30: =(Z14-Y14)/Y14 -> -0.0019624334
D31: =(D15-C15)/C15 -> #VALUE! | E31: =(E15-D15)/D15 -> -0.12161752 | F31: =(F15-E15)/E15 -> 0.17559891 | G31: =(G15-F15)/F15 -> -0.033629428 | H31: =(H15-G15)/G15 -> 0.13501611 | I31: =(I15-H15)/H15 -> -0.43968863 | J31: =(J15-I15)/I15 -> 0.38696435 | K31: =(K15-J15)/J15 -> -0.4697662 | ... Z31: =(Z15-Y15)/Y15 -> -0.17957809
D32: =(D16-C16)/C16 -> #VALUE! | E32: =(E16-D16)/D16 -> 0.98379165 | F32: =(F16-E16)/E16 -> -0.059990951 | G32: =(G16-F16)/F16 -> 0.014413877 | H32: =(H16-G16)/G16 -> 0.2694759 | I32: =(I16-H16)/H16 -> -0.13470732 | J32: =(J16-I16)/I16 -> 0.18451021 | K32: =(K16-J16)/J16 -> 0.061572307 | ... Z32: =(Z16-Y16)/Y16 -> 0.07741283

Sheet Durum_Mo
A1: Commodity | B1: Metric | C1: Crop Year | D1: AUG | E1: SEP | F1: OCT | G1: NOV | H1: DEC | I1: JAN | J1: FEB | K1: MAR | L1: APR | M1: MAY | N1: JUN | O1: JUL | P1: AUG/JUL
A2: Durum wheat | B2: Planted Area | C2: 02-03 | D2: 6.125 | P2: =D2 -> 6.125
A3: Durum wheat | B3: Planted Area | C3: 03-04 | D3: 5.96 | P3: =D3 -> 5.96
A4: Durum wheat | B4: Planted Area | C4: 04-05 | D4: 5.285 | P4: =D4 -> 5.285
A5: Durum wheat | B5: Planted Area | C5: 05-06 | D5: 5.7 | P5: =D5 -> 5.7
A6: Durum wheat | B6: Planted Area | C6: 06-07 | D6: 3.79538 | P6: =D6 -> 3.79538
A7: Durum wheat | B7: Planted Area | C7: 07-08 | D7: 4.765 | P7: =D7 -> 4.765
A8: Durum wheat | B8: Planted Area | C8: 08-09 | D8: 6.03 | P8: =D8 -> 6.03
A9: Durum wheat | B9: Planted Area | C9: 09-10 | D9: 5.66 | P9: =D9 -> 5.66
A10: Durum wheat | B10: Planted Area | C10: 10-11 | D10: 3.15 | P10: =D10 -> 3.15
A11: Durum wheat | B11: Planted Area | C11: 11-12 | D11: 4.011018 | P11: =D11 -> 4.011018
A12: Durum wheat | B12: Planted Area | C12: 12-13 | D12: 4.625 | P12: =D12 -> 4.625
A13: Durum wheat | B13: Planted Area | C13: 13-14 | D13: 4.985 | P13: =D13 -> 4.985
... A93: Durum wheat | B93: Production | C93: 24-25 | D93: 6380.3 | P93: =D93 -> 6380.3
A94: Durum wheat | B94: Exports | C94: 02-03 | D94: 414.552 | E94: 297.094 | F94: 267.688 | G94: 167.284 | H94: 258.208 | I94: 181.278 | J94: 149.184 | K94: 87.454 | L94: 212.996 | M94: 353.506 | N94: 245.686 | O94: 350.084 | P94: =SUM(D94:O94) -> 2985.014
A95: Durum wheat | B95: Exports | C95: 03-04 | D95: 411.186 | E95: 337.574 | F95: 369.48 | G95: 358.792 | H95: 234.652 | I95: 344.048 | J95: 144.822 | K95: 153.258 | L95: 129.95 | M95: 241.972 | N95: 219.92 | O95: 495.534 | P95: =SUM(D95:O95) -> 3441.188
A96: Durum wheat | B96: Exports | C96: 04-05 | D96: 513.84 | E96: 364.616 | F96: 248.96 | G96: 255.612 | H96: 119.752 | I96: 156.41 | J96: 177.486 | K96: 164.35 | L96: 125.276 | M96: 458.464 | N96: 345.714 | O96: 256.422 | P96: =SUM(D96:O96) -> 3186.902
A97: Durum wheat | B97: Exports | C97: 05-06 | D97: 381.288 | E97: 382.586 | F97: 359.74 | G97: 417.894 | H97: 245.448 | I97: 339.882 | J97: 209.812 | K97: 332.726 | L97: 527.65 | M97: 350.16 | N97: 398.696 | O97: 205.564 | P97: =SUM(D97:O97) -> 4151.446
A98: Durum wheat | B98: Exports | C98: 06-07 | D98: 292.442 | E98: 375.264 | F98: 625.74 | G98: 474.874 | H98: 434.738 | I98: 295.188 | J98: 223.174 | K98: 196.308 | L98: 398.482 | M98: 428.046 | N98: 381.224 | O98: 332.096 | P98: =SUM(D98:O98) -> 4457.576
A99: Durum wheat | B99: Exports | C99: 07-08 | D99: 378.452 | E99: 128.256 | F99: 340.848 | G99: 357.714 | H99: 355.89 | I99: 341.108 | J99: 248.312 | K99: 214.058 | L99: 248.672 | M99: 316.414 | N99: 129.098 | O99: 131.946 | P99: =SUM(D99:O99) -> 3190.768
A100: Durum wheat | B100: Exports | C100: 08-09 | D100: 209.114 | E100: 65.39 | F100: 337.846 | G100: 470.54 | H100: 212.004 | I100: 260.832 | J100: 315.31 | K100: 209.994 | L100: 685.188 | M100: 379.364 | N100: 325.308 | O100: 211.256 | P100: =SUM(D100:O100) -> 3682.146
A101: Durum wheat | B101: Exports | C101: 09-10 | D101: 163.144 | E101: 283.424 | F101: 322.854 | G101: 265.098 | H101: 398.718 | I101: 256.162 | J101: 111.932 | K101: 161.032 | L101: 307.29 | M101: 320.008 | N101: 163.52 | O101: 130.304 | P101: =SUM(D101:O101) -> 2883.486
A102: Durum wheat | B102: Exports | C102: 10-11 | D102: 290.176 | E102: 361.55 | F102: 169.092 | G102: 345.41 | H102: 262.148 | I102: 210.46 | J102: 166.606 | K102: 151.362 | L102: 351.016 | M102: 213.788 | N102: 138.616 | O102: 317.64 | P102: =SUM(D102:O102) -> 2977.864
A103: Durum wheat | B103: Exports | C103: 11-12 | D103: 180.526 | E103: 397.608 | F103: 178.8 | G103: 431.714 | H103: 252.332 | I103: 156.458 | J103: 257.121 | K103: 265.129 | L103: 432.695 | M103: 407.323 | N103: 203.983 | O103: 190.325 | P103: =SUM(D103:O103) -> 3354.014
A104: Durum wheat | B104: Exports | C104: 12-13 | D104: 391.684 | E104: 255.012 | F104: 555.281 | G104: 453.701 | H104: 324.959 | I104: 407.946 | J104: 189.717 | K104: 351.419 | L104: 491.837 | M104: 473.373 | N104: 189.314 | O104: 230.718 | P104: =SUM(D104:O104) -> 4314.961
A105: Durum wheat | B105: Exports | C105: 13-14 | D105: 393.827 | E105: 338.098 | F105: 383.67 | G105: 358.168 | H105: 447.795 | I105: 409.517 | J105: 311.298 | K105: 428.465 | L105: 387.447 | M105: 575.928 | N105: 335.924 | O105: 635.319 | P105: =SUM(D105:O105) -> 5005.456
... A208: Durum wheat | B208: Seed | C208: 24-25 | D208: 0 | E208: 0 | F208: 0 | G208: 0 | H208: 0 | I208: 0 | J208: 0 | K208: 0 | L208: 0 | M208: 0 | N208: 0 | O208: 0 | P208: =SUM(D208:O208) -> 0
A209: Durum wheat | B209: Food & Processing | C209: 02-03 | D209: =D140+D163 -> 23.025 | E209: =E140+E163 -> 23.025 | F209: =F140+F163 -> 23.025 | G209: =G140+G163 -> 23.025 | H209: =H140+H163 -> 23.025 | I209: =I140+I163 -> 23.025 | J209: =J140+J163 -> 23.025 | K209: =K140+K163 -> 23.025 | ... O209: =O140+O163 -> 23.025 | P209: =SUM(D209:O209) -> 276.3
A210: Durum wheat | B210: Food & Processing | C210: 03-04 | D210: =D141+D164 -> 20.958333 | E210: =E141+E164 -> 20.958333 | F210: =F141+F164 -> 20.958333 | G210: =G141+G164 -> 20.958333 | H210: =H141+H164 -> 20.958333 | I210: =I141+I164 -> 20.958333 | J210: =J141+J164 -> 20.958333 | K210: =K141+K164 -> 20.958333 | ... O210: =O141+O164 -> 20.958333 | P210: =SUM(D210:O210) -> 251.5
A211: Durum wheat | B211: Food & Processing | C211: 04-05 | D211: =D142+D165 -> 21.183333 | E211: =E142+E165 -> 21.183333 | F211: =F142+F165 -> 21.183333 | G211: =G142+G165 -> 21.183333 | H211: =H142+H165 -> 21.183333 | I211: =I142+I165 -> 21.183333 | J211: =J142+J165 -> 21.183333 | K211: =K142+K165 -> 21.183333 | ... O211: =O142+O165 -> 21.183333 | P211: =SUM(D211:O211) -> 254.2
A212: Durum wheat | B212: Food & Processing | C212: 05-06 | D212: =D143+D166 -> 20.675 | E212: =E143+E166 -> 20.675 | F212: =F143+F166 -> 20.675 | G212: =G143+G166 -> 20.675 | H212: =H143+H166 -> 20.675 | I212: =I143+I166 -> 20.675 | J212: =J143+J166 -> 20.675 | K212: =K143+K166 -> 20.675 | ... O212: =O143+O166 -> 20.675 | P212: =SUM(D212:O212) -> 248.1
A213: Durum wheat | B213: Food & Processing | C213: 06-07 | D213: =D144+D167 -> 21.375 | E213: =E144+E167 -> 21.375 | F213: =F144+F167 -> 21.375 | G213: =G144+G167 -> 21.375 | H213: =H144+H167 -> 21.375 | I213: =I144+I167 -> 21.375 | J213: =J144+J167 -> 21.375 | K213: =K144+K167 -> 21.375 | ... O213: =O144+O167 -> 21.375 | P213: =SUM(D213:O213) -> 256.5
A214: Durum wheat | B214: Food & Processing | C214: 07-08 | D214: =D145+D168 -> 19.041667 | E214: =E145+E168 -> 19.041667 | F214: =F145+F168 -> 19.041667 | G214: =G145+G168 -> 19.041667 | H214: =H145+H168 -> 19.041667 | I214: =I145+I168 -> 19.041667 | J214: =J145+J168 -> 19.041667 | K214: =K145+K168 -> 19.041667 | ... O214: =O145+O168 -> 19.041667 | P214: =SUM(D214:O214) -> 228.5
A215: Durum wheat | B215: Food & Processing | C215: 08-09 | D215: =D146+D169 -> 19.691667 | E215: =E146+E169 -> 19.691667 | F215: =F146+F169 -> 19.691667 | G215: =G146+G169 -> 19.691667 | H215: =H146+H169 -> 19.691667 | I215: =I146+I169 -> 19.691667 | J215: =J146+J169 -> 19.691667 | K215: =K146+K169 -> 19.691667 | ... O215: =O146+O169 -> 19.691667 | P215: =SUM(D215:O215) -> 236.3
A216: Durum wheat | B216: Food & Processing | C216: 09-10 | D216: =D147+D170 -> 21.733333 | E216: =E147+E170 -> 21.733333 | F216: =F147+F170 -> 21.733333 | G216: =G147+G170 -> 21.733333 | H216: =H147+H170 -> 21.733333 | I216: =I147+I170 -> 21.733333 | J216: =J147+J170 -> 21.733333 | K216: =K147+K170 -> 21.733333 | ... O216: =O147+O170 -> 21.733333 | P216: =SUM(D216:O216) -> 260.8
A217: Durum wheat | B217: Food & Processing | C217: 10-11 | D217: =D148+D171 -> 21.216667 | E217: =E148+E171 -> 21.216667 | F217: =F148+F171 -> 21.216667 | G217: =G148+G171 -> 21.216667 | H217: =H148+H171 -> 21.216667 | I217: =I148+I171 -> 21.216667 | J217: =J148+J171 -> 21.216667 | K217: =K148+K171 -> 21.216667 | ... O217: =O148+O171 -> 21.216667 | P217: =SUM(D217:O217) -> 254.6
A218: Durum wheat | B218: Food & Processing | C218: 11-12 | D218: =D149+D172 -> 19.366667 | E218: =E149+E172 -> 19.366667 | F218: =F149+F172 -> 19.366667 | G218: =G149+G172 -> 19.366667 | H218: =H149+H172 -> 19.366667 | I218: =I149+I172 -> 19.366667 | J218: =J149+J172 -> 19.366667 | K218: =K149+K172 -> 19.366667 | ... O218: =O149+O172 -> 19.366667 | P218: =SUM(D218:O218) -> 232.4
A219: Durum wheat | B219: Food & Processing | C219: 12-13 | D219: =D150+D173 -> 19.258333 | E219: =E150+E173 -> 19.258333 | F219: =F150+F173 -> 19.258333 | G219: =G150+G173 -> 19.258333 | H219: =H150+H173 -> 19.258333 | I219: =I150+I173 -> 19.258333 | J219: =J150+J173 -> 19.258333 | K219: =K150+K173 -> 19.258333 | ... O219: =O150+O173 -> 19.258333 | P219: =SUM(D219:O219) -> 231.1
A220: Durum wheat | B220: Food & Processing | C220: 13-14 | D220: =D151+D174 -> 19.691667 | E220: =E151+E174 -> 19.691667 | F220: =F151+F174 -> 19.691667 | G220: =G151+G174 -> 19.691667 | H220: =H151+H174 -> 19.691667 | I220: =I151+I174 -> 19.691667 | J220: =J151+J174 -> 19.691667 | K220: =K151+K174 -> 19.691667 | ... O220: =O151+O174 -> 19.691667 | P220: =SUM(D220:O220) -> 236.3
... A231: Durum wheat | B231: Food & Processing | C231: 24-25 | D231: =D162+D185 -> 16.075 | E231: =E162+E185 -> 16.075 | F231: =F162+F185 -> 16.075 | G231: =G162+G185 -> 16.075 | H231: =H162+H185 -> 16.075 | I231: =I162+I185 -> 16.075 | J231: =J162+J185 -> 16.075 | K231: =K162+K185 -> 16.075 | ... O231: =O162+O185 -> 16.075 | P231: =SUM(D231:O231) -> 192.9
...

Sheet Durum_Yr
A1: Durum
A2: Commodity | B2: Metric | C2: Unit | D2: 02-03 | E2: 03-04 | F2: 04-05 | G2: 05-06 | H2: 06-07 | I2: 07-08 | J2: 08-09 | K2: 09-10 | L2: 10-11 | M2: 11-12 | N2: 12-13 | O2: 13-14 | P2: 14-15 | Q2: 15-16 | R2: 16-17 | S2: 17-18 | T2: 18-19 | U2: 19-20 | V2: 20-21 | W2: 21-22 | X2: 22-23 | Y2: 23-24 | Z2: 24-25
A3: Durum | B3: Planted Area | C3: MLN AC | D3: =SUMIFS(Durum_Mo!$P:$P,Durum_Mo!$B:$B,"Planted Area",Durum_Mo!$C:$C,RIGHT(D$2,5)) -> 6.125 | E3: =SUMIFS(Durum_Mo!$P:$P,Durum_Mo!$B:$B,"Planted Area",Durum_Mo!$C:$C,RIGHT(E$2,5)) -> 5.96 | F3: =SUMIFS(Durum_Mo!$P:$P,Durum_Mo!$B:$B,"Planted Area",Durum_Mo!$C:$C,RIGHT(F$2,5)) -> 5.285 | G3: =SUMIFS(Durum_Mo!$P:$P,Durum_Mo!$B:$B,"Planted Area",Durum_Mo!$C:$C,RIGHT(G$2,5)) -> 5.7 | H3: =SUMIFS(Durum_Mo!$P:$P,Durum_Mo!$B:$B,"Planted Area",Durum_Mo!$C:$C,RIGHT(H$2,5)) -> 3.79538 | I3: =SUMIFS(Durum_Mo!$P:$P,Durum_Mo!$B:$B,"Planted Area",Durum_Mo!$C:$C,RIGHT(I$2,5)) -> 4.765 | J3: =SUMIFS(Durum_Mo!$P:$P,Durum_Mo!$B:$B,"Planted Area",Durum_Mo!$C:$C,RIGHT(J$2,5)) -> 6.03 | K3: =SUMIFS(Durum_Mo!$P:$P,Durum_Mo!$B:$B,"Planted Area",Durum_Mo!$C:$C,RIGHT(K$2,5)) -> 5.66 | ... Z3: =SUMIFS(Durum_Mo!$P:$P,Durum_Mo!$B:$B,"Planted Area",Durum_Mo!$C:$C,RIGHT(Z$2,5)) -> 6.3644
A4: Durum | B4: Harvested Area | C4: MLN AC | D4: =SUMIFS(Durum_Mo!$P:$P,Durum_Mo!$B:$B,"Harvested Area",Durum_Mo!$C:$C,RIGHT(D$2,5)) -> 5.55 | E4: =SUMIFS(Durum_Mo!$P:$P,Durum_Mo!$B:$B,"Harvested Area",Durum_Mo!$C:$C,RIGHT(E$2,5)) -> 5.915 | F4: =SUMIFS(Durum_Mo!$P:$P,Durum_Mo!$B:$B,"Harvested Area",Durum_Mo!$C:$C,RIGHT(F$2,5)) -> 5.07 | G4: =SUMIFS(Durum_Mo!$P:$P,Durum_Mo!$B:$B,"Harvested Area",Durum_Mo!$C:$C,RIGHT(G$2,5)) -> 5.63 | H4: =SUMIFS(Durum_Mo!$P:$P,Durum_Mo!$B:$B,"Harvested Area",Durum_Mo!$C:$C,RIGHT(H$2,5)) -> 3.75 | I4: =SUMIFS(Durum_Mo!$P:$P,Durum_Mo!$B:$B,"Harvested Area",Durum_Mo!$C:$C,RIGHT(I$2,5)) -> 4.71 | J4: =SUMIFS(Durum_Mo!$P:$P,Durum_Mo!$B:$B,"Harvested Area",Durum_Mo!$C:$C,RIGHT(J$2,5)) -> 5.97 | K4: =SUMIFS(Durum_Mo!$P:$P,Durum_Mo!$B:$B,"Harvested Area",Durum_Mo!$C:$C,RIGHT(K$2,5)) -> 5.51 | ... Z4: =SUMIFS(Durum_Mo!$P:$P,Durum_Mo!$B:$B,"Harvested Area",Durum_Mo!$C:$C,RIGHT(Z$2,5)) -> 6.3388
A5: Durum | B5: Proportion Harvested | C5: % | D5: =IF(D3<>0,D4/D3,"") -> 0.90612245 | E5: =IF(E3<>0,E4/E3,"") -> 0.99244966 | F5: =IF(F3<>0,F4/F3,"") -> 0.95931883 | G5: =IF(G3<>0,G4/G3,"") -> 0.9877193 | H5: =IF(H3<>0,H4/H3,"") -> 0.98804336 | I5: =IF(I3<>0,I4/I3,"") -> 0.9884575 | J5: =IF(J3<>0,J4/J3,"") -> 0.99004975 | K5: =IF(K3<>0,K4/K3,"") -> 0.97349823 | ... Z5: =IF(Z3<>0,Z4/Z3,"") -> 0.99597763
A6: Durum | B6: Yield | C6: BU/AC | D6: =SUMIFS(Durum_Mo!$P:$P,Durum_Mo!$B:$B,"Yield",Durum_Mo!$C:$C,RIGHT(D$2,5)) -> 25.666964 | E6: =SUMIFS(Durum_Mo!$P:$P,Durum_Mo!$B:$B,"Yield",Durum_Mo!$C:$C,RIGHT(E$2,5)) -> 26.16226 | F6: =SUMIFS(Durum_Mo!$P:$P,Durum_Mo!$B:$B,"Yield",Durum_Mo!$C:$C,RIGHT(F$2,5)) -> 34.797081 | G6: =SUMIFS(Durum_Mo!$P:$P,Durum_Mo!$B:$B,"Yield",Durum_Mo!$C:$C,RIGHT(G$2,5)) -> 38.601117 | H6: =SUMIFS(Durum_Mo!$P:$P,Durum_Mo!$B:$B,"Yield",Durum_Mo!$C:$C,RIGHT(H$2,5)) -> 32.787138 | I6: =SUMIFS(Durum_Mo!$P:$P,Durum_Mo!$B:$B,"Yield",Durum_Mo!$C:$C,RIGHT(I$2,5)) -> 28.719375 | J6: =SUMIFS(Durum_Mo!$P:$P,Durum_Mo!$B:$B,"Yield",Durum_Mo!$C:$C,RIGHT(J$2,5)) -> 33.969766 | K6: =SUMIFS(Durum_Mo!$P:$P,Durum_Mo!$B:$B,"Yield",Durum_Mo!$C:$C,RIGHT(K$2,5)) -> 36.007492 | ... Z6: =SUMIFS(Durum_Mo!$P:$P,Durum_Mo!$B:$B,"Yield",Durum_Mo!$C:$C,RIGHT(Z$2,5)) -> 36.98426
A8: Durum | B8: Beginning Stocks | C8: KMT | D8: =SUMIFS(Durum_Mo!$D:$D,Durum_Mo!$B:$B,"STOCKS",Durum_Mo!$C:$C,RIGHT(D$2,5))-SUMIFS(Durum_Mo!$D:$D,Durum_Mo!$B:$B,"Production",Durum_Mo!$C:$C,RIGHT(D$2,5))-SUMIFS(Durum_Mo!$D:$D,Durum_Mo!$B:$B,"Imports",Durum_Mo!$C:$C,RIGHT(D$2,5))+SUMIFS(Durum_Mo!$D:$D,Durum_Mo!$B:$B,"Exports",Durum_Mo!$C:$C,RIGHT(D$2,5))+SUMIFS(Durum_Mo!$D:$D,Durum_Mo!$B:$B,"Food & Processing",Durum_Mo!$C:$C,RIGHT(D$2,5))+SUMIFS(Durum_Mo!$D:$D,Durum_Mo!$B:$B,"FSR",Durum_Mo!$C:$C,RIGHT(D$2,5))+SUMIFS(Durum_Mo!$D:$D,Durum_Mo!$B:$B,"Seed",Durum_Mo!$C:$C,RIGHT(D$2,5)) -> 1544.9 | E8: =D19 -> 1608.6 | F8: =E19 -> 1774.1 | G8: =F19 -> 2486.9 | H8: =G19 -> 3273.4 | I8: =H19 -> 1256.8 | J8: =I19 -> 808.7 | K8: =J19 -> 2003.1 | L8: =K19 -> 2693.9 | ... Z8: =Y19 -> 668.9
A9: Durum | B9: Imports | C9: KMT | D9: =SUMIFS(Durum_Mo!$P:$P,Durum_Mo!$B:$B,"Imports",Durum_Mo!$C:$C,RIGHT(D$2,5)) -> 5.546 | E9: =SUMIFS(Durum_Mo!$P:$P,Durum_Mo!$B:$B,"Imports",Durum_Mo!$C:$C,RIGHT(E$2,5)) -> 1.344 | F9: =SUMIFS(Durum_Mo!$P:$P,Durum_Mo!$B:$B,"Imports",Durum_Mo!$C:$C,RIGHT(F$2,5)) -> 0.828 | G9: =SUMIFS(Durum_Mo!$P:$P,Durum_Mo!$B:$B,"Imports",Durum_Mo!$C:$C,RIGHT(G$2,5)) -> 3.628 | H9: =SUMIFS(Durum_Mo!$P:$P,Durum_Mo!$B:$B,"Imports",Durum_Mo!$C:$C,RIGHT(H$2,5)) -> 0.868 | I9: =SUMIFS(Durum_Mo!$P:$P,Durum_Mo!$B:$B,"Imports",Durum_Mo!$C:$C,RIGHT(I$2,5)) -> 2.926 | J9: =SUMIFS(Durum_Mo!$P:$P,Durum_Mo!$B:$B,"Imports",Durum_Mo!$C:$C,RIGHT(J$2,5)) -> 2.38 | K9: =SUMIFS(Durum_Mo!$P:$P,Durum_Mo!$B:$B,"Imports",Durum_Mo!$C:$C,RIGHT(K$2,5)) -> 2.442 | ... Z9: =SUMIFS(Durum_Mo!$P:$P,Durum_Mo!$B:$B,"Imports",Durum_Mo!$C:$C,RIGHT(Z$2,5)) -> 5.075
A10: Durum | B10: Production | C10: KMT | D10: =SUMIFS(Durum_Mo!$P:$P,Durum_Mo!$B:$B,"Production",Durum_Mo!$C:$C,RIGHT(D$2,5)) -> 3876.9 | E10: =SUMIFS(Durum_Mo!$P:$P,Durum_Mo!$B:$B,"Production",Durum_Mo!$C:$C,RIGHT(E$2,5)) -> 4211.6 | F10: =SUMIFS(Durum_Mo!$P:$P,Durum_Mo!$B:$B,"Production",Durum_Mo!$C:$C,RIGHT(F$2,5)) -> 4801.4 | G10: =SUMIFS(Durum_Mo!$P:$P,Durum_Mo!$B:$B,"Production",Durum_Mo!$C:$C,RIGHT(G$2,5)) -> 5914.6 | H10: =SUMIFS(Durum_Mo!$P:$P,Durum_Mo!$B:$B,"Production",Durum_Mo!$C:$C,RIGHT(H$2,5)) -> 3346.2 | I10: =SUMIFS(Durum_Mo!$P:$P,Durum_Mo!$B:$B,"Production",Durum_Mo!$C:$C,RIGHT(I$2,5)) -> 3681.4 | J10: =SUMIFS(Durum_Mo!$P:$P,Durum_Mo!$B:$B,"Production",Durum_Mo!$C:$C,RIGHT(J$2,5)) -> 5519.3 | K10: =SUMIFS(Durum_Mo!$P:$P,Durum_Mo!$B:$B,"Production",Durum_Mo!$C:$C,RIGHT(K$2,5)) -> 5399.6 | ... Z10: =SUMIFS(Durum_Mo!$P:$P,Durum_Mo!$B:$B,"Production",Durum_Mo!$C:$C,RIGHT(Z$2,5)) -> 6380.3
A11: Durum | B11: Total Supply | C11: KMT | D11: =D8+D9+D10 -> 5427.346 | E11: =E8+E9+E10 -> 5821.544 | F11: =F8+F9+F10 -> 6576.328 | G11: =G8+G9+G10 -> 8405.128 | H11: =H8+H9+H10 -> 6620.468 | I11: =I8+I9+I10 -> 4941.126 | J11: =J8+J9+J10 -> 6330.38 | K11: =K8+K9+K10 -> 7405.142 | ... Z11: =Z8+Z9+Z10 -> 7054.275
A13: Durum | B13: Food | C13: KMT | D13: =SUMIFS(Durum_Mo!$P:$P,Durum_Mo!$B:$B,"Food",Durum_Mo!$C:$C,RIGHT(D$2,5)) -> 276.3 | E13: =SUMIFS(Durum_Mo!$P:$P,Durum_Mo!$B:$B,"Food",Durum_Mo!$C:$C,RIGHT(E$2,5)) -> 251.5 | F13: =SUMIFS(Durum_Mo!$P:$P,Durum_Mo!$B:$B,"Food",Durum_Mo!$C:$C,RIGHT(F$2,5)) -> 254.2 | G13: =SUMIFS(Durum_Mo!$P:$P,Durum_Mo!$B:$B,"Food",Durum_Mo!$C:$C,RIGHT(G$2,5)) -> 248.1 | H13: =SUMIFS(Durum_Mo!$P:$P,Durum_Mo!$B:$B,"Food",Durum_Mo!$C:$C,RIGHT(H$2,5)) -> 256.5 | I13: =SUMIFS(Durum_Mo!$P:$P,Durum_Mo!$B:$B,"Food",Durum_Mo!$C:$C,RIGHT(I$2,5)) -> 228.5 | J13: =SUMIFS(Durum_Mo!$P:$P,Durum_Mo!$B:$B,"Food",Durum_Mo!$C:$C,RIGHT(J$2,5)) -> 236.3 | K13: =SUMIFS(Durum_Mo!$P:$P,Durum_Mo!$B:$B,"Food",Durum_Mo!$C:$C,RIGHT(K$2,5)) -> 260.8 | ... Z13: =SUMIFS(Durum_Mo!$P:$P,Durum_Mo!$B:$B,"Food",Durum_Mo!$C:$C,RIGHT(Z$2,5)) -> 192.9
A14: Durum | B14: Industrial | C14: KMT | D14: =SUMIFS(Durum_Mo!$P:$P,Durum_Mo!$B:$B,"Industrial",Durum_Mo!$C:$C,RIGHT(D$2,5)) -> 0 | E14: =SUMIFS(Durum_Mo!$P:$P,Durum_Mo!$B:$B,"Industrial",Durum_Mo!$C:$C,RIGHT(E$2,5)) -> 0 | F14: =SUMIFS(Durum_Mo!$P:$P,Durum_Mo!$B:$B,"Industrial",Durum_Mo!$C:$C,RIGHT(F$2,5)) -> 0 | G14: =SUMIFS(Durum_Mo!$P:$P,Durum_Mo!$B:$B,"Industrial",Durum_Mo!$C:$C,RIGHT(G$2,5)) -> 0 | H14: =SUMIFS(Durum_Mo!$P:$P,Durum_Mo!$B:$B,"Industrial",Durum_Mo!$C:$C,RIGHT(H$2,5)) -> 0 | I14: =SUMIFS(Durum_Mo!$P:$P,Durum_Mo!$B:$B,"Industrial",Durum_Mo!$C:$C,RIGHT(I$2,5)) -> 0 | J14: =SUMIFS(Durum_Mo!$P:$P,Durum_Mo!$B:$B,"Industrial",Durum_Mo!$C:$C,RIGHT(J$2,5)) -> 0 | K14: =SUMIFS(Durum_Mo!$P:$P,Durum_Mo!$B:$B,"Industrial",Durum_Mo!$C:$C,RIGHT(K$2,5)) -> 0 | ... Z14: =SUMIFS(Durum_Mo!$P:$P,Durum_Mo!$B:$B,"Industrial",Durum_Mo!$C:$C,RIGHT(Z$2,5)) -> 0
A15: Durum | B15: FSR | C15: KMT | D15: =SUMIFS(Durum_Mo!$P:$P,Durum_Mo!$B:$B,"FSR",Durum_Mo!$C:$C,RIGHT(D$2,5))+SUMIFS(Durum_Mo!$P:$P,Durum_Mo!$B:$B,"Seed",Durum_Mo!$C:$C,RIGHT(D$2,5)) -> 557.432 | E15: =SUMIFS(Durum_Mo!$P:$P,Durum_Mo!$B:$B,"FSR",Durum_Mo!$C:$C,RIGHT(E$2,5))+SUMIFS(Durum_Mo!$P:$P,Durum_Mo!$B:$B,"Seed",Durum_Mo!$C:$C,RIGHT(E$2,5)) -> 354.756 | F15: =SUMIFS(Durum_Mo!$P:$P,Durum_Mo!$B:$B,"FSR",Durum_Mo!$C:$C,RIGHT(F$2,5))+SUMIFS(Durum_Mo!$P:$P,Durum_Mo!$B:$B,"Seed",Durum_Mo!$C:$C,RIGHT(F$2,5)) -> 648.326 | G15: =SUMIFS(Durum_Mo!$P:$P,Durum_Mo!$B:$B,"FSR",Durum_Mo!$C:$C,RIGHT(G$2,5))+SUMIFS(Durum_Mo!$P:$P,Durum_Mo!$B:$B,"Seed",Durum_Mo!$C:$C,RIGHT(G$2,5)) -> 732.182 | H15: =SUMIFS(Durum_Mo!$P:$P,Durum_Mo!$B:$B,"FSR",Durum_Mo!$C:$C,RIGHT(H$2,5))+SUMIFS(Durum_Mo!$P:$P,Durum_Mo!$B:$B,"Seed",Durum_Mo!$C:$C,RIGHT(H$2,5)) -> 649.592 | I15: =SUMIFS(Durum_Mo!$P:$P,Durum_Mo!$B:$B,"FSR",Durum_Mo!$C:$C,RIGHT(I$2,5))+SUMIFS(Durum_Mo!$P:$P,Durum_Mo!$B:$B,"Seed",Durum_Mo!$C:$C,RIGHT(I$2,5)) -> 713.158 | J15: =SUMIFS(Durum_Mo!$P:$P,Durum_Mo!$B:$B,"FSR",Durum_Mo!$C:$C,RIGHT(J$2,5))+SUMIFS(Durum_Mo!$P:$P,Durum_Mo!$B:$B,"Seed",Durum_Mo!$C:$C,RIGHT(J$2,5)) -> 408.834 | K15: =SUMIFS(Durum_Mo!$P:$P,Durum_Mo!$B:$B,"FSR",Durum_Mo!$C:$C,RIGHT(K$2,5))+SUMIFS(Durum_Mo!$P:$P,Durum_Mo!$B:$B,"Seed",Durum_Mo!$C:$C,RIGHT(K$2,5)) -> 1566.956 | ... Z15: =SUMIFS(Durum_Mo!$P:$P,Durum_Mo!$B:$B,"FSR",Durum_Mo!$C:$C,RIGHT(Z$2,5))+SUMIFS(Durum_Mo!$P:$P,Durum_Mo!$B:$B,"Seed",Durum_Mo!$C:$C,RIGHT(Z$2,5)) -> 549.981
A16: Durum | B16: Exports | C16: KMT | D16: =SUMIFS(Durum_Mo!$P:$P,Durum_Mo!$B:$B,"Exports",Durum_Mo!$C:$C,RIGHT(D$2,5)) -> 2985.014 | E16: =SUMIFS(Durum_Mo!$P:$P,Durum_Mo!$B:$B,"Exports",Durum_Mo!$C:$C,RIGHT(E$2,5)) -> 3441.188 | F16: =SUMIFS(Durum_Mo!$P:$P,Durum_Mo!$B:$B,"Exports",Durum_Mo!$C:$C,RIGHT(F$2,5)) -> 3186.902 | G16: =SUMIFS(Durum_Mo!$P:$P,Durum_Mo!$B:$B,"Exports",Durum_Mo!$C:$C,RIGHT(G$2,5)) -> 4151.446 | H16: =SUMIFS(Durum_Mo!$P:$P,Durum_Mo!$B:$B,"Exports",Durum_Mo!$C:$C,RIGHT(H$2,5)) -> 4457.576 | I16: =SUMIFS(Durum_Mo!$P:$P,Durum_Mo!$B:$B,"Exports",Durum_Mo!$C:$C,RIGHT(I$2,5)) -> 3190.768 | J16: =SUMIFS(Durum_Mo!$P:$P,Durum_Mo!$B:$B,"Exports",Durum_Mo!$C:$C,RIGHT(J$2,5)) -> 3682.146 | K16: =SUMIFS(Durum_Mo!$P:$P,Durum_Mo!$B:$B,"Exports",Durum_Mo!$C:$C,RIGHT(K$2,5)) -> 2883.486 | ... Z16: =SUMIFS(Durum_Mo!$P:$P,Durum_Mo!$B:$B,"Exports",Durum_Mo!$C:$C,RIGHT(Z$2,5)) -> 5799.494
A17: Durum | B17: Total Disposition | C17: KMT | D17: =D13+D14+D15+D16 -> 3818.746 | E17: =E13+E14+E15+E16 -> 4047.444 | F17: =F13+F14+F15+F16 -> 4089.428 | G17: =G13+G14+G15+G16 -> 5131.728 | H17: =H13+H14+H15+H16 -> 5363.668 | I17: =I13+I14+I15+I16 -> 4132.426 | J17: =J13+J14+J15+J16 -> 4327.28 | K17: =K13+K14+K15+K16 -> 4711.242 | ... Z17: =Z13+Z14+Z15+Z16 -> 6542.375
A19: Durum | B19: Ending Stocks | C19: KMT | D19: =D11-D17 -> 1608.6 | E19: =E11-E17 -> 1774.1 | F19: =F11-F17 -> 2486.9 | G19: =G11-G17 -> 3273.4 | H19: =H11-H17 -> 1256.8 | I19: =I11-I17 -> 808.7 | J19: =J11-J17 -> 2003.1 | K19: =K11-K17 -> 2693.9 | ... Z19: =Z11-Z17 -> 511.9
A20: Durum | B20: Stocks-to-Use | C20: % | D20: =IF(D17<>0,D19/D17,"") -> 0.42123776 | E20: =IF(E17<>0,E19/E17,"") -> 0.43832602 | F20: =IF(F17<>0,F19/F17,"") -> 0.60812906 | G20: =IF(G17<>0,G19/G17,"") -> 0.63787481 | H20: =IF(H17<>0,H19/H17,"") -> 0.23431726 | I20: =IF(I17<>0,I19/I17,"") -> 0.19569618 | J20: =IF(J17<>0,J19/J17,"") -> 0.46290048 | K20: =IF(K17<>0,K19/K17,"") -> 0.57180251 | ... Z20: =IF(Z17<>0,Z19/Z17,"") -> 0.078243757
A21: Durum | B21: STU Days | C21: Days | D21: =IF(D17<>0,D19/D17*365,"") -> 153.75178 | E21: =IF(E17<>0,E19/E17*365,"") -> 159.989 | F21: =IF(F17<>0,F19/F17*365,"") -> 221.96711 | G21: =IF(G17<>0,G19/G17*365,"") -> 232.8243 | H21: =IF(H17<>0,H19/H17*365,"") -> 85.525801 | I21: =IF(I17<>0,I19/I17*365,"") -> 71.429107 | J21: =IF(J17<>0,J19/J17*365,"") -> 168.95868 | K21: =IF(K17<>0,K19/K17*365,"") -> 208.70792 | ... Z21: =IF(Z17<>0,Z19/Z17*365,"") -> 28.558971
A22: Durum | B22: CHECK | C22: KMT | D22: =D19-SUMIFS(Durum_Mo!$P:$P,Durum_Mo!$B:$B,"STOCKS",Durum_Mo!$C:$C,RIGHT(D$2,5)) -> 0 | E22: =E19-SUMIFS(Durum_Mo!$P:$P,Durum_Mo!$B:$B,"STOCKS",Durum_Mo!$C:$C,RIGHT(E$2,5)) -> 2.0463631e-12 | F22: =F19-SUMIFS(Durum_Mo!$P:$P,Durum_Mo!$B:$B,"STOCKS",Durum_Mo!$C:$C,RIGHT(F$2,5)) -> 0 | G22: =G19-SUMIFS(Durum_Mo!$P:$P,Durum_Mo!$B:$B,"STOCKS",Durum_Mo!$C:$C,RIGHT(G$2,5)) -> 9.094947e-12 | H22: =H19-SUMIFS(Durum_Mo!$P:$P,Durum_Mo!$B:$B,"STOCKS",Durum_Mo!$C:$C,RIGHT(H$2,5)) -> 8.412826e-12 | I22: =I19-SUMIFS(Durum_Mo!$P:$P,Durum_Mo!$B:$B,"STOCKS",Durum_Mo!$C:$C,RIGHT(I$2,5)) -> 7.730705e-12 | J22: =J19-SUMIFS(Durum_Mo!$P:$P,Durum_Mo!$B:$B,"STOCKS",Durum_Mo!$C:$C,RIGHT(J$2,5)) -> 5.0022209e-12 | K22: =K19-SUMIFS(Durum_Mo!$P:$P,Durum_Mo!$B:$B,"STOCKS",Durum_Mo!$C:$C,RIGHT(K$2,5)) -> 4.0927262e-12 | ... Z22: =Z19-SUMIFS(Durum_Mo!$P:$P,Durum_Mo!$B:$B,"STOCKS",Durum_Mo!$C:$C,RIGHT(Z$2,5)) -> -5.570655e-12
A25: =A22 -> Durum | B25: FS/Prod | D25: {=SUM(D13:D14/D$10)} -> 0.071268281 | E25: {=SUM(E13:E14/E$10)} -> 0.059716022 | F25: {=SUM(F13:F14/F$10)} -> 0.052942892 | G25: {=SUM(G13:G14/G$10)} -> 0.041947046 | H25: {=SUM(H13:H14/H$10)} -> 0.076654115 | I25: {=SUM(I13:I14/I$10)} -> 0.062068778 | J25: {=SUM(J13:J14/J$10)} -> 0.0428134 | K25: {=SUM(K13:K14/K$10)} -> 0.048299874 | ... Z25: {=SUM(Z13:Z14/Z$10)} -> 0.030233688
A26: =A25 -> Durum | B26: FSR/Prod | D26: =D15/D$10 -> 0.14378292 | E26: =E15/E$10 -> 0.084233071 | F26: =F15/F$10 -> 0.13502853 | G26: =G15/G$10 -> 0.12379231 | H26: =H15/H$10 -> 0.19412826 | I26: =I15/I$10 -> 0.19371924 | J26: =J15/J$10 -> 0.074073524 | K26: =K15/K$10 -> 0.29019853 | ... Z26: =Z15/Z$10 -> 0.086199865
A27: =A26 -> Durum | B27: Exp/Prod | D27: =D16/D$10 -> 0.76994867 | E27: =E16/E$10 -> 0.8170738 | F27: =F16/F$10 -> 0.66374432 | G27: =G16/G$10 -> 0.70189802 | H27: =H16/H$10 -> 1.3321308 | I27: =I16/I$10 -> 0.86672679 | J27: =J16/J$10 -> 0.66714004 | K27: =K16/K$10 -> 0.53401845 | ... Z27: =Z16/Z$10 -> 0.90896886
D29: =(D13-C13)/C13 -> #VALUE! | E29: =(E13-D13)/D13 -> -0.08975751 | F29: =(F13-E13)/E13 -> 0.010735586 | G29: =(G13-F13)/F13 -> -0.023996853 | H29: =(H13-G13)/G13 -> 0.033857316 | I29: =(I13-H13)/H13 -> -0.10916179 | J29: =(J13-I13)/I13 -> 0.034135667 | K29: =(K13-J13)/J13 -> 0.10368176 | ... Z29: =(Z13-Y13)/Y13 -> 0.0094191523
D30: =(D14-C14)/C14 -> #VALUE! | E30: =(E14-D14)/D14 -> #DIV/0! | F30: =(F14-E14)/E14 -> #DIV/0! | G30: =(G14-F14)/F14 -> #DIV/0! | H30: =(H14-G14)/G14 -> #DIV/0! | I30: =(I14-H14)/H14 -> #DIV/0! | J30: =(J14-I14)/I14 -> #DIV/0! | K30: =(K14-J14)/J14 -> #DIV/0! | ... Z30: =(Z14-Y14)/Y14 -> #DIV/0!
D31: =(D15-C15)/C15 -> #VALUE! | E31: =(E15-D15)/D15 -> -0.36358874 | F31: =(F15-E15)/E15 -> 0.82752653 | G31: =(G15-F15)/F15 -> 0.12934234 | H31: =(H15-G15)/G15 -> -0.11279982 | I31: =(I15-H15)/H15 -> 0.097855269 | J31: =(J15-I15)/I15 -> -0.42672732 | K31: =(K15-J15)/J15 -> 2.8327439 | ... Z31: =(Z15-Y15)/Y15 -> 0.25246174
D32: =(D16-C16)/C16 -> #VALUE! | E32: =(E16-D16)/D16 -> 0.15282139 | F32: =(F16-E16)/E16 -> -0.073894829 | G32: =(G16-F16)/F16 -> 0.30265882 | H32: =(H16-G16)/G16 -> 0.073740571 | I32: =(I16-H16)/H16 -> -0.28419213 | J32: =(J16-I16)/I16 -> 0.15399991 | K32: =(K16-J16)/J16 -> -0.21690069 | ... Z32: =(Z16-Y16)/Y16 -> 0.64540056

Sheet Canola_Mo
A1: Commodity | B1: Metric | C1: Crop Year | D1: AUG | E1: SEP | F1: OCT | G1: NOV | H1: DEC | I1: JAN | J1: FEB | K1: MAR | L1: APR | M1: MAY | N1: JUN | O1: JUL | P1: AUG/JUL
A2: Canola | B2: Planted Area | C2: 02-03 | D2: 9.5798 | P2: =D2 -> 9.5798
A3: Canola | B3: Planted Area | C3: 03-04 | D3: 11.7022 | P3: =D3 -> 11.7022
A4: Canola | B4: Planted Area | C4: 04-05 | D4: 12.8946 | P4: =D4 -> 12.8946
A5: Canola | B5: Planted Area | C5: 05-06 | D5: 13.2696 | P5: =D5 -> 13.2696
A6: Canola | B6: Planted Area | C6: 06-07 | D6: 13.055339 | P6: =D6 -> 13.055339
A7: Canola | B7: Planted Area | C7: 07-08 | D7: 15.771 | P7: =D7 -> 15.771
A8: Canola | B8: Planted Area | C8: 08-09 | D8: 16.1632 | P8: =D8 -> 16.1632
A9: Canola | B9: Planted Area | C9: 09-10 | D9: 16.5297 | P9: =D9 -> 16.5297
A10: Canola | B10: Planted Area | C10: 10-11 | D10: 17.5859 | P10: =D10 -> 17.5859
A11: Canola | B11: Planted Area | C11: 11-12 | D11: 18.98968 | P11: =D11 -> 18.98968
A12: Canola | B12: Planted Area | C12: 12-13 | D12: 22.176 | P12: =D12 -> 22.176
A13: Canola | B13: Planted Area | C13: 13-14 | D13: 20.4458 | P13: =D13 -> 20.4458
... A93: Canola | B93: Production | C93: 24-25 | D93: 19239.5 | P93: =D93 -> 19239.5
A94: Canola | B94: Exports | C94: 02-03 | D94: 110.128 | E94: 76.545 | F94: 302.921 | G94: 271.653 | H94: 250.428 | I94: 121.786 | J94: 172.517 | K94: 246.011 | L94: 178.539 | M94: 223.581 | N94: 242.753 | O94: 224.641 | P94: =SUM(D94:O94) -> 2421.503
A95: Canola | B95: Exports | C95: 03-04 | D95: 211.528 | E95: 298.391 | F95: 515.689 | G95: 492.864 | H95: 315.167 | I95: 237.938 | J95: 244.574 | K95: 341.281 | L95: 238.947 | M95: 279.388 | N95: 295.363 | O95: 291.413 | P95: =SUM(D95:O95) -> 3762.543
A96: Canola | B96: Exports | C96: 04-05 | D96: 184.774 | E96: 101.71 | F96: 595.667 | G96: 460.283 | H96: 316.037 | I96: 215.275 | J96: 224.963 | K96: 313.013 | L96: 287.774 | M96: 201.374 | N96: 379.36 | O96: 212.518 | P96: =SUM(D96:O96) -> 3492.748
A97: Canola | B97: Exports | C97: 05-06 | D97: 312.173 | E97: 242.812 | F97: 587.031 | G97: 451.328 | H97: 573.591 | I97: 354.796 | J97: 441.028 | K97: 610.963 | L97: 453.897 | M97: 552.746 | N97: 306.77 | O97: 523.472 | P97: =SUM(D97:O97) -> 5410.607
A98: Canola | B98: Exports | C98: 06-07 | D98: 424.326 | E98: 565.646 | F98: 534.336 | G98: 435.171 | H98: 348.661 | I98: 528.273 | J98: 362.078 | K98: 498.142 | L98: 378.435 | M98: 522.484 | N98: 394.492 | O98: 468.086 | P98: =SUM(D98:O98) -> 5460.13
A99: Canola | B99: Exports | C99: 07-08 | D99: 454.134 | E99: 501.447 | F99: 446.035 | G99: 413.339 | H99: 434.68 | I99: 565.795 | J99: 582.547 | K99: 657.934 | L99: 461.698 | M99: 452.537 | N99: 474.133 | O99: 363.886 | P99: =SUM(D99:O99) -> 5808.165
A100: Canola | B100: Exports | C100: 08-09 | D100: 470.345 | E100: 593.405 | F100: 716.45 | G100: 722.78 | H100: 606.513 | I100: 505.087 | J100: 628.35 | K100: 682.419 | L100: 886.93 | M100: 667.515 | N100: 857.088 | O100: 561.024 | P100: =SUM(D100:O100) -> 7897.906
A101: Canola | B101: Exports | C101: 09-10 | D101: 442.487 | E101: 422.537 | F101: 813.726 | G101: 770.447 | H101: 441.517 | I101: 500.829 | J101: 567.936 | K101: 848.435 | L101: 549.167 | M101: 639.695 | N101: 586.525 | O101: 588.489 | P101: =SUM(D101:O101) -> 7171.79
A102: Canola | B102: Exports | C102: 10-11 | D102: 508.364 | E102: 499.587 | F102: 783.054 | G102: 787.267 | H102: 611.296 | I102: 611.358 | J102: 687.326 | K102: 484.746 | L102: 496.229 | M102: 626.791 | N102: 425.438 | O102: 685.077 | P102: =SUM(D102:O102) -> 7206.533
A103: Canola | B103: Exports | C103: 11-12 | D103: 349.61 | E103: 746.499 | F103: 1024.729 | G103: 893.605 | H103: 857.237 | I103: 1038.209 | J103: 800.539 | K103: 777.248 | L103: 596.185 | M103: 668.659 | N103: 495.469 | O103: 447.196 | P103: =SUM(D103:O103) -> 8695.185
A104: Canola | B104: Exports | C104: 12-13 | D104: 368.876 | E104: 712.644 | F104: 1014.113 | G104: 646.14 | H104: 774.078 | I104: 598.109 | J104: 571.295 | K104: 694.252 | L104: 526.695 | M104: 590.042 | N104: 248.343 | O104: 365.233 | P104: =SUM(D104:O104) -> 7109.82
A105: Canola | B105: Exports | C105: 13-14 | D105: 264.638 | E105: 504.343 | F105: 1090.745 | G105: 834.041 | H105: 680.255 | I105: 651.871 | J105: 564.09 | K105: 925.143 | L105: 975.471 | M105: 960.725 | N105: 1004.882 | O105: 718.343 | P105: =SUM(D105:O105) -> 9174.547
... A208: Canola | B208: Seed | C208: 24-25 | D208: 0 | E208: 0 | F208: 0 | G208: 0 | H208: 0 | I208: 0 | J208: 0 | K208: 0 | L208: 0 | M208: 0 | N208: 0 | O208: 0 | P208: =SUM(D208:O208) -> 0
A209: Canola | B209: Food & Processing | C209: 02-03 | D209: =D140+D163 -> 185.40833 | E209: =E140+E163 -> 185.40833 | F209: =F140+F163 -> 185.40833 | G209: =G140+G163 -> 185.40833 | H209: =H140+H163 -> 185.40833 | I209: =I140+I163 -> 185.40833 | J209: =J140+J163 -> 185.40833 | K209: =K140+K163 -> 185.40833 | ... O209: =O140+O163 -> 185.40833 | P209: =SUM(D209:O209) -> 2224.9
A210: Canola | B210: Food & Processing | C210: 03-04 | D210: =D141+D164 -> 282.46667 | E210: =E141+E164 -> 282.46667 | F210: =F141+F164 -> 282.46667 | G210: =G141+G164 -> 282.46667 | H210: =H141+H164 -> 282.46667 | I210: =I141+I164 -> 282.46667 | J210: =J141+J164 -> 282.46667 | K210: =K141+K164 -> 282.46667 | ... O210: =O141+O164 -> 282.46667 | P210: =SUM(D210:O210) -> 3389.6
A211: Canola | B211: Food & Processing | C211: 04-05 | D211: =D142+D165 -> 252.575 | E211: =E142+E165 -> 252.575 | F211: =F142+F165 -> 252.575 | G211: =G142+G165 -> 252.575 | H211: =H142+H165 -> 252.575 | I211: =I142+I165 -> 252.575 | J211: =J142+J165 -> 252.575 | K211: =K142+K165 -> 252.575 | ... O211: =O142+O165 -> 252.575 | P211: =SUM(D211:O211) -> 3030.9
A212: Canola | B212: Food & Processing | C212: 05-06 | D212: =D143+D166 -> 285.21667 | E212: =E143+E166 -> 285.21667 | F212: =F143+F166 -> 285.21667 | G212: =G143+G166 -> 285.21667 | H212: =H143+H166 -> 285.21667 | I212: =I143+I166 -> 285.21667 | J212: =J143+J166 -> 285.21667 | K212: =K143+K166 -> 285.21667 | ... O212: =O143+O166 -> 285.21667 | P212: =SUM(D212:O212) -> 3422.6
A213: Canola | B213: Food & Processing | C213: 06-07 | D213: =D144+D167 -> 298.21667 | E213: =E144+E167 -> 298.21667 | F213: =F144+F167 -> 298.21667 | G213: =G144+G167 -> 298.21667 | H213: =H144+H167 -> 298.21667 | I213: =I144+I167 -> 298.21667 | J213: =J144+J167 -> 298.21667 | K213: =K144+K167 -> 298.21667 | ... O213: =O144+O167 -> 298.21667 | P213: =SUM(D213:O213) -> 3578.6
A214: Canola | B214: Food & Processing | C214: 07-08 | D214: =D145+D168 -> 345.36667 | E214: =E145+E168 -> 345.36667 | F214: =F145+F168 -> 345.36667 | G214: =G145+G168 -> 345.36667 | H214: =H145+H168 -> 345.36667 | I214: =I145+I168 -> 345.36667 | J214: =J145+J168 -> 345.36667 | K214: =K145+K168 -> 345.36667 | ... O214: =O145+O168 -> 345.36667 | P214: =SUM(D214:O214) -> 4144.4
A215: Canola | B215: Food & Processing | C215: 08-09 | D215: =D146+D169 -> 356.65833 | E215: =E146+E169 -> 356.65833 | F215: =F146+F169 -> 356.65833 | G215: =G146+G169 -> 356.65833 | H215: =H146+H169 -> 356.65833 | I215: =I146+I169 -> 356.65833 | J215: =J146+J169 -> 356.65833 | K215: =K146+K169 -> 356.65833 | ... O215: =O146+O169 -> 356.65833 | P215: =SUM(D215:O215) -> 4279.9
A216: Canola | B216: Food & Processing | C216: 09-10 | D216: =D147+D170 -> 398.98333 | E216: =E147+E170 -> 398.98333 | F216: =F147+F170 -> 398.98333 | G216: =G147+G170 -> 398.98333 | H216: =H147+H170 -> 398.98333 | I216: =I147+I170 -> 398.98333 | J216: =J147+J170 -> 398.98333 | K216: =K147+K170 -> 398.98333 | ... O216: =O147+O170 -> 398.98333 | P216: =SUM(D216:O216) -> 4787.8
A217: Canola | B217: Food & Processing | C217: 10-11 | D217: =D148+D171 -> 525.86667 | E217: =E148+E171 -> 525.86667 | F217: =F148+F171 -> 525.86667 | G217: =G148+G171 -> 525.86667 | H217: =H148+H171 -> 525.86667 | I217: =I148+I171 -> 525.86667 | J217: =J148+J171 -> 525.86667 | K217: =K148+K171 -> 525.86667 | ... O217: =O148+O171 -> 525.86667 | P217: =SUM(D217:O217) -> 6310.4
A218: Canola | B218: Food & Processing | C218: 11-12 | D218: =D149+D172 -> 583.275 | E218: =E149+E172 -> 583.275 | F218: =F149+F172 -> 583.275 | G218: =G149+G172 -> 583.275 | H218: =H149+H172 -> 583.275 | I218: =I149+I172 -> 583.275 | J218: =J149+J172 -> 583.275 | K218: =K149+K172 -> 583.275 | ... O218: =O149+O172 -> 583.275 | P218: =SUM(D218:O218) -> 6999.3
A219: Canola | B219: Food & Processing | C219: 12-13 | D219: =D150+D173 -> 559.73333 | E219: =E150+E173 -> 559.73333 | F219: =F150+F173 -> 559.73333 | G219: =G150+G173 -> 559.73333 | H219: =H150+H173 -> 559.73333 | I219: =I150+I173 -> 559.73333 | J219: =J150+J173 -> 559.73333 | K219: =K150+K173 -> 559.73333 | ... O219: =O150+O173 -> 559.73333 | P219: =SUM(D219:O219) -> 6716.8
A220: Canola | B220: Food & Processing | C220: 13-14 | D220: =D151+D174 -> 581.61667 | E220: =E151+E174 -> 581.61667 | F220: =F151+F174 -> 581.61667 | G220: =G151+G174 -> 581.61667 | H220: =H151+H174 -> 581.61667 | I220: =I151+I174 -> 581.61667 | J220: =J151+J174 -> 581.61667 | K220: =K151+K174 -> 581.61667 | ... O220: =O151+O174 -> 581.61667 | P220: =SUM(D220:O220) -> 6979.4
... A231: Canola | B231: Food & Processing | C231: 24-25 | D231: =D162+D185 -> 951 | E231: =E162+E185 -> 951 | F231: =F162+F185 -> 951 | G231: =G162+G185 -> 951 | H231: =H162+H185 -> 951 | I231: =I162+I185 -> 951 | J231: =J162+J185 -> 951 | K231: =K162+K185 -> 951 | ... O231: =O162+O185 -> 951 | P231: =SUM(D231:O231) -> 11412
...

Sheet Canola_Yr
A1: Canola
