Workbook

Sheet Wheat_Mo
A1: Commodity | B1: Metric | C1: Crop Year | D1: AUG | E1: SEP | F1: OCT | G1: NOV | H1: DEC | I1: JAN | J1: FEB | K1: MAR | L1: APR | M1: MAY | N1: JUN | O1: JUL | P1: AUG/JUL
A2: Wheat, excluding durum | B2: Planted Area | C2: 02-03 | D2: 19.5012 | P2: =D2
A3: Wheat, excluding durum | B3: Planted Area | C3: 03-04 | D3: 19.7719 | P3: =D3
A4: Wheat, excluding durum | B4: Planted Area | C4: 04-05 | D4: 19.1433 | P4: =D4
A5: Wheat, excluding durum | B5: Planted Area | C5: 05-06 | D5: 18.1559 | P5: =D5
A6: Wheat, excluding durum | B6: Planted Area | C6: 06-07 | D6: 20.549875 | P6: =D6
A7: Wheat, excluding durum | B7: Planted Area | C7: 07-08 | D7: 16.9631 | P7: =D7
A8: Wheat, excluding durum | B8: Planted Area | C8: 08-09 | D8: 19.111 | P8: =D8
A9: Wheat, excluding durum | B9: Planted Area | C9: 09-10 | D9: 19.2571 | P9: =D9
A10: Wheat, excluding durum | B10: Planted Area | C10: 10-11 | D10: 17.9841 | P10: =D10
A11: Wheat, excluding durum | B11: Planted Area | C11: 11-12 | D11: 17.551812 | P11: =D11
A12: Wheat, excluding durum | B12: Planted Area | C12: 12-13 | D12: 19.0678 | P12: =D12
A13: Wheat, excluding durum | B13: Planted Area | C13: 13-14 | D13: 21.2865 | P13: =D13
... A93: Wheat, excluding durum | B93: Production | C93: 24-25 | D93: 29558.525 | P93: =D93
A94: Wheat, excluding durum | B94: Exports | C94: 02-03 | D94: 557.6 | E94: 557.6 | F94: 557.6 | G94: 557.6 | H94: 557.6 | I94: 349.26667 | J94: 349.26667 | K94: 349.26667 | L94: 596.85 | M94: 596.85 | N94: 596.85 | O94: 596.85 | P94: =SUM(D94:O94)
A95: Wheat, excluding durum | B95: Exports | C95: 03-04 | D95: 1012.5 | E95: 1012.5 | F95: 1012.5 | G95: 1012.5 | H95: 1012.5 | I95: 837.56667 | J95: 837.56667 | K95: 837.56667 | L95: 1181.025 | M95: 1181.025 | N95: 1181.025 | O95: 1181.025 | P95: =SUM(D95:O95)
A96: Wheat, excluding durum | B96: Exports | C96: 04-05 | D96: 995.62 | E96: 995.62 | F96: 995.62 | G96: 995.62 | H96: 995.62 | I96: 993.8 | J96: 993.8 | K96: 993.8 | L96: 908.9 | M96: 908.9 | N96: 908.9 | O96: 908.9 | P96: =SUM(D96:O96)
A97: Wheat, excluding durum | B97: Exports | C97: 05-06 | D97: 813.6 | E97: 813.6 | F97: 813.6 | G97: 813.6 | H97: 813.6 | I97: 846.33333 | J97: 846.33333 | K97: 846.33333 | L97: 1204.725 | M97: 1204.725 | N97: 1204.725 | O97: 1204.725 | P97: =SUM(D97:O97)
A98: Wheat, excluding durum | B98: Exports | C98: 06-07 | D98: 1328.44 | E98: 1328.44 | F98: 1328.44 | G98: 1328.44 | H98: 1328.44 | I98: 1001.2333 | J98: 1001.2333 | K98: 1001.2333 | L98: 1325.675 | M98: 1325.675 | N98: 1325.675 | O98: 1325.675 | P98: =SUM(D98:O98)
A99: Wheat, excluding durum | B99: Exports | C99: 07-08 | D99: 1142.24 | E99: 1142.24 | F99: 1142.24 | G99: 1142.24 | H99: 1142.24 | I99: 872.6 | J99: 872.6 | K99: 872.6 | L99: 1088.275 | M99: 1088.275 | N99: 1088.275 | O99: 1088.275 | P99: =SUM(D99:O99)
A100: Wheat, excluding durum | B100: Exports | C100: 08-09 | D100: 1139.56 | E100: 1139.56 | F100: 1139.56 | G100: 1139.56 | H100: 1139.56 | I100: 1202.9667 | J100: 1202.9667 | K100: 1202.9667 | L100: 1414.925 | M100: 1414.925 | N100: 1414.925 | O100: 1414.925 | P100: =SUM(D100:O100)
A101: Wheat, excluding durum | B101: Exports | C101: 09-10 | D101: 1180.3 | E101: 1180.3 | F101: 1180.3 | G101: 1180.3 | H101: 1180.3 | I101: 1150.1667 | J101: 1150.1667 | K101: 1150.1667 | L101: 1327.35 | M101: 1327.35 | N101: 1327.35 | O101: 1327.35 | P101: =SUM(D101:O101)
A102: Wheat, excluding durum | B102: Exports | C102: 10-11 | D102: 1061.1 | E102: 1061.1 | F102: 1061.1 | G102: 1061.1 | H102: 1061.1 | I102: 854.43333 | J102: 854.43333 | K102: 854.43333 | L102: 1253.025 | M102: 1253.025 | N102: 1253.025 | O102: 1253.025 | P102: =SUM(D102:O102)
A103: Wheat, excluding durum | B103: Exports | C103: 11-12 | D103: 1185.26 | E103: 1185.26 | F103: 1185.26 | G103: 1185.26 | H103: 1185.26 | I103: 1166.2 | J103: 1166.2 | K103: 1166.2 | L103: 1122.825 | M103: 1122.825 | N103: 1122.825 | O103: 1122.825 | P103: =SUM(D103:O103)
A104: Wheat, excluding durum | B104: Exports | C104: 12-13 | D104: 1221.06 | E104: 1221.06 | F104: 1221.06 | G104: 1221.06 | H104: 1221.06 | I104: 1235.3 | J104: 1235.3 | K104: 1235.3 | L104: 1380.375 | M104: 1380.375 | N104: 1380.375 | O104: 1380.375 | P104: =SUM(D104:O104)
A105: Wheat, excluding durum | B105: Exports | C105: 13-14 | D105: 1389.6 | E105: 1389.6 | F105: 1389.6 | G105: 1389.6 | H105: 1389.6 | I105: 1356.7 | J105: 1356.7 | K105: 1356.7 | L105: 1852.075 | M105: 1852.075 | N105: 1852.075 | O105: 1852.075 | P105: =SUM(D105:O105)
... A254: Wheat, excluding durum | B254: FSR | C254: 24-25 | D254: 267.48667 | E254: 267.48667 | F254: 267.48667 | G254: 267.48667 | H254: 267.48667 | I254: 247.66667 | J254: 247.66667 | K254: 247.66667 | L254: 429.54167 | M254: 429.54167 | N254: 429.54167 | O254: 429.54167 | P254: =SUM(D254:O254)
A255: Wheat, excluding durum | B255: STOCKS | C255: 02-03 | D255: 16151.675 | E255: 15063.948 | F255: 13947.305 | G255: 12866.386 | H255: 11815.781 | I255: 10976.048 | J255: 10111.689 | K255: 9248.088 | L255: 7962.742 | M255: 6678.452 | N255: 5392.77 | O255: 4106.552 | P255: =O255
A256: Wheat, excluding durum | B256: STOCKS | C256: 03-04 | D256: 21432.351 | E256: 19924.308 | F256: 18414.015 | G256: 16902.702 | H256: 15391.129 | I256: 14092.037 | J256: 12793.206 | K256: 11494.202 | L256: 9673.569 | M256: 7852.816 | N256: 6031.973 | O256: 4211.064 | P256: =O256
A257: Wheat, excluding durum | B257: STOCKS | C257: 04-05 | D257: 22654.862 | E257: 21105.19 | F257: 19555.164 | G257: 18003.912 | H257: 16452.342 | I257: 14928.591 | J257: 13404.675 | K257: 11881.082 | L257: 10269.305 | M257: 8657.568 | N257: 7046.531 | O257: 5435.038 | P257: =O257
A258: Wheat, excluding durum | B258: STOCKS | C258: 05-06 | D258: 23873.432 | E258: 22477.65 | F258: 21081.27 | G258: 19683.67 | H258: 18285.95 | I258: 16906.088 | J258: 15525.896 | K258: 14145.858 | L258: 12214.775 | M258: 10283.896 | N258: 8353.827 | O258: 6423.97 | P258: =O258
A259: Wheat, excluding durum | B259: STOCKS | C259: 06-07 | D259: 26399.879 | E259: 24456.54 | F259: 22510.723 | G259: 20563.93 | H259: 18617.181 | I259: 17015.655 | J259: 15413.72 | K259: 13811.518 | L259: 11760.424 | M259: 9709.822 | N259: 7659.254 | O259: 5608.144 | P259: =O259
A260: Wheat, excluding durum | B260: STOCKS | C260: 07-08 | D260: 20414.747 | E260: 18815.195 | F260: 17213.422 | G260: 15611.581 | H260: 14009.001 | I260: 12728.011 | J260: 11446.675 | K260: 10166.273 | L260: 8514.328 | M260: 6862.3013 | N260: 5209.5547 | O260: 3557.422 | P260: =O260
A261: Wheat, excluding durum | B261: STOCKS | C261: 08-09 | D261: 24974.793 | E261: 23292.671 | F261: 21608.764 | G261: 19924.279 | H261: 18239.437 | I261: 16523.579 | J261: 14808.1 | K261: 13092.833 | L261: 10980.958 | M261: 8869.7567 | N261: 6755.5693 | O261: 4641.696 | P261: =O261
A262: Wheat, excluding durum | B262: STOCKS | C262: 09-10 | D262: 24505.106 | E262: 22809.274 | F262: 21107.072 | G262: 19405.63 | H262: 17692.05 | I262: 16125.203 | J262: 14558.045 | K262: 12991.158 | L262: 11005.026 | M262: 9018.242 | N262: 7032.256 | O262: 5048.966 | P262: =O262
A263: Wheat, excluding durum | B263: STOCKS | C263: 10-11 | D263: 23712.117 | E263: 22102.003 | F263: 20489.174 | G263: 18876.605 | H263: 17264.467 | I263: 15933.209 | J263: 14601.487 | K263: 13270.055 | L263: 11399.071 | M263: 9527.8907 | N263: 7656.4363 | O263: 5793.688 | P263: =O263
A264: Wheat, excluding durum | B264: STOCKS | C264: 11-12 | D264: 25048.217 | E264: 23187.563 | F264: 21324.92 | G264: 19466.707 | H264: 17604.119 | I264: 15799.712 | J264: 14006.974 | K264: 12212.829 | L264: 10269.672 | M264: 8325.0923 | N264: 6389.4037 | O264: 4445.797 | P264: =O264
A265: Wheat, excluding durum | B265: STOCKS | C265: 12-13 | D265: 25224.128 | E265: 23383.559 | F265: 21542.851 | G265: 19701.293 | H265: 17859.205 | I265: 16088.534 | J265: 14317.626 | K265: 12546.849 | L265: 10403.09 | M265: 8259.5283 | N265: 6128.4277 | O265: 3985.236 | P265: =O265
A266: Wheat, excluding durum | B266: STOCKS | C266: 13-14 | D266: 33052.108 | E266: 31035.351 | F266: 29016.786 | G266: 26997.994 | H266: 24984.69 | I266: 23033.509 | J266: 21082.601 | K266: 19135.13 | L266: 16520.188 | M266: 13898.952 | N266: 11279.242 | O266: 8658.62 | P266: =O266
... A277: Wheat, excluding durum | B277: STOCKS | C277: 24-25 | D277: 31948.314 | E277: 29613.339 | F277: 27292.678 | G277: 24961.843 | H277: 22631.29 | I277: 20247.347 | J277: 17861.149 | K277: 15476.003 | L277: 12553.911 | M277: 9631.9843 | N277: 6711.4837 | O277: 3808.442 | P277: =O277

Sheet Wheat_Yr
A1: Wheat
A2: Commodity | B2: Metric | C2: Unit | D2: 2002-03 | E2: 2003-04 | F2: 2004-05 | G2: 2005-06 | H2: 2006-07 | I2: 2007-08 | J2: 2008-09 | K2: 2009-10 | L2: 2010-11 | M2: 2011-12 | N2: 2012-13 | O2: 2013-14 | P2: 2014-15 | Q2: 2015-16 | R2: 2016-17 | S2: 2017-18 | T2: 2018-19 | U2: 2019-20 | V2: 2020-21 | W2: 2021-22 | X2: 2022-23 | Y2: 2023-24 | Z2: 2024-25 | AA2: 2025-26
A3: Wheat | B3: Planted Area | C3: MLN AC | D3: =Wheat_Mo!P3 | E3: =Wheat_Mo!P18 | F3: =Wheat_Mo!P33 | G3: =Wheat_Mo!P48 | H3: =Wheat_Mo!P63 | I3: =Wheat_Mo!P78 | J3: =Wheat_Mo!P93 | K3: =Wheat_Mo!P108 | L3: =Wheat_Mo!P123 | M3: =Wheat_Mo!P138 | N3: =Wheat_Mo!P153 | O3: =Wheat_Mo!P168 | P3: =Wheat_Mo!P183 | Q3: =Wheat_Mo!P198 | R3: =Wheat_Mo!P213 | S3: =Wheat_Mo!P228 | T3: =Wheat_Mo!P243 | U3: =Wheat_Mo!P258 | V3: =Wheat_Mo!P273 | W3: =Wheat_Mo!P288 | X3: =Wheat_Mo!P303 | Y3: =Wheat_Mo!P318 | Z3: =Wheat_Mo!P333 | AA3: =Wheat_Mo!P348
A4: Wheat | B4: Harvested Area | C4: MLN AC | D4: =Wheat_Mo!P4 | E4: =Wheat_Mo!P19 | F4: =Wheat_Mo!P34 | G4: =Wheat_Mo!P49 | H4: =Wheat_Mo!P64 | I4: =Wheat_Mo!P79 | J4: =Wheat_Mo!P94 | K4: =Wheat_Mo!P109 | L4: =Wheat_Mo!P124 | M4: =Wheat_Mo!P139 | N4: =Wheat_Mo!P154 | O4: =Wheat_Mo!P169 | P4: =Wheat_Mo!P184 | Q4: =Wheat_Mo!P199 | R4: =Wheat_Mo!P214 | S4: =Wheat_Mo!P229 | T4: =Wheat_Mo!P244 | U4: =Wheat_Mo!P259 | V4: =Wheat_Mo!P274 | W4: =Wheat_Mo!P289 | X4: =Wheat_Mo!P304 | Y4: =Wheat_Mo!P319 | Z4: =Wheat_Mo!P334 | AA4: =Wheat_Mo!P349
A5: Wheat | B5: Proportion Harvested | C5: % | D5: =IF(D3<>0,D4/D3,"") | E5: =IF(E3<>0,E4/E3,"") | F5: =IF(F3<>0,F4/F3,"") | G5: =IF(G3<>0,G4/G3,"") | H5: =IF(H3<>0,H4/H3,"") | I5: =IF(I3<>0,I4/I3,"") | J5: =IF(J3<>0,J4/J3,"") | K5: =IF(K3<>0,K4/K3,"") | ... AA5: =IF(AA3<>0,AA4/AA3,"")
A6: Wheat | B6: Yield | C6: BU/AC | D6: =Wheat_Mo!O6 | E6: =Wheat_Mo!O21 | F6: =Wheat_Mo!O36 | G6: =Wheat_Mo!O51 | H6: =Wheat_Mo!O66 | I6: =Wheat_Mo!O81 | J6: =Wheat_Mo!O96 | K6: =Wheat_Mo!O111 | L6: =Wheat_Mo!O126 | M6: =Wheat_Mo!O141 | N6: =Wheat_Mo!O156 | O6: =Wheat_Mo!O171 | P6: =Wheat_Mo!O186 | Q6: =Wheat_Mo!O201 | R6: =Wheat_Mo!O216 | S6: =Wheat_Mo!O231 | T6: =Wheat_Mo!O246 | U6: =Wheat_Mo!O261 | V6: =Wheat_Mo!O276 | W6: =Wheat_Mo!O291 | X6: =Wheat_Mo!O306 | Y6: =Wheat_Mo!O321 | Z6: =Wheat_Mo!O336 | AA6: =Wheat_Mo!O351
A7: Wheat
A8: Wheat | B8: Beginning Stocks | C8: KMT | D8: =Wheat_Mo!P8 | E8: =Wheat_Mo!P23 | F8: =Wheat_Mo!P38 | G8: =Wheat_Mo!P53 | H8: =Wheat_Mo!P68 | I8: =Wheat_Mo!P83 | J8: =Wheat_Mo!P98 | K8: =Wheat_Mo!P113 | L8: =Wheat_Mo!P128 | M8: =Wheat_Mo!P143 | N8: =Wheat_Mo!P158 | O8: =Wheat_Mo!P173 | P8: =Wheat_Mo!P188 | Q8: =Wheat_Mo!P203 | R8: =Wheat_Mo!P218 | S8: =Wheat_Mo!P233 | T8: =Wheat_Mo!P248 | U8: =Wheat_Mo!P263 | V8: =Wheat_Mo!P278 | X8: =Wheat_Mo!P308 | Y8: =Wheat_Mo!P323 | Z8: =Wheat_Mo!P338 | AA8: =Wheat_Mo!P353
A9: Wheat | B9: Imports | C9: KMT | D9: =Wheat_Mo!P9 | E9: =Wheat_Mo!P24 | F9: =Wheat_Mo!P39 | G9: =Wheat_Mo!P54 | H9: =Wheat_Mo!P69 | I9: =Wheat_Mo!P84 | J9: =Wheat_Mo!P99 | K9: =Wheat_Mo!P114 | L9: =Wheat_Mo!P129 | M9: =Wheat_Mo!P144 | N9: =Wheat_Mo!P159 | O9: =Wheat_Mo!P174 | P9: =Wheat_Mo!P189 | Q9: =Wheat_Mo!P204 | R9: =Wheat_Mo!P219 | S9: =Wheat_Mo!P234 | T9: =Wheat_Mo!P249 | U9: =Wheat_Mo!P264 | V9: =Wheat_Mo!P279 | W9: =Wheat_Mo!P294 | X9: =Wheat_Mo!P309 | Y9: =Wheat_Mo!P324 | Z9: =Wheat_Mo!P339 | AA9: =Wheat_Mo!P354
A10: Wheat | B10: Production | C10: KMT | D10: =Wheat_Mo!P10 | E10: =Wheat_Mo!P25 | F10: =Wheat_Mo!P40 | G10: =Wheat_Mo!P55 | H10: =Wheat_Mo!P70 | I10: =Wheat_Mo!P85 | J10: =Wheat_Mo!P100 | K10: =Wheat_Mo!P115 | L10: =Wheat_Mo!P130 | M10: =Wheat_Mo!P145 | N10: =Wheat_Mo!P160 | O10: =Wheat_Mo!P175 | P10: =Wheat_Mo!P190 | Q10: =Wheat_Mo!P205 | R10: =Wheat_Mo!P220 | S10: =Wheat_Mo!P235 | T10: =Wheat_Mo!P250 | U10: =Wheat_Mo!P265 | V10: =Wheat_Mo!P280 | W10: =Wheat_Mo!P295 | X10: =Wheat_Mo!P310 | Y10: =Wheat_Mo!P325 | Z10: =Wheat_Mo!P340 | AA10: =Wheat_Mo!P355
A11: Wheat
A12: Wheat | B12: Food | C12: KMT | D12: =Wheat_Mo!P12 | E12: =Wheat_Mo!P27 | F12: =Wheat_Mo!P42 | G12: =Wheat_Mo!P57 | H12: =Wheat_Mo!P72 | I12: =Wheat_Mo!P87 | J12: =Wheat_Mo!P102 | K12: =Wheat_Mo!P117 | L12: =Wheat_Mo!P132 | M12: =Wheat_Mo!P147 | N12: =Wheat_Mo!P162 | O12: =Wheat_Mo!P177 | P12: =Wheat_Mo!P192 | Q12: =Wheat_Mo!P207 | R12: =Wheat_Mo!P222 | S12: =Wheat_Mo!P237 | T12: =Wheat_Mo!P252 | U12: =Wheat_Mo!P267 | V12: =Wheat_Mo!P282 | W12: =Wheat_Mo!P297 | X12: =Wheat_Mo!P312 | Y12: =Wheat_Mo!P327 | Z12: =Wheat_Mo!P342 | AA12: =Wheat_Mo!P357
A13: Wheat | B13: Industrial | C13: KMT | D13: =Wheat_Mo!P13 | E13: =Wheat_Mo!P28 | F13: =Wheat_Mo!P43 | G13: =Wheat_Mo!P58 | H13: =Wheat_Mo!P73 | I13: =Wheat_Mo!P88 | J13: =Wheat_Mo!P103 | K13: =Wheat_Mo!P118 | L13: =Wheat_Mo!P133 | M13: =Wheat_Mo!P148 | N13: =Wheat_Mo!P163 | O13: =Wheat_Mo!P178 | P13: =Wheat_Mo!P193 | Q13: =Wheat_Mo!P208 | R13: =Wheat_Mo!P223 | S13: =Wheat_Mo!P238 | T13: =Wheat_Mo!P253 | U13: =Wheat_Mo!P268 | V13: =Wheat_Mo!P283 | W13: =Wheat_Mo!P298 | X13: =Wheat_Mo!P313 | Y13: =Wheat_Mo!P328 | Z13: =Wheat_Mo!P343 | AA13: =Wheat_Mo!P358
A14: Wheat | B14: FSR | C14: KMT | D14: =Wheat_Mo!P14 | E14: =Wheat_Mo!P29 | F14: =Wheat_Mo!P44 | G14: =Wheat_Mo!P59 | H14: =Wheat_Mo!P74 | I14: =Wheat_Mo!P89 | J14: =Wheat_Mo!P104 | K14: =Wheat_Mo!P119 | L14: =Wheat_Mo!P134 | M14: =Wheat_Mo!P149 | N14: =Wheat_Mo!P164 | O14: =Wheat_Mo!P179 | P14: =Wheat_Mo!P194 | Q14: =Wheat_Mo!P209 | R14: =Wheat_Mo!P224 | S14: =Wheat_Mo!P239 | T14: =Wheat_Mo!P254 | U14: =Wheat_Mo!P269 | V14: =Wheat_Mo!P284 | W14: =Wheat_Mo!P299 | X14: =Wheat_Mo!P314 | Y14: =Wheat_Mo!P329 | Z14: =Wheat_Mo!P344 | AA14: =Wheat_Mo!P359
A15: Wheat | B15: Exports | C15: KMT | D15: =Wheat_Mo!P15 | E15: =Wheat_Mo!P30 | F15: =Wheat_Mo!P45 | G15: =Wheat_Mo!P60 | H15: =Wheat_Mo!P75 | I15: =Wheat_Mo!P90 | J15: =Wheat_Mo!P105 | K15: =Wheat_Mo!P120 | L15: =Wheat_Mo!P135 | M15: =Wheat_Mo!P150 | N15: =Wheat_Mo!P165 | O15: =Wheat_Mo!P180 | P15: =Wheat_Mo!P195 | Q15: =Wheat_Mo!P210 | R15: =Wheat_Mo!P225 | S15: =Wheat_Mo!P240 | T15: =Wheat_Mo!P255 | U15: =Wheat_Mo!P270 | V15: =Wheat_Mo!P285 | W15: =Wheat_Mo!P300 | X15: =Wheat_Mo!P315 | Y15: =Wheat_Mo!P330 | Z15: =Wheat_Mo!P345 | AA15: =Wheat_Mo!P360
A16: Wheat
A17: Wheat | B17: Ending Stocks | C17: KMT | D17: =Wheat_Mo!P17 | E17: =Wheat_Mo!P32 | F17: =Wheat_Mo!P47 | G17: =Wheat_Mo!P62 | H17: =Wheat_Mo!P77 | I17: =Wheat_Mo!P92 | J17: =Wheat_Mo!P107 | K17: =Wheat_Mo!P122 | L17: =Wheat_Mo!P137 | M17: =Wheat_Mo!P152 | N17: =Wheat_Mo!P167 | O17: =Wheat_Mo!P182 | P17: =Wheat_Mo!P197 | Q17: =Wheat_Mo!P212 | R17: =Wheat_Mo!P227 | S17: =Wheat_Mo!P242 | T17: =Wheat_Mo!P257 | U17: =Wheat_Mo!P272 | V17: =Wheat_Mo!P287 | W17: =Wheat_Mo!P302 | X17: =Wheat_Mo!P317 | Y17: =Wheat_Mo!P332 | Z17: =Wheat_Mo!P347 | AA17: =Wheat_Mo!P362
A18: Wheat | B18: Stocks-to-Use | C18: %
A19: Wheat | B19: STU Days | C19: Days
A20: Wheat | B20: CHECK | C20: KMT | D20: =D8+D10+D9-D12-D13-D14-D15-D17 | E20: =E8+E10+E9-E12-E13-E14-E15-E17 | F20: =F8+F10+F9-F12-F13-F14-F15-F17 | G20: =G8+G10+G9-G12-G13-G14-G15-G17 | H20: =H8+H10+H9-H12-H13-H14-H15-H17 | I20: =I8+I10+I9-I12-I13-I14-I15-I17 | J20: =J8+J10+J9-J12-J13-J14-J15-J17 | K20: =K8+K10+K9-K12-K13-K14-K15-K17 | ... AA20: =AA8+AA10+AA9-AA12-AA13-AA14-AA15-AA17

Sheet Durum_Yr
A1: Durum
A2: Commodity | B2: Metric | C2: Unit | D2: 2002-03 | E2: 2003-04 | F2: 2004-05 | G2: 2005-06 | H2: 2006-07 | I2: 2007-08 | J2: 2008-09 | K2: 2009-10 | L2: 2010-11 | M2: 2011-12 | N2: 2012-13 | O2: 2013-14 | P2: 2014-15 | Q2: 2015-16 | R2: 2016-17 | S2: 2017-18 | T2: 2018-19 | U2: 2019-20 | V2: 2020-21 | W2: 2021-22 | X2: 2022-23 | Y2: 2023-24 | Z2: 2024-25 | AA2: 2025-26
A3: Durum | B3: Planted Area | C3: MLN AC | D3: =Durum_Mo!P3 | E3: =Durum_Mo!P18 | F3: =Durum_Mo!P33 | G3: =Durum_Mo!P48 | H3: =Durum_Mo!P63 | I3: =Durum_Mo!P78 | J3: =Durum_Mo!P93 | K3: =Durum_Mo!P108 | L3: =Durum_Mo!P123 | M3: =Durum_Mo!P138 | N3: =Durum_Mo!P153 | O3: =Durum_Mo!P168 | P3: =Durum_Mo!P183 | Q3: =Durum_Mo!P198 | R3: =Durum_Mo!P213 | S3: =Durum_Mo!P228 | T3: =Durum_Mo!P243 | U3: =Durum_Mo!P258 | V3: =Durum_Mo!P273 | W3: =Durum_Mo!P288 | X3: =Durum_Mo!P303 | Y3: =Durum_Mo!P318 | Z3: =Durum_Mo!P333 | AA3: =Durum_Mo!P348
A4: Durum | B4: Harvested Area | C4: MLN AC | D4: =Durum_Mo!P4 | E4: =Durum_Mo!P19 | F4: =Durum_Mo!P34 | G4: =Durum_Mo!P49 | H4: =Durum_Mo!P64 | I4: =Durum_Mo!P79 | J4: =Durum_Mo!P94 | K4: =Durum_Mo!P109 | L4: =Durum_Mo!P124 | M4: =Durum_Mo!P139 | N4: =Durum_Mo!P154 | O4: =Durum_Mo!P169 | P4: =Durum_Mo!P184 | Q4: =Durum_Mo!P199 | R4: =Durum_Mo!P214 | S4: =Durum_Mo!P229 | T4: =Durum_Mo!P244 | U4: =Durum_Mo!P259 | V4: =Durum_Mo!P274 | W4: =Durum_Mo!P289 | X4: =Durum_Mo!P304 | Y4: =Durum_Mo!P319 | Z4: =Durum_Mo!P334 | AA4: =Durum_Mo!P349
A5: Durum | B5: Proportion Harvested | C5: % | D5: =IF(D3<>0,D4/D3,"") | E5: =IF(E3<>0,E4/E3,"") | F5: =IF(F3<>0,F4/F3,"") | G5: =IF(G3<>0,G4/G3,"") | H5: =IF(H3<>0,H4/H3,"") | I5: =IF(I3<>0,I4/I3,"") | J5: =IF(J3<>0,J4/J3,"") | K5: =IF(K3<>0,K4/K3,"") | ... AA5: =IF(AA3<>0,AA4/AA3,"")
A6: Durum | B6: Yield | C6: BU/AC | D6: =Durum_Mo!O6 | E6: =Durum_Mo!O21 | F6: =Durum_Mo!O36 | G6: =Durum_Mo!O51 | H6: =Durum_Mo!O66 | I6: =Durum_Mo!O81 | J6: =Durum_Mo!O96 | K6: =Durum_Mo!O111 | L6: =Durum_Mo!O126 | M6: =Durum_Mo!O141 | N6: =Durum_Mo!O156 | O6: =Durum_Mo!O171 | P6: =Durum_Mo!O186 | Q6: =Durum_Mo!O201 | R6: =Durum_Mo!O216 | S6: =Durum_Mo!O231 | T6: =Durum_Mo!O246 | U6: =Durum_Mo!O261 | V6: =Durum_Mo!O276 | W6: =Durum_Mo!O291 | X6: =Durum_Mo!O306 | Y6: =Durum_Mo!O321 | Z6: =Durum_Mo!O336 | AA6: =Durum_Mo!O351
A7: Durum
A8: Durum | B8: Beginning Stocks | C8: KMT | D8: =Durum_Mo!P8 | E8: =Durum_Mo!P23 | F8: =Durum_Mo!P38 | G8: =Durum_Mo!P53 | H8: =Durum_Mo!P68 | I8: =Durum_Mo!P83 | J8: =Durum_Mo!P98 | K8: =Durum_Mo!P113 | L8: =Durum_Mo!P128 | M8: =Durum_Mo!P143 | N8: =Durum_Mo!P158 | O8: =Durum_Mo!P173 | P8: =Durum_Mo!P188 | Q8: =Durum_Mo!P203 | R8: =Durum_Mo!P218 | S8: =Durum_Mo!P233 | T8: =Durum_Mo!P248 | U8: =Durum_Mo!P263 | V8: =Durum_Mo!P278 | W8: =Durum_Mo!P293 | X8: =Durum_Mo!P308 | Y8: =Durum_Mo!P323 | Z8: =Durum_Mo!P338 | AA8: =Durum_Mo!P353
A9: Durum | B9: Imports | C9: KMT | D9: =Durum_Mo!P9 | E9: =Durum_Mo!P24 | F9: =Durum_Mo!P39 | G9: =Durum_Mo!P54 | H9: =Durum_Mo!P69 | I9: =Durum_Mo!P84 | J9: =Durum_Mo!P99 | K9: =Durum_Mo!P114 | L9: =Durum_Mo!P129 | M9: =Durum_Mo!P144 | N9: =Durum_Mo!P159 | O9: =Durum_Mo!P174 | P9: =Durum_Mo!P189 | Q9: =Durum_Mo!P204 | R9: =Durum_Mo!P219 | S9: =Durum_Mo!P234 | T9: =Durum_Mo!P249 | U9: =Durum_Mo!P264 | V9: =Durum_Mo!P279 | W9: =Durum_Mo!P294 | X9: =Durum_Mo!P309 | Y9: =Durum_Mo!P324 | Z9: =Durum_Mo!P339 | AA9: =Durum_Mo!P354
A10: Durum | B10: Production | C10: KMT | D10: =Durum_Mo!P10 | E10: =Durum_Mo!P25 | F10: =Durum_Mo!P40 | G10: =Durum_Mo!P55 | H10: =Durum_Mo!P70 | I10: =Durum_Mo!P85 | J10: =Durum_Mo!P100 | K10: =Durum_Mo!P115 | L10: =Durum_Mo!P130 | M10: =Durum_Mo!P145 | N10: =Durum_Mo!P160 | O10: =Durum_Mo!P175 | P10: =Durum_Mo!P190 | Q10: =Durum_Mo!P205 | R10: =Durum_Mo!P220 | S10: =Durum_Mo!P235 | T10: =Durum_Mo!P250 | U10: =Durum_Mo!P265 | V10: =Durum_Mo!P280 | W10: =Durum_Mo!P295 | X10: =Durum_Mo!P310 | Y10: =Durum_Mo!P325 | Z10: =Durum_Mo!P340 | AA10: =Durum_Mo!P355
A11: Durum
A12: Durum | B12: Food | C12: KMT | D12: =Durum_Mo!P12 | E12: =Durum_Mo!P27 | F12: =Durum_Mo!P42 | G12: =Durum_Mo!P57 | H12: =Durum_Mo!P72 | I12: =Durum_Mo!P87 | J12: =Durum_Mo!P102 | K12: =Durum_Mo!P117 | L12: =Durum_Mo!P132 | M12: =Durum_Mo!P147 | N12: =Durum_Mo!P162 | O12: =Durum_Mo!P177 | P12: =Durum_Mo!P192 | Q12: =Durum_Mo!P207 | R12: =Durum_Mo!P222 | S12: =Durum_Mo!P237 | T12: =Durum_Mo!P252 | U12: =Durum_Mo!P267 | V12: =Durum_Mo!P282 | W12: =Durum_Mo!P297 | X12: =Durum_Mo!P312 | Y12: =Durum_Mo!P327 | Z12: =Durum_Mo!P342 | AA12: =Durum_Mo!P357
A13: Durum | B13: Industrial | C13: KMT | D13: =Durum_Mo!P13 | E13: =Durum_Mo!P28 | F13: =Durum_Mo!P43 | G13: =Durum_Mo!P58 | H13: =Durum_Mo!P73 | I13: =Durum_Mo!P88 | J13: =Durum_Mo!P103 | K13: =Durum_Mo!P118 | L13: =Durum_Mo!P133 | M13: =Durum_Mo!P148 | N13: =Durum_Mo!P163 | O13: =Durum_Mo!P178 | P13: =Durum_Mo!P193 | Q13: =Durum_Mo!P208 | R13: =Durum_Mo!P223 | S13: =Durum_Mo!P238 | T13: =Durum_Mo!P253 | U13: =Durum_Mo!P268 | V13: =Durum_Mo!P283 | W13: =Durum_Mo!P298 | X13: =Durum_Mo!P313 | Y13: =Durum_Mo!P328 | Z13: =Durum_Mo!P343 | AA13: =Durum_Mo!P358
A14: Durum | B14: FSR | C14: KMT | D14: =Durum_Mo!P14 | E14: =Durum_Mo!P29 | F14: =Durum_Mo!P44 | G14: =Durum_Mo!P59 | H14: =Durum_Mo!P74 | I14: =Durum_Mo!P89 | J14: =Durum_Mo!P104 | K14: =Durum_Mo!P119 | L14: =Durum_Mo!P134 | M14: =Durum_Mo!P149 | N14: =Durum_Mo!P164 | O14: =Durum_Mo!P179 | P14: =Durum_Mo!P194 | Q14: =Durum_Mo!P209 | R14: =Durum_Mo!P224 | S14: =Durum_Mo!P239 | T14: =Durum_Mo!P254 | U14: =Durum_Mo!P269 | V14: =Durum_Mo!P284 | W14: =Durum_Mo!P299 | X14: =Durum_Mo!P314 | Y14: =Durum_Mo!P329 | Z14: =Durum_Mo!P344 | AA14: =Durum_Mo!P359
A15: Durum | B15: Exports | C15: KMT | D15: =Durum_Mo!P15 | E15: =Durum_Mo!P30 | F15: =Durum_Mo!P45 | G15: =Durum_Mo!P60 | H15: =Durum_Mo!P75 | I15: =Durum_Mo!P90 | J15: =Durum_Mo!P105 | K15: =Durum_Mo!P120 | L15: =Durum_Mo!P135 | M15: =Durum_Mo!P150 | N15: =Durum_Mo!P165 | O15: =Durum_Mo!P180 | P15: =Durum_Mo!P195 | Q15: =Durum_Mo!P210 | R15: =Durum_Mo!P225 | S15: =Durum_Mo!P240 | T15: =Durum_Mo!P255 | U15: =Durum_Mo!P270 | V15: =Durum_Mo!P285 | W15: =Durum_Mo!P300 | X15: =Durum_Mo!P315 | Y15: =Durum_Mo!P330 | Z15: =Durum_Mo!P345 | AA15: =Durum_Mo!P360
A16: Durum
A17: Durum | B17: Ending Stocks | C17: KMT | D17: =Durum_Mo!P17 | E17: =Durum_Mo!P32 | F17: =Durum_Mo!P47 | G17: =Durum_Mo!P62 | H17: =Durum_Mo!P77 | I17: =Durum_Mo!P92 | J17: =Durum_Mo!P107 | K17: =Durum_Mo!P122 | L17: =Durum_Mo!P137 | M17: =Durum_Mo!P152 | N17: =Durum_Mo!P167 | O17: =Durum_Mo!P182 | P17: =Durum_Mo!P197 | Q17: =Durum_Mo!P212 | R17: =Durum_Mo!P227 | S17: =Durum_Mo!P242 | T17: =Durum_Mo!P257 | U17: =Durum_Mo!P272 | V17: =Durum_Mo!P287 | W17: =Durum_Mo!P302 | X17: =Durum_Mo!P317 | Y17: =Durum_Mo!P332 | Z17: =Durum_Mo!P347 | AA17: =Durum_Mo!P362
A18: Durum | B18: Stocks-to-Use | C18: %
A19: Durum | B19: STU Days | C19: Days
A20: Durum | B20: CHECK | C20: KMT | D20: =D8+D10+D9-D12-D13-D14-D15-D17 | E20: =E8+E10+E9-E12-E13-E14-E15-E17 | F20: =F8+F10+F9-F12-F13-F14-F15-F17 | G20: =G8+G10+G9-G12-G13-G14-G15-G17 | H20: =H8+H10+H9-H12-H13-H14-H15-H17 | I20: =I8+I10+I9-I12-I13-I14-I15-I17 | J20: =J8+J10+J9-J12-J13-J14-J15-J17 | K20: =K8+K10+K9-K12-K13-K14-K15-K17 | ... AA20: =AA8+AA10+AA9-AA12-AA13-AA14-AA15-AA17

Sheet Canola_Yr
A1: Canola
A2: Commodity | B2: Metric | C2: Unit | D2: 2002-03 | E2: 2003-04 | F2: 2004-05 | G2: 2005-06 | H2: 2006-07 | I2: 2007-08 | J2: 2008-09 | K2: 2009-10 | L2: 2010-11 | M2: 2011-12 | N2: 2012-13 | O2: 2013-14 | P2: 2014-15 | Q2: 2015-16 | R2: 2016-17 | S2: 2017-18 | T2: 2018-19 | U2: 2019-20 | V2: 2020-21 | W2: 2021-22 | X2: 2022-23 | Y2: 2023-24 | Z2: 2024-25 | AA2: 2025-26
A3: Canola | B3: Planted Area | C3: MLN AC | D3: =Canola_Mo!P3 | E3: =Canola_Mo!P18 | F3: =Canola_Mo!P33 | G3: =Canola_Mo!P48 | H3: =Canola_Mo!P63 | I3: =Canola_Mo!P78 | J3: =Canola_Mo!P93 | K3: =Canola_Mo!P108 | L3: =Canola_Mo!P123 | M3: =Canola_Mo!P138 | N3: =Canola_Mo!P153 | O3: =Canola_Mo!P168 | P3: =Canola_Mo!P183 | Q3: =Canola_Mo!P198 | R3: =Canola_Mo!P213 | S3: =Canola_Mo!P228 | T3: =Canola_Mo!P243 | U3: =Canola_Mo!P258 | V3: =Canola_Mo!P273 | W3: =Canola_Mo!P288 | X3: =Canola_Mo!P303 | Y3: =Canola_Mo!P318 | Z3: =Canola_Mo!P333 | AA3: =Canola_Mo!P348
A4: Canola | B4: Harvested Area | C4: MLN AC | D4: =Canola_Mo!P4 | E4: =Canola_Mo!P19 | F4: =Canola_Mo!P34 | G4: =Canola_Mo!P49 | H4: =Canola_Mo!P64 | I4: =Canola_Mo!P79 | J4: =Canola_Mo!P94 | K4: =Canola_Mo!P109 | L4: =Canola_Mo!P124 | M4: =Canola_Mo!P139 | N4: =Canola_Mo!P154 | O4: =Canola_Mo!P169 | P4: =Canola_Mo!P184 | Q4: =Canola_Mo!P199 | R4: =Canola_Mo!P214 | S4: =Canola_Mo!P229 | T4: =Canola_Mo!P244 | U4: =Canola_Mo!P259 | V4: =Canola_Mo!P274 | W4: =Canola_Mo!P289 | X4: =Canola_Mo!P304 | Y4: =Canola_Mo!P319 | Z4: =Canola_Mo!P334 | AA4: =Canola_Mo!P349
A5: Canola | B5: Proportion Harvested | C5: % | D5: =IF(D3<>0,D4/D3,"") | E5: =IF(E3<>0,E4/E3,"") | F5: =IF(F3<>0,F4/F3,"") | G5: =IF(G3<>0,G4/G3,"") | H5: =IF(H3<>0,H4/H3,"") | I5: =IF(I3<>0,I4/I3,"") | J5: =IF(J3<>0,J4/J3,"") | K5: =IF(K3<>0,K4/K3,"") | ... AA5: =IF(AA3<>0,AA4/AA3,"")
A6: Canola | B6: Yield | C6: BU/AC | D6: =Canola_Mo!O6 | E6: =Canola_Mo!O21 | F6: =Canola_Mo!O36 | G6: =Canola_Mo!O51 | H6: =Canola_Mo!O66 | I6: =Canola_Mo!O81 | J6: =Canola_Mo!O96 | K6: =Canola_Mo!O111 | L6: =Canola_Mo!O126 | M6: =Canola_Mo!O141 | N6: =Canola_Mo!O156 | O6: =Canola_Mo!O171 | P6: =Canola_Mo!O186 | Q6: =Canola_Mo!O201 | R6: =Canola_Mo!O216 | S6: =Canola_Mo!O231 | T6: =Canola_Mo!O246 | U6: =Canola_Mo!O261 | V6: =Canola_Mo!O276 | W6: =Canola_Mo!O291 | X6: =Canola_Mo!O306 | Y6: =Canola_Mo!O321 | Z6: =Canola_Mo!O336 | AA6: =Canola_Mo!O351
A7: Canola
A8: Canola | B8: Beginning Stocks | C8: KMT | D8: =Canola_Mo!P8 | E8: =Canola_Mo!P23 | F8: =Canola_Mo!P38 | G8: =Canola_Mo!P53 | H8: =Canola_Mo!P68 | I8: =Canola_Mo!P83 | J8: =Canola_Mo!P98 | K8: =Canola_Mo!P113 | L8: =Canola_Mo!P128 | M8: =Canola_Mo!P143 | N8: =Canola_Mo!P158 | O8: =Canola_Mo!P173 | P8: =Canola_Mo!P188 | Q8: =Canola_Mo!P203 | R8: =Canola_Mo!P218 | S8: =Canola_Mo!P233 | T8: =Canola_Mo!P248 | U8: =Canola_Mo!P263 | V8: =Canola_Mo!P278 | W8: =Canola_Mo!P293 | X8: =Canola_Mo!P308 | Y8: =Canola_Mo!P323 | Z8: =Canola_Mo!P338 | AA8: =Canola_Mo!P353
A9: Canola | B9: Imports | C9: KMT | D9: =Canola_Mo!P9 | E9: =Canola_Mo!P24 | F9: =Canola_Mo!P39 | G9: =Canola_Mo!P54 | H9: =Canola_Mo!P69 | I9: =Canola_Mo!P84 | J9: =Canola_Mo!P99 | K9: =Canola_Mo!P114 | L9: =Canola_Mo!P129 | M9: =Canola_Mo!P144 | N9: =Canola_Mo!P159 | O9: =Canola_Mo!P174 | P9: =Canola_Mo!P189 | Q9: =Canola_Mo!P204 | R9: =Canola_Mo!P219 | S9: =Canola_Mo!P234 | T9: =Canola_Mo!P249 | U9: =Canola_Mo!P264 | V9: =Canola_Mo!P279 | W9: =Canola_Mo!P294 | X9: =Canola_Mo!P309 | Y9: =Canola_Mo!P324 | Z9: =Canola_Mo!P339 | AA9: =Canola_Mo!P354
A10: Canola | B10: Production | C10: KMT | D10: =Canola_Mo!P10 | E10: =Canola_Mo!P25 | F10: =Canola_Mo!P40 | G10: =Canola_Mo!P55 | H10: =Canola_Mo!P70 | I10: =Canola_Mo!P85 | J10: =Canola_Mo!P100 | K10: =Canola_Mo!P115 | L10: =Canola_Mo!P130 | M10: =Canola_Mo!P145 | N10: =Canola_Mo!P160 | O10: =Canola_Mo!P175 | P10: =Canola_Mo!P190 | Q10: =Canola_Mo!P205 | R10: =Canola_Mo!P220 | S10: =Canola_Mo!P235 | T10: =Canola_Mo!P250 | U10: =Canola_Mo!P265 | V10: =Canola_Mo!P280 | W10: =Canola_Mo!P295 | X10: =Canola_Mo!P310 | Y10: =Canola_Mo!P325 | Z10: =Canola_Mo!P340 | AA10: =Canola_Mo!P355
A11: Canola
A12: Canola | B12: Food | C12: KMT | D12: =Canola_Mo!P12 | E12: =Canola_Mo!P27 | F12: =Canola_Mo!P42 | G12: =Canola_Mo!P57 | H12: =Canola_Mo!P72 | I12: =Canola_Mo!P87 | J12: =Canola_Mo!P102 | K12: =Canola_Mo!P117 | L12: =Canola_Mo!P132 | M12: =Canola_Mo!P147 | N12: =Canola_Mo!P162 | O12: =Canola_Mo!P177 | P12: =Canola_Mo!P192 | Q12: =Canola_Mo!P207 | R12: =Canola_Mo!P222 | S12: =Canola_Mo!P237 | T12: =Canola_Mo!P252 | U12: =Canola_Mo!P267 | V12: =Canola_Mo!P282 | W12: =Canola_Mo!P297 | X12: =Canola_Mo!P312 | Y12: =Canola_Mo!P327 | Z12: =Canola_Mo!P342 | AA12: =Canola_Mo!P357
A13: Canola | B13: Crush | C13: KMT | D13: =Canola_Mo!P13 | E13: =Canola_Mo!P28 | F13: =Canola_Mo!P43 | G13: =Canola_Mo!P58 | H13: =Canola_Mo!P73 | I13: =Canola_Mo!P88 | J13: =Canola_Mo!P103 | K13: =Canola_Mo!P118 | L13: =Canola_Mo!P133 | M13: =Canola_Mo!P148 | N13: =Canola_Mo!P163 | O13: =Canola_Mo!P178 | P13: =Canola_Mo!P193 | Q13: =Canola_Mo!P208 | R13: =Canola_Mo!P223 | S13: =Canola_Mo!P238 | T13: =Canola_Mo!P253 | U13: =Canola_Mo!P268 | V13: =Canola_Mo!P283 | W13: =Canola_Mo!P298 | X13: =Canola_Mo!P313 | Y13: =Canola_Mo!P328 | Z13: =Canola_Mo!P343 | AA13: =Canola_Mo!P358
A14: Canola | B14: FSR | C14: KMT | D14: =Canola_Mo!P14 | E14: =Canola_Mo!P29 | F14: =Canola_Mo!P44 | G14: =Canola_Mo!P59 | H14: =Canola_Mo!P74 | I14: =Canola_Mo!P89 | J14: =Canola_Mo!P104 | K14: =Canola_Mo!P119 | L14: =Canola_Mo!P134 | M14: =Canola_Mo!P149 | N14: =Canola_Mo!P164 | O14: =Canola_Mo!P179 | P14: =Canola_Mo!P194 | Q14: =Canola_Mo!P209 | R14: =Canola_Mo!P224 | S14: =Canola_Mo!P239 | T14: =Canola_Mo!P254 | U14: =Canola_Mo!P269 | V14: =Canola_Mo!P284 | W14: =Canola_Mo!P299 | X14: =Canola_Mo!P314 | Y14: =Canola_Mo!P329 | Z14: =Canola_Mo!P344 | AA14: =Canola_Mo!P359
A15: Canola | B15: Exports | C15: KMT | D15: =Canola_Mo!P15 | E15: =Canola_Mo!P30 | F15: =Canola_Mo!P45 | G15: =Canola_Mo!P60 | H15: =Canola_Mo!P75 | I15: =Canola_Mo!P90 | J15: =Canola_Mo!P105 | K15: =Canola_Mo!P120 | L15: =Canola_Mo!P135 | M15: =Canola_Mo!P150 | N15: =Canola_Mo!P165 | O15: =Canola_Mo!P180 | P15: =Canola_Mo!P195 | Q15: =Canola_Mo!P210 | R15: =Canola_Mo!P225 | S15: =Canola_Mo!P240 | T15: =Canola_Mo!P255 | U15: =Canola_Mo!P270 | V15: =Canola_Mo!P285 | W15: =Canola_Mo!P300 | X15: =Canola_Mo!P315 | Y15: =Canola_Mo!P330 | Z15: =Canola_Mo!P345 | AA15: =Canola_Mo!P360
A16: Canola
A17: Canola | B17: Ending Stocks | C17: KMT | D17: =Canola_Mo!P17 | E17: =Canola_Mo!P32 | F17: =Canola_Mo!P47 | G17: =Canola_Mo!P62 | H17: =Canola_Mo!P77 | I17: =Canola_Mo!P92 | J17: =Canola_Mo!P107 | K17: =Canola_Mo!P122 | L17: =Canola_Mo!P137 | M17: =Canola_Mo!P152 | N17: =Canola_Mo!P167 | O17: =Canola_Mo!P182 | P17: =Canola_Mo!P197 | Q17: =Canola_Mo!P212 | R17: =Canola_Mo!P227 | S17: =Canola_Mo!P242 | T17: =Canola_Mo!P257 | U17: =Canola_Mo!P272 | V17: =Canola_Mo!P287 | W17: =Canola_Mo!P302 | X17: =Canola_Mo!P317 | Y17: =Canola_Mo!P332 | Z17: =Canola_Mo!P347 | AA17: =Canola_Mo!P362
A18: Canola | B18: Stocks-to-Use | C18: %
A19: Canola | B19: STU Days | C19: Days
A20: Canola | B20: CHECK | C20: KMT

Sheet Barley_Yr
A1: Barley
A2: Commodity | B2: Metric | C2: Unit | D2: 2002-03 | E2: 2003-04 | F2: 2004-05 | G2: 2005-06 | H2: 2006-07 | I2: 2007-08 | J2: 2008-09 | K2: 2009-10 | L2: 2010-11 | M2: 2011-12 | N2: 2012-13 | O2: 2013-14 | P2: 2014-15 | Q2: 2015-16 | R2: 2016-17 | S2: 2017-18 | T2: 2018-19 | U2: 2019-20 | V2: 2020-21 | W2: 2021-22 | X2: 2022-23 | Y2: 2023-24 | Z2: 2024-25 | AA2: 2025-26
A3: Barley | B3: Planted Area | C3: MLN AC | D3: =Barley_Mo!P3 | E3: =Barley_Mo!P18 | F3: =Barley_Mo!P33 | G3: =Barley_Mo!P48 | H3: =Barley_Mo!P63 | I3: =Barley_Mo!P78 | J3: =Barley_Mo!P93 | K3: =Barley_Mo!P108 | L3: =Barley_Mo!P123 | M3: =Barley_Mo!P138 | N3: =Barley_Mo!P153 | O3: =Barley_Mo!P168 | P3: =Barley_Mo!P183 | Q3: =Barley_Mo!P198 | R3: =Barley_Mo!P213 | S3: =Barley_Mo!P228 | T3: =Barley_Mo!P243 | U3: =Barley_Mo!P258 | V3: =Barley_Mo!P273 | W3: =Barley_Mo!P288 | X3: =Barley_Mo!P303 | Y3: =Barley_Mo!P318 | Z3: =Barley_Mo!P333 | AA3: =Barley_Mo!P348
A4: Barley | B4: Harvested Area | C4: MLN AC | D4: =Barley_Mo!P4 | E4: =Barley_Mo!P19 | F4: =Barley_Mo!P34 | G4: =Barley_Mo!P49 | H4: =Barley_Mo!P64 | I4: =Barley_Mo!P79 | J4: =Barley_Mo!P94 | K4: =Barley_Mo!P109 | L4: =Barley_Mo!P124 | M4: =Barley_Mo!P139 | N4: =Barley_Mo!P154 | O4: =Barley_Mo!P169 | P4: =Barley_Mo!P184 | Q4: =Barley_Mo!P199 | R4: =Barley_Mo!P214 | S4: =Barley_Mo!P229 | T4: =Barley_Mo!P244 | U4: =Barley_Mo!P259 | V4: =Barley_Mo!P274 | W4: =Barley_Mo!P289 | X4: =Barley_Mo!P304 | Y4: =Barley_Mo!P319 | Z4: =Barley_Mo!P334 | AA4: =Barley_Mo!P349
A5: Barley | B5: Proportion Harvested | C5: % | D5: =IF(D3<>0,D4/D3,"") | E5: =IF(E3<>0,E4/E3,"") | F5: =IF(F3<>0,F4/F3,"") | G5: =IF(G3<>0,G4/G3,"") | H5: =IF(H3<>0,H4/H3,"") | I5: =IF(I3<>0,I4/I3,"") | J5: =IF(J3<>0,J4/J3,"") | K5: =IF(K3<>0,K4/K3,"") | ... AA5: =IF(AA3<>0,AA4/AA3,"")
A6: Barley | B6: Yield | C6: BU/AC | D6: =Barley_Mo!O6 | E6: =Barley_Mo!O21 | F6: =Barley_Mo!O36 | G6: =Barley_Mo!O51 | H6: =Barley_Mo!O66 | I6: =Barley_Mo!O81 | J6: =Barley_Mo!O96 | K6: =Barley_Mo!O111 | L6: =Barley_Mo!O126 | M6: =Barley_Mo!O141 | N6: =Barley_Mo!O156 | O6: =Barley_Mo!O171 | P6: =Barley_Mo!O186 | Q6: =Barley_Mo!O201 | R6: =Barley_Mo!O216 | S6: =Barley_Mo!O231 | T6: =Barley_Mo!O246 | U6: =Barley_Mo!O261 | V6: =Barley_Mo!O276 | W6: =Barley_Mo!O291 | X6: =Barley_Mo!O306 | Y6: =Barley_Mo!O321 | Z6: =Barley_Mo!O336 | AA6: =Barley_Mo!O351
A7: Barley
A8: Barley | B8: Beginning Stocks | C8: KMT | D8: =Barley_Mo!P8 | E8: =Barley_Mo!P23 | F8: =Barley_Mo!P38 | G8: =Barley_Mo!P53 | H8: =Barley_Mo!P68 | I8: =Barley_Mo!P83 | J8: =Barley_Mo!P98 | K8: =Barley_Mo!P113 | L8: =Barley_Mo!P128 | M8: =Barley_Mo!P143 | N8: =Barley_Mo!P158 | O8: =Barley_Mo!P173 | P8: =Barley_Mo!P188 | Q8: =Barley_Mo!P203 | R8: =Barley_Mo!P218 | S8: =Barley_Mo!P233 | T8: =Barley_Mo!P248 | U8: =Barley_Mo!P263 | V8: =Barley_Mo!P278 | W8: =Barley_Mo!P293 | X8: =Barley_Mo!P308 | Y8: =Barley_Mo!P323 | Z8: =Barley_Mo!P338 | AA8: =Barley_Mo!P353
A9: Barley | B9: Imports | C9: KMT | D9: =Barley_Mo!P9 | E9: =Barley_Mo!P24 | F9: =Barley_Mo!P39 | G9: =Barley_Mo!P54 | H9: =Barley_Mo!P69 | I9: =Barley_Mo!P84 | J9: =Barley_Mo!P99 | K9: =Barley_Mo!P114 | L9: =Barley_Mo!P129 | M9: =Barley_Mo!P144 | N9: =Barley_Mo!P159 | O9: =Barley_Mo!P174 | P9: =Barley_Mo!P189 | Q9: =Barley_Mo!P204 | R9: =Barley_Mo!P219 | S9: =Barley_Mo!P234 | T9: =Barley_Mo!P249 | U9: =Barley_Mo!P264 | V9: =Barley_Mo!P279 | W9: =Barley_Mo!P294 | X9: =Barley_Mo!P309 | Y9: =Barley_Mo!P324 | Z9: =Barley_Mo!P339 | AA9: =Barley_Mo!P354
A10: Barley | B10: Production | C10: KMT | D10: =Barley_Mo!P10 | E10: =Barley_Mo!P25 | F10: =Barley_Mo!P40 | G10: =Barley_Mo!P55 | H10: =Barley_Mo!P70 | I10: =Barley_Mo!P85 | J10: =Barley_Mo!P100 | K10: =Barley_Mo!P115 | L10: =Barley_Mo!P130 | M10: =Barley_Mo!P145 | N10: =Barley_Mo!P160 | O10: =Barley_Mo!P175 | P10: =Barley_Mo!P190 | Q10: =Barley_Mo!P205 | R10: =Barley_Mo!P220 | S10: =Barley_Mo!P235 | T10: =Barley_Mo!P250 | U10: =Barley_Mo!P265 | V10: =Barley_Mo!P280 | W10: =Barley_Mo!P295 | X10: =Barley_Mo!P310 | Y10: =Barley_Mo!P325 | Z10: =Barley_Mo!P340 | AA10: =Barley_Mo!P355
A11: Barley
A12: Barley | B12: Food | C12: KMT | D12: =Barley_Mo!P12 | E12: =Barley_Mo!P27 | F12: =Barley_Mo!P42 | G12: =Barley_Mo!P57 | H12: =Barley_Mo!P72 | I12: =Barley_Mo!P87 | J12: =Barley_Mo!P102 | K12: =Barley_Mo!P117 | L12: =Barley_Mo!P132 | M12: =Barley_Mo!P147 | N12: =Barley_Mo!P162 | O12: =Barley_Mo!P177 | P12: =Barley_Mo!P192 | Q12: =Barley_Mo!P207 | R12: =Barley_Mo!P222 | S12: =Barley_Mo!P237 | T12: =Barley_Mo!P252 | U12: =Barley_Mo!P267 | V12: =Barley_Mo!P282 | W12: =Barley_Mo!P297 | X12: =Barley_Mo!P312 | Y12: =Barley_Mo!P327 | Z12: =Barley_Mo!P342 | AA12: =Barley_Mo!P357
A13: Barley | B13: Industrial | C13: KMT | D13: =Barley_Mo!P13 | E13: =Barley_Mo!P28 | F13: =Barley_Mo!P43 | G13: =Barley_Mo!P58 | H13: =Barley_Mo!P73 | I13: =Barley_Mo!P88 | J13: =Barley_Mo!P103 | K13: =Barley_Mo!P118 | L13: =Barley_Mo!P133 | M13: =Barley_Mo!P148 | N13: =Barley_Mo!P163 | O13: =Barley_Mo!P178 | P13: =Barley_Mo!P193 | Q13: =Barley_Mo!P208 | R13: =Barley_Mo!P223 | S13: =Barley_Mo!P238 | T13: =Barley_Mo!P253 | U13: =Barley_Mo!P268 | V13: =Barley_Mo!P283 | W13: =Barley_Mo!P298 | X13: =Barley_Mo!P313 | Y13: =Barley_Mo!P328 | Z13: =Barley_Mo!P343 | AA13: =Barley_Mo!P358
A14: Barley | B14: FSR | C14: KMT | D14: =Barley_Mo!P14 | E14: =Barley_Mo!P29 | F14: =Barley_Mo!P44 | G14: =Barley_Mo!P59 | H14: =Barley_Mo!P74 | I14: =Barley_Mo!P89 | J14: =Barley_Mo!P104 | K14: =Barley_Mo!P119 | L14: =Barley_Mo!P134 | M14: =Barley_Mo!P149 | N14: =Barley_Mo!P164 | O14: =Barley_Mo!P179 | P14: =Barley_Mo!P194 | Q14: =Barley_Mo!P209 | R14: =Barley_Mo!P224 | S14: =Barley_Mo!P239 | T14: =Barley_Mo!P254 | U14: =Barley_Mo!P269 | V14: =Barley_Mo!P284 | W14: =Barley_Mo!P299 | X14: =Barley_Mo!P314 | Y14: =Barley_Mo!P329 | Z14: =Barley_Mo!P344 | AA14: =Barley_Mo!P359
A15: Barley | B15: Exports | C15: KMT | D15: =Barley_Mo!P15 | E15: =Barley_Mo!P30 | F15: =Barley_Mo!P45 | G15: =Barley_Mo!P60 | H15: =Barley_Mo!P75 | I15: =Barley_Mo!P90 | J15: =Barley_Mo!P105 | K15: =Barley_Mo!P120 | L15: =Barley_Mo!P135 | M15: =Barley_Mo!P150 | N15: =Barley_Mo!P165 | O15: =Barley_Mo!P180 | P15: =Barley_Mo!P195 | Q15: =Barley_Mo!P210 | R15: =Barley_Mo!P225 | S15: =Barley_Mo!P240 | T15: =Barley_Mo!P255 | U15: =Barley_Mo!P270 | V15: =Barley_Mo!P285 | W15: =Barley_Mo!P300 | X15: =Barley_Mo!P315 | Y15: =Barley_Mo!P330 | Z15: =Barley_Mo!P345 | AA15: =Barley_Mo!P360
A16: Barley
A17: Barley | B17: Ending Stocks | C17: KMT | D17: =Barley_Mo!P17 | E17: =Barley_Mo!P32 | F17: =Barley_Mo!P47 | G17: =Barley_Mo!P62 | H17: =Barley_Mo!P77 | I17: =Barley_Mo!P92 | J17: =Barley_Mo!P107 | K17: =Barley_Mo!P122 | L17: =Barley_Mo!P137 | M17: =Barley_Mo!P152 | N17: =Barley_Mo!P167 | O17: =Barley_Mo!P182 | P17: =Barley_Mo!P197 | Q17: =Barley_Mo!P212 | R17: =Barley_Mo!P227 | S17: =Barley_Mo!P242 | T17: =Barley_Mo!P257 | U17: =Barley_Mo!P272 | V17: =Barley_Mo!P287 | W17: =Barley_Mo!P302 | X17: =Barley_Mo!P317 | Y17: =Barley_Mo!P332 | Z17: =Barley_Mo!P347 | AA17: =Barley_Mo!P362
A18: Barley | B18: Stocks-to-Use | C18: %
A19: Barley | B19: STU Days | C19: Days
A20: Barley | B20: CHECK | C20: KMT | D20: =D8+D10+D9-D12-D13-D14-D15-D17 | E20: =E8+E10+E9-E12-E13-E14-E15-E17 | F20: =F8+F10+F9-F12-F13-F14-F15-F17 | G20: =G8+G10+G9-G12-G13-G14-G15-G17 | H20: =H8+H10+H9-H12-H13-H14-H15-H17 | I20: =I8+I10+I9-I12-I13-I14-I15-I17 | J20: =J8+J10+J9-J12-J13-J14-J15-J17 | K20: =K8+K10+K9-K12-K13-K14-K15-K17 | ... AA20: =AA8+AA10+AA9-AA12-AA13-AA14-AA15-AA17

Sheet Oats_Yr
A1: Oats
A2: Commodity | B2: Metric | C2: Unit | D2: 2002-03 | E2: 2003-04 | F2: 2004-05 | G2: 2005-06 | H2: 2006-07 | I2: 2007-08 | J2: 2008-09 | K2: 2009-10 | L2: 2010-11 | M2: 2011-12 | N2: 2012-13 | O2: 2013-14 | P2: 2014-15 | Q2: 2015-16 | R2: 2016-17 | S2: 2017-18 | T2: 2018-19 | U2: 2019-20 | V2: 2020-21 | W2: 2021-22 | X2: 2022-23 | Y2: 2023-24 | Z2: 2024-25 | AA2: 2025-26
A3: Oats | B3: Planted Area | C3: MLN AC | D3: =Oats_Mo!P3 | E3: =Oats_Mo!P18 | F3: =Oats_Mo!P33 | G3: =Oats_Mo!P48 | H3: =Oats_Mo!P63 | I3: =Oats_Mo!P78 | J3: =Oats_Mo!P93 | K3: =Oats_Mo!P108 | L3: =Oats_Mo!P123 | M3: =Oats_Mo!P138 | N3: =Oats_Mo!P153 | O3: =Oats_Mo!P168 | P3: =Oats_Mo!P183 | Q3: =Oats_Mo!P198 | R3: =Oats_Mo!P213 | S3: =Oats_Mo!P228 | T3: =Oats_Mo!P243 | U3: =Oats_Mo!P258 | V3: =Oats_Mo!P273 | W3: =Oats_Mo!P288 | X3: =Oats_Mo!P303 | Y3: =Oats_Mo!P318 | Z3: =Oats_Mo!P333 | AA3: =Oats_Mo!P348
A4: Oats | B4: Harvested Area | C4: MLN AC | D4: =Oats_Mo!P4 | E4: =Oats_Mo!P19 | F4: =Oats_Mo!P34 | G4: =Oats_Mo!P49 | H4: =Oats_Mo!P64 | I4: =Oats_Mo!P79 | J4: =Oats_Mo!P94 | K4: =Oats_Mo!P109 | L4: =Oats_Mo!P124 | M4: =Oats_Mo!P139 | N4: =Oats_Mo!P154 | O4: =Oats_Mo!P169 | P4: =Oats_Mo!P184 | Q4: =Oats_Mo!P199 | R4: =Oats_Mo!P214 | S4: =Oats_Mo!P229 | T4: =Oats_Mo!P244 | U4: =Oats_Mo!P259 | V4: =Oats_Mo!P274 | W4: =Oats_Mo!P289 | X4: =Oats_Mo!P304 | Y4: =Oats_Mo!P319 | Z4: =Oats_Mo!P334 | AA4: =Oats_Mo!P349
A5: Oats | B5: Proportion Harvested | C5: % | D5: =IF(D3<>0,D4/D3,"") | E5: =IF(E3<>0,E4/E3,"") | F5: =IF(F3<>0,F4/F3,"") | G5: =IF(G3<>0,G4/G3,"") | H5: =IF(H3<>0,H4/H3,"") | I5: =IF(I3<>0,I4/I3,"") | J5: =IF(J3<>0,J4/J3,"") | K5: =IF(K3<>0,K4/K3,"") | ... AA5: =IF(AA3<>0,AA4/AA3,"")
A6: Oats | B6: Yield | C6: BU/AC | D6: =Oats_Mo!O6 | E6: =Oats_Mo!O21 | F6: =Oats_Mo!O36 | G6: =Oats_Mo!O51 | H6: =Oats_Mo!O66 | I6: =Oats_Mo!O81 | J6: =Oats_Mo!O96 | K6: =Oats_Mo!O111 | L6: =Oats_Mo!O126 | M6: =Oats_Mo!O141 | N6: =Oats_Mo!O156 | O6: =Oats_Mo!O171 | P6: =Oats_Mo!O186 | Q6: =Oats_Mo!O201 | R6: =Oats_Mo!O216 | S6: =Oats_Mo!O231 | T6: =Oats_Mo!O246 | U6: =Oats_Mo!O261 | V6: =Oats_Mo!O276 | W6: =Oats_Mo!O291 | X6: =Oats_Mo!O306 | Y6: =Oats_Mo!O321 | Z6: =Oats_Mo!O336 | AA6: =Oats_Mo!O351
A7: Oats
A8: Oats | B8: Beginning Stocks | C8: KMT | D8: =Oats_Mo!P8 | E8: =Oats_Mo!P23 | F8: =Oats_Mo!P38 | G8: =Oats_Mo!P53 | H8: =Oats_Mo!P68 | I8: =Oats_Mo!P83 | J8: =Oats_Mo!P98 | K8: =Oats_Mo!P113 | L8: =Oats_Mo!P128 | M8: =Oats_Mo!P143 | N8: =Oats_Mo!P158 | O8: =Oats_Mo!P173 | P8: =Oats_Mo!P188 | Q8: =Oats_Mo!P203 | R8: =Oats_Mo!P218 | S8: =Oats_Mo!P233 | T8: =Oats_Mo!P248 | U8: =Oats_Mo!P263 | V8: =Oats_Mo!P278 | W8: =Oats_Mo!P293 | X8: =Oats_Mo!P308 | Y8: =Oats_Mo!P323 | Z8: =Oats_Mo!P338 | AA8: =Oats_Mo!P353
A9: Oats | B9: Imports | C9: KMT | D9: =Oats_Mo!P9 | E9: =Oats_Mo!P24 | F9: =Oats_Mo!P39 | G9: =Oats_Mo!P54 | H9: =Oats_Mo!P69 | I9: =Oats_Mo!P84 | J9: =Oats_Mo!P99 | K9: =Oats_Mo!P114 | L9: =Oats_Mo!P129 | M9: =Oats_Mo!P144 | N9: =Oats_Mo!P159 | O9: =Oats_Mo!P174 | P9: =Oats_Mo!P189 | Q9: =Oats_Mo!P204 | R9: =Oats_Mo!P219 | S9: =Oats_Mo!P234 | T9: =Oats_Mo!P249 | U9: =Oats_Mo!P264 | V9: =Oats_Mo!P279 | W9: =Oats_Mo!P294 | X9: =Oats_Mo!P309 | Y9: =Oats_Mo!P324 | Z9: =Oats_Mo!P339 | AA9: =Oats_Mo!P354
A10: Oats | B10: Production | C10: KMT | D10: =Oats_Mo!P10 | E10: =Oats_Mo!P25 | F10: =Oats_Mo!P40 | G10: =Oats_Mo!P55 | H10: =Oats_Mo!P70 | I10: =Oats_Mo!P85 | J10: =Oats_Mo!P100 | K10: =Oats_Mo!P115 | L10: =Oats_Mo!P130 | M10: =Oats_Mo!P145 | N10: =Oats_Mo!P160 | O10: =Oats_Mo!P175 | P10: =Oats_Mo!P190 | Q10: =Oats_Mo!P205 | R10: =Oats_Mo!P220 | S10: =Oats_Mo!P235 | T10: =Oats_Mo!P250 | U10: =Oats_Mo!P265 | V10: =Oats_Mo!P280 | W10: =Oats_Mo!P295 | X10: =Oats_Mo!P310 | Y10: =Oats_Mo!P325 | Z10: =Oats_Mo!P340 | AA10: =Oats_Mo!P355
A11: Oats
A12: Oats | B12: Food | C12: KMT | D12: =Oats_Mo!P12 | E12: =Oats_Mo!P27 | F12: =Oats_Mo!P42 | G12: =Oats_Mo!P57 | H12: =Oats_Mo!P72 | I12: =Oats_Mo!P87 | J12: =Oats_Mo!P102 | K12: =Oats_Mo!P117 | L12: =Oats_Mo!P132 | M12: =Oats_Mo!P147 | N12: =Oats_Mo!P162 | O12: =Oats_Mo!P177 | P12: =Oats_Mo!P192 | Q12: =Oats_Mo!P207 | R12: =Oats_Mo!P222 | S12: =Oats_Mo!P237 | T12: =Oats_Mo!P252 | U12: =Oats_Mo!P267 | V12: =Oats_Mo!P282 | W12: =Oats_Mo!P297 | X12: =Oats_Mo!P312 | Y12: =Oats_Mo!P327 | Z12: =Oats_Mo!P342 | AA12: =Oats_Mo!P357
A13: Oats | B13: Industrial | C13: KMT | D13: =Oats_Mo!P13 | E13: =Oats_Mo!P28 | F13: =Oats_Mo!P43 | G13: =Oats_Mo!P58 | H13: =Oats_Mo!P73 | I13: =Oats_Mo!P88 | J13: =Oats_Mo!P103 | K13: =Oats_Mo!P118 | L13: =Oats_Mo!P133 | M13: =Oats_Mo!P148 | N13: =Oats_Mo!P163 | O13: =Oats_Mo!P178 | P13: =Oats_Mo!P193 | Q13: =Oats_Mo!P208 | R13: =Oats_Mo!P223 | S13: =Oats_Mo!P238 | T13: =Oats_Mo!P253 | U13: =Oats_Mo!P268 | V13: =Oats_Mo!P283 | W13: =Oats_Mo!P298 | X13: =Oats_Mo!P313 | Y13: =Oats_Mo!P328 | Z13: =Oats_Mo!P343 | AA13: =Oats_Mo!P358
A14: Oats | B14: FSR | C14: KMT | D14: =Oats_Mo!P14 | E14: =Oats_Mo!P29 | F14: =Oats_Mo!P44 | G14: =Oats_Mo!P59 | H14: =Oats_Mo!P74 | I14: =Oats_Mo!P89 | J14: =Oats_Mo!P104 | K14: =Oats_Mo!P119 | L14: =Oats_Mo!P134 | M14: =Oats_Mo!P149 | N14: =Oats_Mo!P164 | O14: =Oats_Mo!P179 | P14: =Oats_Mo!P194 | Q14: =Oats_Mo!P209 | R14: =Oats_Mo!P224 | S14: =Oats_Mo!P239 | T14: =Oats_Mo!P254 | U14: =Oats_Mo!P269 | V14: =Oats_Mo!P284 | W14: =Oats_Mo!P299 | X14: =Oats_Mo!P314 | Y14: =Oats_Mo!P329 | Z14: =Oats_Mo!P344 | AA14: =Oats_Mo!P359
A15: Oats | B15: Exports | C15: KMT | D15: =Oats_Mo!P15 | E15: =Oats_Mo!P30 | F15: =Oats_Mo!P45 | G15: =Oats_Mo!P60 | H15: =Oats_Mo!P75 | I15: =Oats_Mo!P90 | J15: =Oats_Mo!P105 | K15: =Oats_Mo!P120 | L15: =Oats_Mo!P135 | M15: =Oats_Mo!P150 | N15: =Oats_Mo!P165 | O15: =Oats_Mo!P180 | P15: =Oats_Mo!P195 | Q15: =Oats_Mo!P210 | R15: =Oats_Mo!P225 | S15: =Oats_Mo!P240 | T15: =Oats_Mo!P255 | U15: =Oats_Mo!P270 | V15: =Oats_Mo!P285 | W15: =Oats_Mo!P300 | X15: =Oats_Mo!P315 | Y15: =Oats_Mo!P330 | Z15: =Oats_Mo!P345 | AA15: =Oats_Mo!P360
A16: Oats
A17: Oats | B17: Ending Stocks | C17: KMT | D17: =Oats_Mo!P17 | E17: =Oats_Mo!P32 | F17: =Oats_Mo!P47 | G17: =Oats_Mo!P62 | H17: =Oats_Mo!P77 | I17: =Oats_Mo!P92 | J17: =Oats_Mo!P107 | K17: =Oats_Mo!P122 | L17: =Oats_Mo!P137 | M17: =Oats_Mo!P152 | N17: =Oats_Mo!P167 | O17: =Oats_Mo!P182 | P17: =Oats_Mo!P197 | Q17: =Oats_Mo!P212 | R17: =Oats_Mo!P227 | S17: =Oats_Mo!P242 | T17: =Oats_Mo!P257 | U17: =Oats_Mo!P272 | V17: =Oats_Mo!P287 | W17: =Oats_Mo!P302 | X17: =Oats_Mo!P317 | Y17: =Oats_Mo!P332 | Z17: =Oats_Mo!P347 | AA17: =Oats_Mo!P362
A18: Oats | B18: Stocks-to-Use | C18: %
A19: Oats | B19: STU Days | C19: Days
A20: Oats | B20: CHECK | C20: KMT | D20: =D8+D10+D9-D12-D13-D14-D15-D17 | E20: =E8+E10+E9-E12-E13-E14-E15-E17 | F20: =F8+F10+F9-F12-F13-F14-F15-F17 | G20: =G8+G10+G9-G12-G13-G14-G15-G17 | H20: =H8+H10+H9-H12-H13-H14-H15-H17 | I20: =I8+I10+I9-I12-I13-I14-I15-I17 | J20: =J8+J10+J9-J12-J13-J14-J15-J17 | K20: =K8+K10+K9-K12-K13-K14-K15-K17 | ... AA20: =AA8+AA10+AA9-AA12-AA13-AA14-AA15-AA17

Sheet Soybeans_Mo
A1: Soybeans
A2: Commodity | B2: Metric | C2: Crop Year | D2: 09 | E2: 10 | F2: 11 | G2: 12 | H2: 01 | I2: 02 | J2: 03 | K2: 04 | L2: 05 | M2: 06 | N2: 07 | O2: 08 | P2: Total
A3: Soybeans | B3: Planted Area | C3: 2002-03 | P3: =SUM(D3:O3)
A4: Soybeans | B4: Harvested Area | C4: 2002-03 | P4: =SUM(D4:O4)
A5: Soybeans | B5: Proportion Harvested | C5: 2002-03 | P5: =SUM(D5:O5)
A6: Soybeans | B6: Yield | C6: 2002-03 | P6: =SUM(D6:O6)
A7: Soybeans | C7: 2002-03
A8: Soybeans | B8: Beginning Stocks | C8: 2002-03 | N8: 171.8 | P8: =SUM(D8:O8)
A9: Soybeans | B9: Imports | C9: 2002-03 | N9: 651 | P9: =SUM(D9:O9)
A10: Soybeans | B10: Production | C10: 2002-03 | N10: 2335.7 | P10: =SUM(D10:O10)
A11: Soybeans | C11: 2002-03
A12: Soybeans | B12: Food | C12: 2002-03 | N12: 418.8 | P12: =SUM(D12:O12)
A13: Soybeans | B13: Crush | C13: 2002-03 | P13: =SUM(D13:O13)
A14: Soybeans | B14: FSR | C14: 2002-03 | N14: 1871.5 | P14: =SUM(D14:O14)
A15: Soybeans | B15: Exports | C15: 2002-03 | N15: 723.2 | P15: =SUM(D15:O15)
A16: Soybeans | C16: 2002-03
A17: Soybeans | B17: Ending Stocks | C17: 2002-03 | N17: 145 | P17: =SUM(D17:O17)
A18: Soybeans | B18: Stocks-to-Use | C18: 2002-03 | N18: 0.048116808 | P18: =SUM(D18:O18)
A19: Soybeans | B19: STU Days | C19: 2002-03 | N19: 17.562635 | P19: =SUM(D19:O19)
A20: Soybeans | B20: CHECK | C20: 2002-03 | N20: -2.2737368e-13 | P20: =SUM(D20:O20)
A21: Soybeans | B21: Planted Area | C21: 2003-04 | P21: =SUM(D21:O21)
A22: Soybeans | B22: Harvested Area | C22: 2003-04 | P22: =SUM(D22:O22)
A23: Soybeans | B23: Proportion Harvested | C23: 2003-04 | P23: =SUM(D23:O23)
A24: Soybeans | B24: Yield | C24: 2003-04 | P24: =SUM(D24:O24)
A25: Soybeans | C25: 2003-04
A26: Soybeans | B26: Beginning Stocks | C26: 2003-04 | N26: 145 | P26: =SUM(D26:O26)
A27: Soybeans | B27: Imports | C27: 2003-04 | N27: 586.7 | P27: =SUM(D27:O27)
A28: Soybeans | B28: Production | C28: 2003-04 | N28: 2273.3 | P28: =SUM(D28:O28)
A29: Soybeans | C29: 2003-04
A30: Soybeans | B30: Food | C30: 2003-04 | N30: 324.1 | P30: =SUM(D30:O30)
A31: Soybeans | B31: Crush | C31: 2003-04 | P31: =SUM(D31:O31)
A32: Soybeans | B32: FSR | C32: 2003-04 | N32: 1627.3 | P32: =SUM(D32:O32)
A33: Soybeans | B33: Exports | C33: 2003-04 | N33: 913.6 | P33: =SUM(D33:O33)
A34: Soybeans | C34: 2003-04
A35: Soybeans | B35: Ending Stocks | C35: 2003-04 | N35: 140 | P35: =SUM(D35:O35)
A36: Soybeans | B36: Stocks-to-Use | C36: 2003-04 | N36: 0.04886562 | P36: =SUM(D36:O36)
A37: Soybeans | B37: STU Days | C37: 2003-04 | N37: 17.835951 | P37: =SUM(D37:O37)
A38: Soybeans | B38: CHECK | C38: 2003-04 | N38: 1.1368684e-13 | P38: =SUM(D38:O38)
A39: Soybeans | B39: Planted Area | C39: 2004-05 | P39: =SUM(D39:O39)
A40: Soybeans | B40: Harvested Area | C40: 2004-05 | P40: =SUM(D40:O40)
...

Sheet Soybeans_Yr
A1: Soybeans
A2: Commodity | B2: Metric | C2: Unit | D2: 2002-03 | E2: 2003-04 | F2: 2004-05 | G2: 2005-06 | H2: 2006-07 | I2: 2007-08 | J2: 2008-09 | K2: 2009-10 | L2: 2010-11 | M2: 2011-12 | N2: 2012-13 | O2: 2013-14 | P2: 2014-15 | Q2: 2015-16 | R2: 2016-17 | S2: 2017-18 | T2: 2018-19 | U2: 2019-20 | V2: 2020-21 | W2: 2021-22 | X2: 2022-23 | Y2: 2023-24 | Z2: 2024-25 | AA2: 2025-26
A3: Soybeans | B3: Planted Area | C3: MLN AC | D3: =Soybeans_Mo!P3 | E3: =Soybeans_Mo!P18 | F3: =Soybeans_Mo!P33 | G3: =Soybeans_Mo!P48 | H3: =Soybeans_Mo!P63 | I3: =Soybeans_Mo!P78 | J3: =Soybeans_Mo!P93 | K3: =Soybeans_Mo!P108 | L3: =Soybeans_Mo!P123 | M3: =Soybeans_Mo!P138 | N3: =Soybeans_Mo!P153 | O3: =Soybeans_Mo!P168 | P3: =Soybeans_Mo!P183 | Q3: =Soybeans_Mo!P198 | R3: =Soybeans_Mo!P213 | S3: =Soybeans_Mo!P228 | T3: =Soybeans_Mo!P243 | U3: =Soybeans_Mo!P258 | V3: =Soybeans_Mo!P273 | W3: =Soybeans_Mo!P288 | X3: =Soybeans_Mo!P303 | Y3: =Soybeans_Mo!P318 | Z3: =Soybeans_Mo!P333 | AA3: =Soybeans_Mo!P348
A4: Soybeans | B4: Harvested Area | C4: MLN AC | D4: =Soybeans_Mo!P4 | E4: =Soybeans_Mo!P19 | F4: =Soybeans_Mo!P34 | G4: =Soybeans_Mo!P49 | H4: =Soybeans_Mo!P64 | I4: =Soybeans_Mo!P79 | J4: =Soybeans_Mo!P94 | K4: =Soybeans_Mo!P109 | L4: =Soybeans_Mo!P124 | M4: =Soybeans_Mo!P139 | N4: =Soybeans_Mo!P154 | O4: =Soybeans_Mo!P169 | P4: =Soybeans_Mo!P184 | Q4: =Soybeans_Mo!P199 | R4: =Soybeans_Mo!P214 | S4: =Soybeans_Mo!P229 | T4: =Soybeans_Mo!P244 | U4: =Soybeans_Mo!P259 | V4: =Soybeans_Mo!P274 | W4: =Soybeans_Mo!P289 | X4: =Soybeans_Mo!P304 | Y4: =Soybeans_Mo!P319 | Z4: =Soybeans_Mo!P334 | AA4: =Soybeans_Mo!P349
A5: Soybeans | B5: Proportion Harvested | C5: % | D5: =IF(D3<>0,D4/D3,"") | E5: =IF(E3<>0,E4/E3,"") | F5: =IF(F3<>0,F4/F3,"") | G5: =IF(G3<>0,G4/G3,"") | H5: =IF(H3<>0,H4/H3,"") | I5: =IF(I3<>0,I4/I3,"") | J5: =IF(J3<>0,J4/J3,"") | K5: =IF(K3<>0,K4/K3,"") | ... AA5: =IF(AA3<>0,AA4/AA3,"")
A6: Soybeans | B6: Yield | C6: BU/AC | D6: =Soybeans_Mo!O6 | E6: =Soybeans_Mo!O21 | F6: =Soybeans_Mo!O36 | G6: =Soybeans_Mo!O51 | H6: =Soybeans_Mo!O66 | I6: =Soybeans_Mo!O81 | J6: =Soybeans_Mo!O96 | K6: =Soybeans_Mo!O111 | L6: =Soybeans_Mo!O126 | M6: =Soybeans_Mo!O141 | N6: =Soybeans_Mo!O156 | O6: =Soybeans_Mo!O171 | P6: =Soybeans_Mo!O186 | Q6: =Soybeans_Mo!O201 | R6: =Soybeans_Mo!O216 | S6: =Soybeans_Mo!O231 | T6: =Soybeans_Mo!O246 | U6: =Soybeans_Mo!O261 | V6: =Soybeans_Mo!O276 | W6: =Soybeans_Mo!O291 | X6: =Soybeans_Mo!O306 | Y6: =Soybeans_Mo!O321 | Z6: =Soybeans_Mo!O336 | AA6: =Soybeans_Mo!O351
A7: Soybeans
A8: Soybeans | B8: Beginning Stocks | C8: KMT | D8: =Soybeans_Mo!P8 | E8: =Soybeans_Mo!P23 | F8: =Soybeans_Mo!P38 | G8: =Soybeans_Mo!P53 | H8: =Soybeans_Mo!P68 | I8: =Soybeans_Mo!P83 | J8: =Soybeans_Mo!P98 | K8: =Soybeans_Mo!P113 | L8: =Soybeans_Mo!P128 | M8: =Soybeans_Mo!P143 | N8: =Soybeans_Mo!P158 | O8: =Soybeans_Mo!P173 | P8: =Soybeans_Mo!P188 | Q8: =Soybeans_Mo!P203 | R8: =Soybeans_Mo!P218 | S8: =Soybeans_Mo!P233 | T8: =Soybeans_Mo!P248 | U8: =Soybeans_Mo!P263 | V8: =Soybeans_Mo!P278 | W8: =Soybeans_Mo!P293 | X8: =Soybeans_Mo!P308 | Y8: =Soybeans_Mo!P323 | Z8: =Soybeans_Mo!P338 | AA8: =Soybeans_Mo!P353
A9: Soybeans | B9: Imports | C9: KMT | D9: =Soybeans_Mo!P9 | E9: =Soybeans_Mo!P24 | F9: =Soybeans_Mo!P39 | G9: =Soybeans_Mo!P54 | H9: =Soybeans_Mo!P69 | I9: =Soybeans_Mo!P84 | J9: =Soybeans_Mo!P99 | K9: =Soybeans_Mo!P114 | L9: =Soybeans_Mo!P129 | M9: =Soybeans_Mo!P144 | N9: =Soybeans_Mo!P159 | O9: =Soybeans_Mo!P174 | P9: =Soybeans_Mo!P189 | Q9: =Soybeans_Mo!P204 | R9: =Soybeans_Mo!P219 | S9: =Soybeans_Mo!P234 | T9: =Soybeans_Mo!P249 | U9: =Soybeans_Mo!P264 | V9: =Soybeans_Mo!P279 | W9: =Soybeans_Mo!P294 | X9: =Soybeans_Mo!P309 | Y9: =Soybeans_Mo!P324 | Z9: =Soybeans_Mo!P339 | AA9: =Soybeans_Mo!P354
A10: Soybeans | B10: Production | C10: KMT | D10: =Soybeans_Mo!P10 | E10: =Soybeans_Mo!P25 | F10: =Soybeans_Mo!P40 | G10: =Soybeans_Mo!P55 | H10: =Soybeans_Mo!P70 | I10: =Soybeans_Mo!P85 | J10: =Soybeans_Mo!P100 | K10: =Soybeans_Mo!P115 | L10: =Soybeans_Mo!P130 | M10: =Soybeans_Mo!P145 | N10: =Soybeans_Mo!P160 | O10: =Soybeans_Mo!P175 | P10: =Soybeans_Mo!P190 | Q10: =Soybeans_Mo!P205 | R10: =Soybeans_Mo!P220 | S10: =Soybeans_Mo!P235 | T10: =Soybeans_Mo!P250 | U10: =Soybeans_Mo!P265 | V10: =Soybeans_Mo!P280 | W10: =Soybeans_Mo!P295 | X10: =Soybeans_Mo!P310 | Y10: =Soybeans_Mo!P325 | Z10: =Soybeans_Mo!P340 | AA10: =Soybeans_Mo!P355
A11: Soybeans
A12: Soybeans | B12: Food | C12: KMT | D12: =Soybeans_Mo!P12 | E12: =Soybeans_Mo!P27 | F12: =Soybeans_Mo!P42 | G12: =Soybeans_Mo!P57 | H12: =Soybeans_Mo!P72 | I12: =Soybeans_Mo!P87 | J12: =Soybeans_Mo!P102 | K12: =Soybeans_Mo!P117 | L12: =Soybeans_Mo!P132 | M12: =Soybeans_Mo!P147 | N12: =Soybeans_Mo!P162 | O12: =Soybeans_Mo!P177 | P12: =Soybeans_Mo!P192 | Q12: =Soybeans_Mo!P207 | R12: =Soybeans_Mo!P222 | S12: =Soybeans_Mo!P237 | T12: =Soybeans_Mo!P252 | U12: =Soybeans_Mo!P267 | V12: =Soybeans_Mo!P282 | W12: =Soybeans_Mo!P297 | X12: =Soybeans_Mo!P312 | Y12: =Soybeans_Mo!P327 | Z12: =Soybeans_Mo!P342 | AA12: =Soybeans_Mo!P357
A13: Soybeans | B13: Crush | C13: KMT | D13: =Soybeans_Mo!P13 | E13: =Soybeans_Mo!P28 | F13: =Soybeans_Mo!P43 | G13: =Soybeans_Mo!P58 | H13: =Soybeans_Mo!P73 | I13: =Soybeans_Mo!P88 | J13: =Soybeans_Mo!P103 | K13: =Soybeans_Mo!P118 | L13: =Soybeans_Mo!P133 | M13: =Soybeans_Mo!P148 | N13: =Soybeans_Mo!P163 | O13: =Soybeans_Mo!P178 | P13: =Soybeans_Mo!P193 | Q13: =Soybeans_Mo!P208 | R13: =Soybeans_Mo!P223 | S13: =Soybeans_Mo!P238 | T13: =Soybeans_Mo!P253 | U13: =Soybeans_Mo!P268 | V13: =Soybeans_Mo!P283 | W13: =Soybeans_Mo!P298 | X13: =Soybeans_Mo!P313 | Y13: =Soybeans_Mo!P328 | Z13: =Soybeans_Mo!P343 | AA13: =Soybeans_Mo!P358
A14: Soybeans | B14: FSR | C14: KMT | D14: =Soybeans_Mo!P14 | E14: =Soybeans_Mo!P29 | F14: =Soybeans_Mo!P44 | G14: =Soybeans_Mo!P59 | H14: =Soybeans_Mo!P74 | I14: =Soybeans_Mo!P89 | J14: =Soybeans_Mo!P104 | K14: =Soybeans_Mo!P119 | L14: =Soybeans_Mo!P134 | M14: =Soybeans_Mo!P149 | N14: =Soybeans_Mo!P164 | O14: =Soybeans_Mo!P179 | P14: =Soybeans_Mo!P194 | Q14: =Soybeans_Mo!P209 | R14: =Soybeans_Mo!P224 | S14: =Soybeans_Mo!P239 | T14: =Soybeans_Mo!P254 | U14: =Soybeans_Mo!P269 | V14: =Soybeans_Mo!P284 | W14: =Soybeans_Mo!P299 | X14: =Soybeans_Mo!P314 | Y14: =Soybeans_Mo!P329 | Z14: =Soybeans_Mo!P344 | AA14: =Soybeans_Mo!P359
A15: Soybeans | B15: Exports | C15: KMT | D15: =Soybeans_Mo!P15 | E15: =Soybeans_Mo!P30 | F15: =Soybeans_Mo!P45 | G15: =Soybeans_Mo!P60 | H15: =Soybeans_Mo!P75 | I15: =Soybeans_Mo!P90 | J15: =Soybeans_Mo!P105 | K15: =Soybeans_Mo!P120 | L15: =Soybeans_Mo!P135 | M15: =Soybeans_Mo!P150 | N15: =Soybeans_Mo!P165 | O15: =Soybeans_Mo!P180 | P15: =Soybeans_Mo!P195 | Q15: =Soybeans_Mo!P210 | R15: =Soybeans_Mo!P225 | S15: =Soybeans_Mo!P240 | T15: =Soybeans_Mo!P255 | U15: =Soybeans_Mo!P270 | V15: =Soybeans_Mo!P285 | W15: =Soybeans_Mo!P300 | X15: =Soybeans_Mo!P315 | Y15: =Soybeans_Mo!P330 | Z15: =Soybeans_Mo!P345 | AA15: =Soybeans_Mo!P360
A16: Soybeans
A17: Soybeans | B17: Ending Stocks | C17: KMT | D17: =Soybeans_Mo!P17 | E17: =Soybeans_Mo!P32 | F17: =Soybeans_Mo!P47 | G17: =Soybeans_Mo!P62 | H17: =Soybeans_Mo!P77 | I17: =Soybeans_Mo!P92 | J17: =Soybeans_Mo!P107 | K17: =Soybeans_Mo!P122 | L17: =Soybeans_Mo!P137 | M17: =Soybeans_Mo!P152 | N17: =Soybeans_Mo!P167 | O17: =Soybeans_Mo!P182 | P17: =Soybeans_Mo!P197 | Q17: =Soybeans_Mo!P212 | R17: =Soybeans_Mo!P227 | S17: =Soybeans_Mo!P242 | T17: =Soybeans_Mo!P257 | U17: =Soybeans_Mo!P272 | V17: =Soybeans_Mo!P287 | W17: =Soybeans_Mo!P302 | X17: =Soybeans_Mo!P317 | Y17: =Soybeans_Mo!P332 | Z17: =Soybeans_Mo!P347 | AA17: =Soybeans_Mo!P362
A18: Soybeans | B18: Stocks-to-Use | C18: %
A19: Soybeans | B19: STU Days | C19: Days
A20: Soybeans | B20: CHECK | C20: KMT

Sheet Dry peas_Yr
A1: Dry peas
A2: Commodity | B2: Metric | C2: Unit | D2: 2002-03 | E2: 2003-04 | F2: 2004-05 | G2: 2005-06 | H2: 2006-07 | I2: 2007-08 | J2: 2008-09 | K2: 2009-10 | L2: 2010-11 | M2: 2011-12 | N2: 2012-13 | O2: 2013-14 | P2: 2014-15 | Q2: 2015-16 | R2: 2016-17 | S2: 2017-18 | T2: 2018-19 | U2: 2019-20 | V2: 2020-21 | W2: 2021-22 | X2: 2022-23 | Y2: 2023-24 | Z2: 2024-25 | AA2: 2025-26
A3: Dry peas | B3: Planted Area | C3: MLN AC | D3: ='Dry peas_Mo'!P3 | E3: ='Dry peas_Mo'!P16 | F3: ='Dry peas_Mo'!P29 | G3: ='Dry peas_Mo'!P42 | H3: ='Dry peas_Mo'!P55 | I3: ='Dry peas_Mo'!P68 | J3: ='Dry peas_Mo'!P81 | K3: ='Dry peas_Mo'!P94 | L3: ='Dry peas_Mo'!P107 | M3: ='Dry peas_Mo'!P120 | N3: ='Dry peas_Mo'!P133 | O3: ='Dry peas_Mo'!P146 | P3: ='Dry peas_Mo'!P159 | Q3: ='Dry peas_Mo'!P172 | R3: ='Dry peas_Mo'!P185 | S3: ='Dry peas_Mo'!P198 | T3: ='Dry peas_Mo'!P211 | U3: ='Dry peas_Mo'!P224 | V3: ='Dry peas_Mo'!P237 | W3: ='Dry peas_Mo'!P250 | X3: ='Dry peas_Mo'!P263 | Y3: ='Dry peas_Mo'!P276 | Z3: ='Dry peas_Mo'!P289 | AA3: ='Dry peas_Mo'!P302
A4: Dry peas | B4: Harvested Area | C4: MLN AC | D4: ='Dry peas_Mo'!P4 | E4: ='Dry peas_Mo'!P17 | F4: ='Dry peas_Mo'!P30 | G4: ='Dry peas_Mo'!P43 | H4: ='Dry peas_Mo'!P56 | I4: ='Dry peas_Mo'!P69 | J4: ='Dry peas_Mo'!P82 | K4: ='Dry peas_Mo'!P95 | L4: ='Dry peas_Mo'!P108 | M4: ='Dry peas_Mo'!P121 | N4: ='Dry peas_Mo'!P134 | O4: ='Dry peas_Mo'!P147 | P4: ='Dry peas_Mo'!P160 | Q4: ='Dry peas_Mo'!P173 | R4: ='Dry peas_Mo'!P186 | S4: ='Dry peas_Mo'!P199 | T4: ='Dry peas_Mo'!P212 | U4: ='Dry peas_Mo'!P225 | V4: ='Dry peas_Mo'!P238 | W4: ='Dry peas_Mo'!P251 | X4: ='Dry peas_Mo'!P264 | Y4: ='Dry peas_Mo'!P277 | Z4: ='Dry peas_Mo'!P290 | AA4: ='Dry peas_Mo'!P303
A5: Dry peas | B5: Proportion Harvested | C5: % | D5: =IF(D3<>0,D4/D3,"") | E5: =IF(E3<>0,E4/E3,"") | F5: =IF(F3<>0,F4/F3,"") | G5: =IF(G3<>0,G4/G3,"") | H5: =IF(H3<>0,H4/H3,"") | I5: =IF(I3<>0,I4/I3,"") | J5: =IF(J3<>0,J4/J3,"") | K5: =IF(K3<>0,K4/K3,"") | ... AA5: =IF(AA3<>0,AA4/AA3,"")
A6: Dry peas | B6: Yield | C6: BU/AC | D6: ='Dry peas_Mo'!O6 | E6: ='Dry peas_Mo'!O19 | F6: ='Dry peas_Mo'!O32 | G6: ='Dry peas_Mo'!O45 | H6: ='Dry peas_Mo'!O58 | I6: ='Dry peas_Mo'!O71 | J6: ='Dry peas_Mo'!O84 | K6: ='Dry peas_Mo'!O97 | L6: ='Dry peas_Mo'!O110 | M6: ='Dry peas_Mo'!O123 | N6: ='Dry peas_Mo'!O136 | O6: ='Dry peas_Mo'!O149 | P6: ='Dry peas_Mo'!O162 | Q6: ='Dry peas_Mo'!O175 | R6: ='Dry peas_Mo'!O188 | S6: ='Dry peas_Mo'!O201 | T6: ='Dry peas_Mo'!O214 | U6: ='Dry peas_Mo'!O227 | V6: ='Dry peas_Mo'!O240 | W6: ='Dry peas_Mo'!O253 | X6: ='Dry peas_Mo'!O266 | Y6: ='Dry peas_Mo'!O279 | Z6: ='Dry peas_Mo'!O292 | AA6: ='Dry peas_Mo'!O305
A7: Dry peas
A8: Dry peas | B8: Beginning Stocks | C8: KMT | D8: ='Dry peas_Mo'!P8 | E8: ='Dry peas_Mo'!P21 | F8: ='Dry peas_Mo'!P34 | G8: ='Dry peas_Mo'!P47 | H8: ='Dry peas_Mo'!P60 | I8: ='Dry peas_Mo'!P73 | J8: ='Dry peas_Mo'!P86 | K8: ='Dry peas_Mo'!P99 | L8: ='Dry peas_Mo'!P112 | M8: ='Dry peas_Mo'!P125 | N8: ='Dry peas_Mo'!P138 | O8: ='Dry peas_Mo'!P151 | P8: ='Dry peas_Mo'!P164 | Q8: ='Dry peas_Mo'!P177 | R8: ='Dry peas_Mo'!P190 | S8: ='Dry peas_Mo'!P203 | T8: ='Dry peas_Mo'!P216 | U8: ='Dry peas_Mo'!P229 | V8: ='Dry peas_Mo'!P242 | W8: ='Dry peas_Mo'!P255 | X8: ='Dry peas_Mo'!P268 | Y8: ='Dry peas_Mo'!P281 | Z8: ='Dry peas_Mo'!P294 | AA8: ='Dry peas_Mo'!P307
A9: Dry peas | B9: Imports | C9: KMT | D9: ='Dry peas_Mo'!P9 | E9: ='Dry peas_Mo'!P22 | F9: ='Dry peas_Mo'!P35 | G9: ='Dry peas_Mo'!P48 | H9: ='Dry peas_Mo'!P61 | I9: ='Dry peas_Mo'!P74 | J9: ='Dry peas_Mo'!P87 | K9: ='Dry peas_Mo'!P100 | L9: ='Dry peas_Mo'!P113 | M9: ='Dry peas_Mo'!P126 | N9: ='Dry peas_Mo'!P139 | O9: ='Dry peas_Mo'!P152 | P9: ='Dry peas_Mo'!P165 | Q9: ='Dry peas_Mo'!P178 | R9: ='Dry peas_Mo'!P191 | S9: ='Dry peas_Mo'!P204 | T9: ='Dry peas_Mo'!P217 | U9: ='Dry peas_Mo'!P230 | V9: ='Dry peas_Mo'!P243 | W9: ='Dry peas_Mo'!P256 | X9: ='Dry peas_Mo'!P269 | Y9: ='Dry peas_Mo'!P282 | Z9: ='Dry peas_Mo'!P295 | AA9: ='Dry peas_Mo'!P308
A10: Dry peas | B10: Production | C10: KMT | D10: ='Dry peas_Mo'!P10 | E10: ='Dry peas_Mo'!P23 | F10: ='Dry peas_Mo'!P36 | G10: ='Dry peas_Mo'!P49 | H10: ='Dry peas_Mo'!P62 | I10: ='Dry peas_Mo'!P75 | J10: ='Dry peas_Mo'!P88 | K10: ='Dry peas_Mo'!P101 | L10: ='Dry peas_Mo'!P114 | M10: ='Dry peas_Mo'!P127 | N10: ='Dry peas_Mo'!P140 | O10: ='Dry peas_Mo'!P153 | P10: ='Dry peas_Mo'!P166 | Q10: ='Dry peas_Mo'!P179 | R10: ='Dry peas_Mo'!P192 | S10: ='Dry peas_Mo'!P205 | T10: ='Dry peas_Mo'!P218 | U10: ='Dry peas_Mo'!P231 | V10: ='Dry peas_Mo'!P244 | W10: ='Dry peas_Mo'!P257 | X10: ='Dry peas_Mo'!P270 | Y10: ='Dry peas_Mo'!P283 | Z10: ='Dry peas_Mo'!P296 | AA10: ='Dry peas_Mo'!P309
A11: Dry peas
